File: ppms-mpms/Bi-O-S_bestsample_Add.dat
[Header]
TITLE,Bi-O-S_bestsample_Add.dat
BYAPP,HeatCapacity,3.8.6,1.7
INFO,,MASS:Sample Mass (mg)
INFO,,MASSERR:Sample Mass Error (mg)
INFO,,MOLWGHT:Formula Weight (g/mole)
INFO,,ATOMS:Atoms per Formula Unit
INFO,PPMS Heat Capacity Option 3.8.6 Build 1,APPNAME
DATATYPE,TIME,1
DATATYPE,COMMENT,2
STARTUPAXIS, X, 8, LINEAR, AUTO
STARTUPAXIS, Y1, 12, LINEAR, AUTO
[Data]
Time Stamp (Seconds),Comment (),System Status (Code),Puck Temp (Kelvin),System Temp (Kelvin),Field (Oersted),Pressure (Torr),Sample Temp (Kelvin),Temp Rise (Kelvin),Samp HC (µJ/K),Samp HC Err (µJ/K),Addenda HC (µJ/K),Addenda HC Err (µJ/K),Total HC (µJ/K),Total HC Err (µJ/K),Fit Deviation (ChiSquare),Time Const tau1 (seconds),Time Const tau2 (seconds),Sample Coupling (Percent),Debye Temp (Kelvin),Debye Temp Err (Kelvin),Cal Correction (Factor),Therm Resist (Ohms),Htr Resist (Ohms),Puck Resist (Ohms),Wire Cond (W/K),Meas Time (seconds),Temp Squared (K^2),Samp HC/Temp (µJ/K/K),Addenda Offset HC (µJ/K)
28483624.91,CALFILE: Puck1089.cal
28483625.03,,5905,1.81555,1.8026,0.174,9.3E-6,1.8331528,0.034018286,0,0,0.11022838,0.0009673,0.11022838,0.0009673,124.18298,0.066829815,0,100,,,1,,,,1.6494E-6,0.1471704,3.3604491,0,0
28483671.5,,5905,1.81568,1.8028,0.174,9.4E-6,1.8318898,0.031452678,0,0,0.10972858,0.001118,0.10972858,0.001118,78.432696,0.065856721,0,100,,,1,,,,1.6662E-6,0.1319202,3.3558202,0,0
28483717.94,,5905,1.81542,1.8023,0.174,9.3E-6,1.8316986,0.031357246,0,0,0.10983541,0.001131,0.10983541,0.001131,234.62959,0.065783148,0,100,,,1,,,,1.6697E-6,0.1314122,3.3551198,0,0
28483764.36,,5905,1.8147,1.8019,0.174,9.3E-6,1.8308146,0.031401364,0,0,0.10971764,0.001105,0.10971764,0.001105,56.137232,0.065713599,0,100,,,1,,,,1.6696E-6,0.1318195,3.3518822,0,0
28483967.86,,5905,1.90279,1.9002,0.174,9.4E-6,1.9140877,0.031757238,0,0,0.11962815,0.001207,0.11962815,0.001207,8.6639981,0.066906705,0,100,,,1,,,,1.788E-6,0.1317165,3.6637316,0,0
28484014.39,,5905,1.90285,1.9009,0.174,9.3E-6,1.9141923,0.032164406,0,0,0.11969477,0.00132,0.11969477,0.00132,17.127929,0.066835004,0,100,,,1,,,,1.7909E-6,0.1345053,3.6641323,0,0
28484063.69,,5905,1.90225,1.9001,0.174,9.4E-6,1.9134766,0.03205958,0,0,0.11965815,0.00117,0.11965815,0.00117,91.03561,0.067098309,0,100,,,1,,,,1.7833E-6,0.1336103,3.6613926,0,0
28484113.03,,5905,1.90213,1.901,0.174,9.3E-6,1.9136229,0.032091288,0,0,0.11974569,0.001371,0.11974569,0.001371,16.526164,0.067123315,0,100,,,1,,,,1.784E-6,0.1339021,3.6619526,0,0
28484315.39,,5905,1.9995,2.0134,0.174,9.3E-6,2.0060635,0.032053501,0,0,0.13211931,0.001419,0.13211931,0.001419,71.074484,0.066938898,0,100,,,1,,,,1.9737E-6,0.1341648,4.0242909,0,0
28484361.69,,5905,1.99982,2.012,0.174,9.4E-6,2.0072816,0.032116309,0,0,0.13220158,0.001408,0.13220158,0.001408,162.49391,0.067314035,0,100,,,1,,,,1.964E-6,0.1339159,4.0291795,0,0
28484411.78,,5905,2.00093,2.013,0.174,9.4E-6,2.0078146,0.032180581,0,0,0.13214165,0.00139,0.13214165,0.00139,18.709287,0.066807251,0,100,,,1,,,,1.978E-6,0.13478,4.0313194,0,0
28484458.11,,5905,2.00099,2.0127,0.174,9.3E-6,2.0079267,0.032109933,0,0,0.1322134,0.001431,0.1322134,0.001431,9.6350322,0.066905051,0,100,,,1,,,,1.9761E-6,0.1342403,4.0317695,0,0
28484655.66,,5905,2.10063,2.1137,0.174,9.3E-6,2.1076148,0.030870868,0,0,0.1486135,0.002006,0.1486135,0.002006,13.387938,0.06342613,0,100,,,1,,,,2.3431E-6,0.1343077,4.44204,0,0
28484702.03,,5905,2.10174,2.1167,0.174,9.3E-6,2.1073013,0.028954104,0,0,0.1474986,0.001976,0.1474986,0.001976,68.806444,0.062505315,0,100,,,1,,,,2.3598E-6,0.124042,4.4407189,0,0
28484749.23,,5905,2.10171,2.1149,0.174,9.3E-6,2.1081502,0.029112876,0,0,0.147571,0.001899,0.147571,0.001899,46.070171,0.062745141,0,100,,,1,,,,2.3519E-6,0.1247144,4.4442974,0,0
28484795.36,,5905,2.10304,2.1178,0.174,9.3E-6,2.1093305,0.029081484,0,0,0.14774704,0.002423,0.14774704,0.002423,9.5925428,0.0626801,0,100,,,1,,,,2.3572E-6,0.1248646,4.4492751,0,0
28484998.92,,5905,2.20284,2.2172,0.174,9.3E-6,2.20898,0.02707364,0,0,0.17209247,0.003107,0.17209247,0.003107,141.35191,0.06044194,0,100,,,1,,,,2.8472E-6,0.1248455,4.8795928,0,0
28485045.33,,5905,2.20343,2.218,0.174,9.4E-6,2.2085768,0.026806273,0,0,0.17051212,0.003057,0.17051212,0.003057,77.964034,0.060109158,0,100,,,1,,,,2.8367E-6,0.1214553,4.8778116,0,0
28485095.34,,5905,2.20488,2.2197,0.174,9.3E-6,2.2091274,0.02667959,0,0,0.17094145,0.002983,0.17094145,0.002983,95.334726,0.06023345,0,100,,,1,,,,2.838E-6,0.1205027,4.8802438,0,0
28485147.2,,5905,2.20453,2.2205,0.174,9.3E-6,2.2098256,0.026841618,0,0,0.1707095,0.003169,0.1707095,0.003169,18.48335,0.060690859,0,100,,,1,,,,2.8128E-6,0.1207714,4.883329,0,0
28485349.75,,5905,2.30351,2.3234,0.174,9.3E-6,2.3062086,0.024531244,0,0,0.20969779,0.005616,0.20969779,0.005616,36.033472,0.064842469,0,100,,,1,,,,3.234E-6,0.1211715,5.3185982,0,0
28485396.3,,5905,2.30436,2.3238,0.174,9.4E-6,2.3085082,0.027056973,0,0,0.2151849,0.005609,0.2151849,0.005609,26.170442,0.068272171,0,100,,,1,,,,3.1519E-6,0.1385409,5.3292103,0,0
28485442.63,,5905,2.3045,2.3231,0.174,9.4E-6,2.3092871,0.026957629,0,0,0.21542992,0.00547,0.21542992,0.00547,83.568447,0.069076819,0,100,,,1,,,,3.1187E-6,0.1367895,5.332807,0,0
28485489.17,,5905,2.3058,2.3252,0.174,9.4E-6,2.3103209,0.026877822,0,0,0.21454798,0.005465,0.21454798,0.005465,28.600799,0.068090726,0,100,,,1,,,,3.1509E-6,0.1362938,5.3375828,0,0
28485693.02,,5905,2.40384,2.4243,0.174,9.4E-6,2.4072851,0.026014473,0,0,0.25991284,0.006766,0.25991284,0.006766,69.66769,0.081123209,0,100,,,1,,,,3.2039E-6,0.1376411,5.7950218,0,0
28485739.52,,5905,2.4056,2.4275,0.174,9.3E-6,2.4129414,0.03246317,0,0,0.2719341,0.006239,0.2719341,0.006239,324.41577,0.091562673,0,100,,,1,,,,2.9699E-6,0.1843483,5.8222861,0,0
28485789.61,,5905,2.4054,2.4263,0.174,9.4E-6,2.4139477,0.032494004,0,0,0.271617,0.006317,0.271617,0.006317,343.44236,0.091778676,0,100,,,1,,,,2.9595E-6,0.1838329,5.8271434,0,0
28485837.72,,5905,2.40762,2.4279,0.174,9.4E-6,2.4154062,0.032583241,0,0,0.2700124,0.006253,0.2700124,0.006253,284.60829,0.090595617,0,100,,,1,,,,2.9804E-6,0.1840687,5.8341869,0,0
28486038.56,,5905,2.50393,2.5268,0.174,9.4E-6,2.5096979,0.032719105,0,0,0.3018829,0.006114,0.3018829,0.006114,168.58233,0.10146794,0,100,,,1,,,,2.9752E-6,0.1810033,6.2985837,0,0
28486088.67,,5905,2.50614,2.5313,0.174,9.4E-6,2.5141483,0.036624473,0,0,0.30662949,0.005849,0.30662949,0.005849,37.834121,0.10687633,0,100,,,1,,,,2.869E-6,0.2106153,6.3209417,0,0
28486135.27,,5905,2.50703,2.5301,0.174,9.4E-6,2.5146872,0.036675577,0,0,0.30453245,0.006098,0.30453245,0.006098,67.317987,0.10484514,0,100,,,1,,,,2.9046E-6,0.2112601,6.3236515,0,0
28486181.84,,5905,2.50818,2.5317,0.174,9.3E-6,2.5156369,0.035950253,0,0,0.30150871,0.005934,0.30150871,0.005934,72.772252,0.10077943,0,100,,,1,,,,2.9918E-6,0.2084681,6.328429,0,0
28486385,,5905,2.60918,2.6253,0.174,9.3E-6,2.6156603,0.036182259,0,0,0.32958917,0.006104,0.32958917,0.006104,15.136594,0.10884465,0,100,,,1,,,,3.0281E-6,0.2027938,6.8416788,0,0
28486431.36,,5905,2.6111,2.627,0.174,9.3E-6,2.6173576,0.038652543,0,0,0.33203507,0.005553,0.33203507,0.005553,131.44451,0.11110835,0,100,,,1,,,,2.9884E-6,0.223176,6.850561,0,0
28486483.44,,5905,2.61096,2.6244,0.174,9.3E-6,2.6199793,0.03880871,0,0,0.33006101,0.005714,0.33006101,0.005714,222.40721,0.11075057,0,100,,,1,,,,2.9802E-6,0.2226557,6.8642916,0,0
28486529.78,,5905,2.61128,2.6244,0.174,9.3E-6,2.6208271,0.038559036,0,0,0.32877735,0.005828,0.32877735,0.005828,215.04511,0.1096567,0,100,,,1,,,,2.9982E-6,0.2198918,6.8687346,0,0
28486735.81,,5905,2.71027,2.7269,0.174,9.4E-6,2.7178771,0.039383435,0,0,0.35758568,0.005704,0.35758568,0.005704,78.360638,0.11797598,0,100,,,1,,,,3.031E-6,0.2189972,7.386856,0,0
28486789.83,,5905,2.70199,2.7422,0.174,9.4E-6,2.7098876,0.041175829,0,0,0.35359503,0.005689,0.35359503,0.005689,66.472948,0.11634605,0,100,,,1,,,,3.0392E-6,0.234413,7.343491,0,0
28486838.61,,5905,2.70525,2.7456,0.174,9.4E-6,2.7130019,0.040849797,0,0,0.35443465,0.005973,0.35443465,0.005973,36.014682,0.1158449,0,100,,,1,,,,3.0596E-6,0.2319086,7.3603793,0,0
28486887.88,,5905,2.70721,2.7471,0.174,9.3E-6,2.7158736,0.041017843,0,0,0.35278236,0.005787,0.35278236,0.005787,25.505241,0.11463069,0,100,,,1,,,,3.0776E-6,0.2323621,7.3759695,0,0
28487085.25,,5905,2.80435,2.8488,0.174,9.3E-6,2.8118016,0.041869986,0,0,0.38073498,0.005519,0.38073498,0.005519,98.047875,0.12279605,0,100,,,1,,,,3.1005E-6,0.2313066,7.9062282,0,0
28487133.64,,5905,2.80696,2.8499,0.174,9.4E-6,2.8157811,0.043819333,0,0,0.38252049,0.005479,0.38252049,0.005479,119.8525,0.12380984,0,100,,,1,,,,3.0896E-6,0.2471609,7.9286232,0,0
28487187.59,,5905,2.80879,2.8518,0.174,9.3E-6,2.8171801,0.043748817,0,0,0.38185545,0.005737,0.38185545,0.005737,110.04604,0.12250371,0,100,,,1,,,,3.1171E-6,0.2464406,7.9365039,0,0
28487235.81,,5905,2.8101,2.8549,0.174,9.3E-6,2.819217,0.043679632,0,0,0.38152604,0.005973,0.38152604,0.005973,88.934485,0.12326292,0,100,,,1,,,,3.0952E-6,0.2440269,7.9479848,0,0
28487436.06,,5905,2.90604,2.9525,0.174,9.4E-6,2.9130747,0.044504439,0,0,0.40846713,0.005595,0.40846713,0.005595,70.468785,0.12979896,0,100,,,1,,,,3.1469E-6,0.2430607,8.4860045,0,0
28487484.59,,5905,2.90884,2.9547,0.174,9.4E-6,2.9167099,0.046554253,0,0,0.41062645,0.005635,0.41062645,0.005635,88.917644,0.12941166,0,100,,,1,,,,3.173E-6,0.2617482,8.5071964,0,0
28487532.81,,5905,2.91026,2.9551,0.174,9.3E-6,2.9196236,0.045296869,0,0,0.4078636,0.005726,0.4078636,0.005726,107.8021,0.12662161,0,100,,,1,,,,3.2211E-6,0.2526684,8.5242019,0,0
28487581.34,,5905,2.91222,2.9571,0.174,9.3E-6,2.920892,0.04543974,0,0,0.40671026,0,0.40671026,0,65.176321,0.12725819,0,100,,,1,,,,3.1959E-6,0.2513439,8.5316102,0,0
28487778.52,,5905,3.00712,3.0562,0.174,9.3E-6,3.0145926,0.04603067,0,0,0.43480632,0.005676,0.43480632,0.005676,113.26474,0.13223505,0,100,,,1,,,,3.2881E-6,0.2501865,9.0877684,0,0
28487827.91,,5905,3.01113,3.0606,0.174,9.4E-6,3.0183881,0.048118067,0,0,0.43528528,0.006058,0.43528528,0.006058,40.809267,0.1324091,0,100,,,1,,,,3.2874E-6,0.2668839,9.1106666,0,0
28487876.16,,5905,3.01214,3.0634,0.174,9.3E-6,3.0209941,0.048095896,0,0,0.4356347,0.005969,0.4356347,0.005969,75.141281,0.13360936,0,100,,,1,,,,3.2605E-6,0.2646077,9.1264054,0,0
28487924.78,,5905,3.01431,3.0657,0.174,9.3E-6,3.0232687,0.048053863,0,0,0.43560705,0.005838,0.43560705,0.005838,48.00047,0.13235318,0,100,,,1,,,,3.2912E-6,0.2649987,9.1401536,0,0
28488120.14,,5905,3.10684,3.1576,0.174,9.4E-6,3.1156485,0.048662455,0,0,0.46169594,0.005708,0.46169594,0.005708,63.448664,0.13764751,0,100,,,1,,,,3.3542E-6,0.2611916,9.7072653,0,0
28488169.64,,5905,3.11037,3.1599,0.174,9.3E-6,3.118867,0.050405287,0,0,0.46598534,0.006011,0.46598534,0.006011,11.906902,0.14015191,0,100,,,1,,,,3.3249E-6,0.2754803,9.7273314,0,0
28488218.55,,5905,3.11383,3.1664,0.174,9.3E-6,3.1221047,0.050458479,0,0,0.46369844,0.005879,0.46369844,0.005879,15.582656,0.13750834,0,100,,,1,,,,3.3721E-6,0.2764245,9.7475379,0,0
28488267.11,,5905,3.11485,3.1676,0.174,9.4E-6,3.1240234,0.049978138,0,0,0.46381851,0.005931,0.46381851,0.005931,38.057257,0.13694742,0,100,,,1,,,,3.3868E-6,0.273883,9.7595223,0,0
28488458.11,,5905,3.20884,3.263,0.174,9.3E-6,3.2173836,0.0502347,0,0,0.49407187,0.005844,0.49407187,0.005844,57.98558,0.14220731,0,100,,,1,,,,3.4743E-6,0.2702017,10.351557,0,0
28488507.52,,5905,3.21115,3.2636,0.174,9.3E-6,3.2226412,0.05260994,0,0,0.49689112,0.005808,0.49689112,0.005808,88.666121,0.14496629,0,100,,,1,,,,3.4276E-6,0.2880145,10.385417,0,0
28488557.91,,5905,3.21434,3.2668,0.174,9.3E-6,3.2241017,0.052122381,0,0,0.49564141,0.006018,0.49564141,0.006018,27.079345,0.14361092,0,100,,,1,,,,3.4513E-6,0.2831838,10.394832,0,0
28488605.91,,5905,3.21681,3.2721,0.174,9.4E-6,3.2266568,0.051887447,0,0,0.49418459,0.006137,0.49418459,0.006137,21.411933,0.14121838,0,100,,,1,,,,3.4994E-6,0.2822896,10.411314,0,0
28488800.33,,5905,3.31073,3.3675,0.174,9.3E-6,3.3192575,0.052736238,0,0,0.52684629,0.005627,0.52684629,0.005627,103.74087,0.14810269,0,100,,,1,,,,3.5573E-6,0.2822582,11.017471,0,0
28488847.3,,5905,3.31354,3.3699,0.174,9.4E-6,3.3240812,0.054882866,0,0,0.52793085,0.005354,0.52793085,0.005354,32.352274,0.14894649,0,100,,,1,,,,3.5444E-6,0.2986927,11.049516,0,0
28488894.98,,5905,3.31621,3.3722,0.174,9.3E-6,3.3272629,0.054689081,0,0,0.52805777,0.005878,0.52805777,0.005878,26.993052,0.14901148,0,100,,,1,,,,3.5437E-6,0.2962361,11.070679,0,0
28488941.98,,5905,3.31863,3.3773,0.174,9.4E-6,3.3286435,0.054813867,0,0,0.52748523,0.005807,0.52748523,0.005807,116.58033,0.1490175,0,100,,,1,,,,3.5398E-6,0.2960301,11.079868,0,0
28489131.66,,5905,3.40966,3.4676,0.174,9.4E-6,3.4198051,0.055941276,0,0,0.56083502,0.00568,0.56083502,0.00568,10.159216,0.1558167,0,100,,,1,,,,3.5993E-6,0.2986386,11.695067,0,0
28489179.84,,5905,3.41368,3.4722,0.174,9.3E-6,3.4238751,0.057305577,0,0,0.55909678,0.005276,0.55909678,0.005276,39.163159,0.15350625,0,100,,,1,,,,3.6422E-6,0.3103423,11.722921,0,0
28489226.48,,5905,3.41699,3.4746,0.174,9.4E-6,3.4266386,0.057366667,0,0,0.56090436,0.005475,0.56090436,0.005475,30.652831,0.15410032,0,100,,,1,,,,3.6399E-6,0.3108874,11.741852,0,0
28489273.25,,5905,3.41832,3.4746,0.174,9.3E-6,3.4285296,0.056972998,0,0,0.55907384,0.005824,0.55907384,0.005824,75.62693,0.1534344,0,100,,,1,,,,3.6437E-6,0.3068581,11.754815,0,0
28489460.92,,5905,3.5115,3.5726,0.174,9.3E-6,3.5211493,0.057632357,0,0,0.59151132,0.005807,0.59151132,0.005807,157.82163,0.15878357,0,100,,,1,,,,3.7253E-6,0.3057499,12.398493,0,0
28489507.92,,5905,3.51531,3.5774,0.174,9.4E-6,3.5262273,0.059483299,0,0,0.59463468,0.00531,0.59463468,0.00531,65.655764,0.15969964,0,100,,,1,,,,3.7235E-6,0.3207975,12.434279,0,0
28489555.75,,5905,3.51789,3.5814,0.174,9.4E-6,3.5293328,0.059373506,0,0,0.59352482,0.005533,0.59352482,0.005533,63.443092,0.15887387,0,100,,,1,,,,3.7358E-6,0.319044,12.45619,0,0
28489602.58,,5905,3.52078,3.5829,0.174,9.3E-6,3.5309308,0.059480546,0,0,0.59437215,0.005914,0.59437215,0.005914,88.903164,0.16061618,0,100,,,1,,,,3.7006E-6,0.3176067,12.467472,0,0
28489791.28,,5905,3.61285,3.6777,0.174,9.3E-6,3.6227811,0.059796385,0,0,0.6275717,0.005364,0.6275717,0.005364,40.605264,0.16387448,0,100,,,1,,,,3.8296E-6,0.315473,13.124543,0,0
28489838.95,,5905,3.61601,3.6791,0.174,9.4E-6,3.6274596,0.061863044,0,0,0.62840201,0.004948,0.62840201,0.004948,29.180032,0.16401382,0,100,,,1,,,,3.8314E-6,0.3322232,13.158463,0,0
28489886.09,,5905,3.62022,3.6859,0.174,9.3E-6,3.6307533,0.061918752,0,0,0.62811947,0.004953,0.62811947,0.004953,38.697548,0.16353474,0,100,,,1,,,,3.8409E-6,0.3317142,13.182369,0,0
28489933.95,,5905,3.62154,3.6867,0.174,9.4E-6,3.6329493,0.062111127,0,0,0.63085167,0.005751,0.63085167,0.005751,30.278204,0.1663143,0,100,,,1,,,,3.7931E-6,0.3310899,13.198321,0,0
28490122.66,,5905,3.71298,3.7815,0.174,9.3E-6,3.7237441,0.062577663,0,0,0.66510913,0.005313,0.66510913,0.005313,14.680115,0.17109311,0,100,,,1,,,,3.8874E-6,0.3280071,13.86627,0,0
28490169.89,,5905,3.72019,3.7835,0.174,9.4E-6,3.7323294,0.064184714,0,0,0.66774822,0.00513,0.66774822,0.00513,12.613891,0.17151367,0,100,,,1,,,,3.8933E-6,0.3402483,13.930283,0,0
28490217.22,,5905,3.72186,3.7868,0.174,9.3E-6,3.7341502,0.064760159,0,0,0.66883311,0.005312,0.66883311,0.005312,29.767125,0.17281343,0,100,,,1,,,,3.8703E-6,0.3441322,13.943878,0,0
28490264.48,,5905,3.72398,3.7891,0.174,9.3E-6,3.7359178,0.064982461,0,0,0.6677963,0.005236,0.6677963,0.005236,17.592793,0.17278264,0,100,,,1,,,,3.865E-6,0.3445209,13.957082,0,0
28490453.3,,5905,3.81597,3.8808,0.174,9.4E-6,3.8269094,0.065073557,0,0,0.70269571,0.00495,0.70269571,0.00495,24.299691,0.17583135,0,100,,,1,,,,3.9964E-6,0.3400651,14.645236,0,0
28490500.69,,5905,3.82008,3.8853,0.174,9.3E-6,3.8320072,0.066808189,0,0,0.70394365,0.005122,0.70394365,0.005122,49.986366,0.17781599,0,100,,,1,,,,3.9588E-6,0.35272,14.684279,0,0
28490548.77,,5905,3.82371,3.8913,0.174,9.4E-6,3.8356837,0.067027207,0,0,0.70343933,0.005166,0.70343933,0.005166,20.522778,0.17585713,0,100,,,1,,,,4.0001E-6,0.3559133,14.712469,0,0
28490596.22,,5905,3.82518,3.8907,0.174,9.4E-6,3.8382152,0.067007294,0,0,0.70307845,0.005487,0.70307845,0.005487,39.117898,0.17664427,0,100,,,1,,,,3.9802E-6,0.3532831,14.731896,0,0
28490785.55,,5905,3.91655,3.9843,0.174,9.4E-6,3.9283778,0.067311934,0,0,0.73991091,0.004996,0.73991091,0.004996,56.718769,0.18175931,0,100,,,1,,,,4.0708E-6,0.3492655,15.432152,0,0
28490832.91,,5905,3.91994,3.9866,0.174,9.4E-6,3.9336074,0.069321207,0,0,0.74182667,0,0.74182667,0,36.941815,0.182041,0,100,,,1,,,,4.0751E-6,0.3648512,15.473267,0,0
28490881.11,,5905,3.92421,3.992,0.174,9.4E-6,3.936691,0.069313727,0,0,0.74254847,0.004804,0.74254847,0.004804,17.873862,0.1815735,0,100,,,1,,,,4.0895E-6,0.3653304,15.497536,0,0
28490931.14,,5905,3.92635,3.9938,0.174,9.4E-6,3.938775,0.069515255,0,0,0.74119628,0.004864,0.74119628,0.004864,39.604706,0.18121131,0,100,,,1,,,,4.0902E-6,0.3655301,15.513949,0,0
28491121.25,,5905,4.018,4.0871,0.174,9.3E-6,4.0310923,0.070544211,0,0,0.78247213,0.00482,0.78247213,0.00482,39.12214,0.18877548,0,100,,,1,,,,4.145E-6,0.3667265,16.249705,0,0
28491169.13,,5905,4.02245,4.0915,0.174,9.4E-6,4.0350336,0.072003519,0,0,0.78242156,0.004591,0.78242156,0.004591,33.902305,0.1884258,0,100,,,1,,,,4.1524E-6,0.3771428,16.281496,0,0
28491220.61,,5905,4.02549,4.0941,0.174,9.3E-6,4.0388454,0.072047738,0,0,0.78317564,0.004963,0.78317564,0.004963,7.7693739,0.18771833,0,100,,,1,,,,4.1721E-6,0.3781015,16.312272,0,0
28491267.72,,5905,4.02869,4.0983,0.174,9.3E-6,4.041814,0.071801353,0,0,0.78301285,0.00492,0.78301285,0.00492,21.032063,0.18772941,0,100,,,1,,,,4.171E-6,0.3747519,16.336261,0,0
28491456.73,,5905,4.12042,4.1913,0.174,9.3E-6,4.1327291,0.07261992,0,0,0.82320385,0.004732,0.82320385,0.004732,11.453529,0.19321654,0,100,,,1,,,,4.2605E-6,0.3744696,17.07945,0,0
28491503.8,,5905,4.12381,4.1938,0.174,9.3E-6,4.1376534,0.07442049,0,0,0.8253527,0.004934,0.8253527,0.004934,19.760792,0.19439317,0,100,,,1,,,,4.2458E-6,0.3887798,17.120176,0,0
28491550.83,,5905,4.12707,4.198,0.174,9.4E-6,4.1411235,0.074394344,0,0,0.82452644,0.004802,0.82452644,0.004802,28.074063,0.19319195,0,100,,,1,,,,4.2679E-6,0.3885972,17.148904,0,0
28491597.89,,5905,4.13007,4.2016,0.174,9.3E-6,4.1427968,0.07419211,0,0,0.8240216,0,0.8240216,0,52.527064,0.19268514,0,100,,,1,,,,4.2765E-6,0.3864965,17.162766,0,0
28491789.45,,5905,4.22134,4.2923,0.174,9.4E-6,4.2337191,0.074947291,0,0,0.86589418,0.004759,0.86589418,0.004759,13.188014,0.19848501,0,100,,,1,,,,4.3625E-6,0.3855824,17.924377,0,0
28491837,,5905,4.22573,4.2997,0.174,9.3E-6,4.2393495,0.076564918,0,0,0.86775118,0.00463,0.86775118,0.00463,22.626563,0.19854463,0,100,,,1,,,,4.3706E-6,0.3982544,17.972084,0,0
28491884.06,,5905,4.22843,4.301,0.174,9.3E-6,4.2423167,0.076975608,0,0,0.87038112,0.004957,0.87038112,0.004957,10.145401,0.2006477,0,100,,,1,,,,4.3379E-6,0.3999976,17.997251,0,0
28491931.02,,5905,4.23076,4.2995,0.174,9.3E-6,4.2440734,0.076659136,0,0,0.86951246,0.004741,0.86951246,0.004741,10.051502,0.19892839,0,100,,,1,,,,4.371E-6,0.3975107,18.012159,0,0
28492116.36,,5905,4.32201,4.3928,0.174,9.4E-6,4.3355845,0.077420846,0,0,0.91328413,0.00445,0.91328413,0.00445,16.274679,0.20479264,0,100,,,1,,,,4.4596E-6,0.3975308,18.797293,0,0
28492163.91,,5905,4.32652,4.3979,0.174,9.4E-6,4.3404129,0.079199045,0,0,0.91450663,0.004493,0.91450663,0.004493,19.914782,0.20537259,0,100,,,1,,,,4.4529E-6,0.4100829,18.839184,0,0
28492214.03,,5905,4.33313,4.4003,0.174,9.3E-6,4.3486311,0.079480796,0,0,0.91789333,0.004383,0.91789333,0.004383,9.5274361,0.20539335,0,100,,,1,,,,4.469E-6,0.4126719,18.910592,0,0
28492261.2,,5905,4.33421,4.3992,0.174,9.4E-6,4.3497557,0.079588032,0,0,0.91710065,0.004441,0.91710065,0.004441,12.445044,0.20517948,0,100,,,1,,,,4.4697E-6,0.4126057,18.920375,0,0
28492451.75,,5905,4.42475,4.494,0.174,9.3E-6,4.4407971,0.080415501,0,0,0.96483406,0.005104,0.96483406,0.005104,16.413904,0.21273745,0,100,,,1,,,,4.5353E-6,0.4117515,19.720679,0,0
28492500.94,,5905,4.42927,4.4952,0.174,9.4E-6,4.445636,0.082156799,0,0,0.96546134,0.00454,0.96546134,0.00454,10.550252,0.21144053,0,100,,,1,,,,4.5661E-6,0.4267542,19.76368,0,0
28492550.22,,5905,4.43286,4.5024,0.174,9.3E-6,4.4484121,0.081826983,0,0,0.96556824,0.004553,0.96556824,0.004553,6.7398958,0.21094916,0,100,,,1,,,,4.5773E-6,0.4229204,19.78837,0,0
28492599.45,,5905,4.4347,4.5041,0.174,9.3E-6,4.4509288,0.082127648,0,0,0.96734716,0.004867,0.96734716,0.004867,8.227327,0.21166021,0,100,,,1,,,,4.5703E-6,0.424752,19.810767,0,0
28492786.72,,5905,4.52505,4.5976,0.174,9.3E-6,4.5404293,0.082947255,0,0,1.0139976,0.004677,1.0139976,0.004677,9.7288445,0.21901303,0,100,,,1,,,,4.6299E-6,0.4233951,20.615498,0,0
28492836.55,,5905,4.53036,4.6031,0.174,9.4E-6,4.5461168,0.084721531,0,0,1.0182952,0.004486,1.0182952,0.004486,18.542909,0.21923121,0,100,,,1,,,,4.6448E-6,0.4389,20.667178,0,0
28492885.53,,5905,4.5327,4.6037,0.174,9.3E-6,4.5497087,0.084280427,0,0,1.0158513,0.004614,1.0158513,0.004614,14.199026,0.21773655,0,100,,,1,,,,4.6655E-6,0.4352745,20.699849,0,0
28492934.8,,5905,4.53534,4.6074,0.174,9.3E-6,4.5522385,0.084540769,0,0,1.0179389,0.004489,1.0179389,0.004489,10.852969,0.2183388,0,100,,,1,,,,4.6622E-6,0.4372268,20.722875,0,0
28493126.56,,5905,4.6273,4.7,0.174,9.4E-6,4.6425733,0.085438176,0,0,1.0659624,0.004264,1.0659624,0.004264,11.769761,0.22353469,0,100,,,1,,,,4.7687E-6,0.4384752,21.553486,0,0
28493176.5,,5905,4.63061,4.7064,0.174,9.3E-6,4.6469825,0.08666717,0,0,1.0684644,0.004719,1.0684644,0.004719,6.3557517,0.22569785,0,100,,,1,,,,4.734E-6,0.4460589,21.594446,0,0
28493225.91,,5905,4.63458,4.7073,0.174,9.3E-6,4.6509836,0.086743542,0,0,1.0700042,0.004644,1.0700042,0.004644,9.8653331,0.22441029,0,100,,,1,,,,4.7681E-6,0.4488622,21.631648,0,0
28493275.05,,5905,4.63775,4.7132,0.174,9.4E-6,4.6528333,0.086650985,0,0,1.069411,0.004374,1.069411,0.004374,7.5010723,0.22349172,0,100,,,1,,,,4.785E-6,0.4476371,21.648858,0,0
28493466.11,,5905,4.72712,4.8048,0.174,9.4E-6,4.7424432,0.087458494,0,0,1.122097,0.005339,1.122097,0.005339,8.2653514,0.229985,0,100,,,1,,,,4.879E-6,0.4497108,22.490767,0,0
28493515.2,,5905,4.7324,4.8098,0.174,9.4E-6,4.7479481,0.088720848,0,0,1.1243527,0.004773,1.1243527,0.004773,16.031481,0.23147408,0,100,,,1,,,,4.8574E-6,0.4573868,22.543011,0,0
28493564.47,,5905,4.73545,4.813,0.174,9.4E-6,4.7518051,0.089146962,0,0,1.1258111,0.004169,1.1258111,0.004169,7.2912983,0.23040926,0,100,,,1,,,,4.8861E-6,0.4617561,22.579652,0,0
28493613.69,,5905,4.73962,4.8184,0.174,9.3E-6,4.755285,0.089300967,0,0,1.1260392,0.004876,1.1260392,0.004876,9.5011239,0.2307554,0,100,,,1,,,,4.8798E-6,0.4618145,22.612736,0,0
28493799.95,,5905,4.82749,4.9079,0.174,9.3E-6,4.8456424,0.089477221,0,0,1.180677,0.004185,1.180677,0.004185,31.467233,0.23533964,0,100,,,1,,,,5.0169E-6,0.4625855,23.48025,0,0
28493847.36,,5905,4.83295,4.9157,0.174,9.3E-6,4.850887,0.091059808,0,0,1.1855809,0.004177,1.1855809,0.004177,22.388077,0.23712819,0,100,,,1,,,,4.9997E-6,0.4744868,23.531104,0,0
28493895,,5905,4.83665,4.918,0.174,9.3E-6,4.8557165,0.091176355,0,0,1.1865694,0.004284,1.1865694,0.004284,35.50772,0.2371869,0,100,,,1,,,,5.0027E-6,0.47473,23.577983,0,0
28493942.61,,5905,4.83859,4.9198,0.174,9.3E-6,4.857547,0.091267189,0,0,1.1901221,0.00438,1.1901221,0.00438,27.872537,0.23877466,0,100,,,1,,,,4.9843E-6,0.4739843,23.595763,0,0
28494127.17,,5905,4.92917,5.0133,0.174,9.4E-6,4.9472859,0.091553201,0,0,1.2448454,0.004366,1.2448454,0.004366,39.498585,0.24335775,0,100,,,1,,,,5.1153E-6,0.473611,24.475638,0,0
28494174.94,,5905,4.93424,5.0178,0.174,9.3E-6,4.952972,0.09320642,0,0,1.2500694,0.004386,1.2500694,0.004386,31.497607,0.24428007,0,100,,,1,,,,5.1174E-6,0.4876954,24.531932,0,0
28494222.73,,5905,4.9383,5.0207,0.174,9.3E-6,4.9572816,0.093490444,0,0,1.2508449,0.004549,1.2508449,0.004549,27.174336,0.24540537,0,100,,,1,,,,5.0971E-6,0.4881574,24.574641,0,0
28494270.39,,5905,4.94156,5.0258,0.174,9.3E-6,4.960521,0.09364034,0,0,1.2504885,0.004302,1.2504885,0.004302,27.069117,0.24288375,0,100,,,1,,,,5.1485E-6,0.4910763,24.606769,0,0
28494455.09,,5905,5.02962,5.1162,0.174,9.3E-6,5.0473474,0.094051698,0,0,1.309643,0.004348,1.309643,0.004348,10.41752,0.2494778,0,100,,,1,,,,5.2495E-6,0.4908843,25.475716,0,0
28494502.58,,5905,5.03491,5.1195,0.174,9.4E-6,5.0548901,0.095282748,0,0,1.3151314,0.004392,1.3151314,0.004392,47.417822,0.25103952,0,100,,,1,,,,5.2387E-6,0.5010309,25.551914,0,0
28494550.3,,5905,5.0386,5.1241,0.174,9.4E-6,5.0576042,0.095516095,0,0,1.3149218,0.004525,1.3149218,0.004525,15.325776,0.25060611,0,100,,,1,,,,5.247E-6,0.501733,25.57936,0,0
28494597.86,,5905,5.04161,5.1263,0.174,9.4E-6,5.0616861,0.095206419,0,0,1.3172296,0.004395,1.3172296,0.004395,12.080934,0.25021692,0,100,,,1,,,,5.2644E-6,0.4999818,25.620666,0,0
28494782.44,,5905,5.13117,5.217,0.174,9.3E-6,5.1498722,0.095708901,0,0,1.3768216,0.004391,1.3768216,0.004391,13.19163,0.25612929,0,100,,,1,,,,5.3755E-6,0.5009497,26.521183,0,0
28494831.33,,5905,5.13684,5.2257,0.174,9.3E-6,5.1563408,0.097120564,0,0,1.3811785,0.004283,1.3811785,0.004283,17.021941,0.25637541,0,100,,,1,,,,5.3873E-6,0.5124031,26.58785,0,0
28494880.08,,5905,5.14113,5.2296,0.174,9.4E-6,5.1600759,0.097841645,0,0,1.3829142,0.004488,1.3829142,0.004488,44.411823,0.25754572,0,100,,,1,,,,5.3696E-6,0.5171141,26.626383,0,0
28494930.36,,5905,5.14399,5.2301,0.174,9.3E-6,5.1640939,0.097376191,0,0,1.3853431,0.004726,1.3853431,0.004726,52.375275,0.25781474,0,100,,,1,,,,5.3734E-6,0.5130386,26.667866,0,0
28495115.59,,5905,5.23256,5.3195,0.174,9.4E-6,5.2517555,0.09830681,0,0,1.4478973,0.004747,1.4478973,0.004747,13.268515,0.26479458,0,100,,,1,,,,5.468E-6,0.5165377,27.580936,0,0
28495163.45,,5905,5.23801,5.3254,0.174,9.3E-6,5.2577635,0.099457447,0,0,1.4521482,0.004578,1.4521482,0.004578,9.2035507,0.26472908,0,100,,,1,,,,5.4854E-6,0.5269551,27.644077,0,0
28495211.47,,5905,5.24355,5.3332,0.174,9.4E-6,5.2630393,0.099894669,0,0,1.453837,0.004649,1.453837,0.004649,14.992687,0.26379756,0,100,,,1,,,,5.5112E-6,0.5312591,27.699583,0,0
28495262.73,,5905,5.24581,5.3334,0.174,9.4E-6,5.2652993,0.099806121,0,0,1.4559451,0.00485,1.4559451,0.00485,10.513539,0.26513626,0,100,,,1,,,,5.4913E-6,0.5280672,27.723376,0,0
28495448.27,,5905,5.33388,5.4245,0.174,9.4E-6,5.3540563,0.10036193,0,0,1.5204475,0.004769,1.5204475,0.004769,14.828511,0.2699217,0,100,,,1,,,,5.6329E-6,0.5325798,28.665919,0,0
28495496.14,,5905,5.33933,5.4278,0.174,9.3E-6,5.3598792,0.10157041,0,0,1.5264511,0.005108,1.5264511,0.005108,11.362086,0.27188081,0,100,,,1,,,,5.6144E-6,0.5407877,28.728305,0,0
28495544.02,,5905,5.3435,5.4312,0.174,9.4E-6,5.364392,0.10194216,0,0,1.5287165,0.004903,1.5287165,0.004903,21.059405,0.27240504,0,100,,,1,,,,5.6119E-6,0.5435572,28.776702,0,0
28495591.72,,5905,5.34678,5.435,0.174,9.4E-6,5.3678606,0.10197345,0,0,1.5299881,0.004914,1.5299881,0.004914,19.107729,0.27289299,0,100,,,1,,,,5.6065E-6,0.5422648,28.813927,0,0
28495777.5,,5905,5.43534,5.5234,0.174,9.4E-6,5.4553803,0.10235418,0,0,1.5994538,0.004809,1.5994538,0.004809,14.599434,0.27813603,0,100,,,1,,,,5.7506E-6,0.5454714,29.761174,0,0
28495825.36,,5905,5.44132,5.528,0.174,9.3E-6,5.4621349,0.10404835,0,0,1.6036422,0.005211,1.6036422,0.005211,36.637621,0.27954138,0,100,,,1,,,,5.7367E-6,0.5584642,29.834918,0,0
28495873.05,,5905,5.44557,5.5342,0.174,9.4E-6,5.4667208,0.10381761,0,0,1.6077376,0.005233,1.6077376,0.005233,11.921891,0.27943235,0,100,,,1,,,,5.7536E-6,0.5571592,29.885036,0,0
28495921.42,,5905,5.44897,5.5374,0.174,9.4E-6,5.4698717,0.10403743,0,0,1.607868,0.004756,1.607868,0.004756,19.501682,0.2788185,0,100,,,1,,,,5.7667E-6,0.5586854,29.919497,0,0
28496107.25,,5905,5.53786,5.6262,0.174,9.4E-6,5.5581548,0.10440148,0,0,1.6814139,0.005249,1.6814139,0.005249,7.8036082,0.28605197,0,100,,,1,,,,5.878E-6,0.5600763,30.893085,0,0
28496155.11,,5905,5.5432,5.6313,0.174,9.3E-6,5.5651555,0.10579896,0,0,1.6846351,0.004932,1.6846351,0.004932,14.863486,0.28615545,0,100,,,1,,,,5.8871E-6,0.5715204,30.970956,0,0
28496202.72,,5905,5.54706,5.6353,0.174,9.4E-6,5.5693727,0.10572655,0,0,1.686838,0.00516,1.686838,0.00516,28.365426,0.28610058,0,100,,,1,,,,5.896E-6,0.5702072,31.017912,0,0
28496250.5,,5905,5.55147,5.6395,0.174,9.3E-6,5.5720195,0.10562097,0,0,1.6898152,0.004963,1.6898152,0.004963,13.682041,0.28596439,0,100,,,1,,,,5.9092E-6,0.5699859,31.047401,0,0
28496436.3,,5905,5.63965,5.7291,0.174,9.3E-6,5.6603523,0.10667671,0,0,1.7628944,0.005485,1.7628944,0.005485,20.948187,0.29371322,0,100,,,1,,,,6.0021E-6,0.5760224,32.039588,0,0
28496483.94,,5905,5.64495,5.7333,0.174,9.3E-6,5.6665278,0.1080256,0,0,1.76719,0.00539,1.76719,0.00539,27.0305,0.29381581,0,100,,,1,,,,6.0146E-6,0.5876202,32.109538,0,0
28496531.78,,5905,5.64897,5.7369,0.174,9.3E-6,5.6710709,0.10823485,0,0,1.7698313,0.005159,1.7698313,0.005159,8.8183928,0.29423308,0,100,,,1,,,,6.0151E-6,0.5887478,32.161045,0,0
28496579.38,,5905,5.65244,5.7405,0.174,9.3E-6,5.6740565,0.10816632,0,0,1.7746176,0.005414,1.7746176,0.005414,21.927855,0.29498353,0,100,,,1,,,,6.016E-6,0.5881465,32.194917,0,0
28496764.41,,5905,5.74162,5.8292,0.174,9.4E-6,5.7624378,0.1084156,0,0,1.8484234,0.005527,1.8484234,0.005527,26.202606,0.30119216,0,100,,,1,,,,6.137E-6,0.5878548,33.20569,0,0
28496812.55,,5905,5.74744,5.8376,0.174,9.4E-6,5.7685934,0.11016105,0,0,1.8533428,0.005373,1.8533428,0.005373,28.462138,0.30073095,0,100,,,1,,,,6.1628E-6,0.6045061,33.27667,0,0
28496860.25,,5905,5.75138,5.8404,0.174,9.3E-6,5.7723715,0.11001362,0,0,1.8564853,0.005826,1.8564853,0.005826,8.3160354,0.3029462,0,100,,,1,,,,6.1281E-6,0.6007203,33.320273,0,0
28496908.14,,5905,5.75331,5.8416,0.174,9.3E-6,5.7752686,0.11046439,0,0,1.8617867,0.005681,1.8617867,0.005681,25.361877,0.30321242,0,100,,,1,,,,6.1402E-6,0.605177,33.353728,0,0
28497094.31,,5905,5.84304,5.9342,0.174,9.3E-6,5.8640713,0.11044544,0,0,1.9385309,0.005823,1.9385309,0.005823,20.195649,0.30949733,0,100,,,1,,,,6.2635E-6,0.6022523,34.387332,0,0
28497142.97,,5905,5.84858,5.9394,0.174,9.3E-6,5.8705894,0.11206332,0,0,1.9442507,0.005675,1.9442507,0.005675,13.035887,0.30956998,0,100,,,1,,,,6.2805E-6,0.6181818,34.46382,0,0
28497191.81,,5905,5.85215,5.9402,0.174,9.3E-6,5.8744284,0.11224443,0,0,1.9492498,0.005911,1.9492498,0.005911,6.8508475,0.30960093,0,100,,,1,,,,6.296E-6,0.619894,34.508909,0,0
28497239.94,,5905,5.85615,5.9471,0.174,9.4E-6,5.8777997,0.11174481,0,0,1.9461841,0.005468,1.9461841,0.005468,13.097763,0.30763081,0,100,,,1,,,,6.3264E-6,0.6160469,34.548529,0,0
28497428.31,,5905,5.94353,6.0354,0.174,9.3E-6,5.964928,0.11214737,0,0,2.0294918,0.005924,2.0294918,0.005924,8.9543083,0.31633109,0,100,,,1,,,,6.4157E-6,0.6165033,35.580366,0,0
28497478.13,,5905,5.949,6.041,0.174,9.3E-6,5.971771,0.11393638,0,0,2.0339748,0.005929,2.0339748,0.005929,23.375601,0.31606494,0,100,,,1,,,,6.4353E-6,0.6328073,35.662049,0,0
28497526.45,,5905,5.95441,6.0455,0.174,9.4E-6,5.9767927,0.1139091,0,0,2.0399595,0.006045,2.0399595,0.006045,14.457593,0.31692794,0,100,,,1,,,,6.4367E-6,0.6329073,35.722052,0,0
28497574.48,,5905,5.95717,6.0485,0.174,9.4E-6,5.9799096,0.11438395,0,0,2.039512,0.005459,2.039512,0.005459,20.316502,0.31677019,0,100,,,1,,,,6.4385E-6,0.6348883,35.759319,0,0
28497758.45,,5905,6.045,6.1399,0.174,9.3E-6,6.0669276,0.11392785,0,0,2.124451,0.006102,2.124451,0.006102,11.68075,0.32398619,0,100,,,1,,,,6.5572E-6,0.6296978,36.807611,0,0
28497806.61,,5905,6.05023,6.1435,0.174,9.4E-6,6.0732792,0.11559492,0,0,2.1307884,0.006031,2.1307884,0.006031,16.378138,0.32395432,0,100,,,1,,,,6.5774E-6,0.645577,36.88472,0,0
28497854.22,,5905,6.05473,6.1491,0.174,9.3E-6,6.0778649,0.11586311,0,0,2.1346032,0.005997,2.1346032,0.005997,22.86007,0.32387537,0,100,,,1,,,,6.5908E-6,0.6481767,36.940442,0,0
28497902.58,,5905,6.05826,6.1523,0.174,9.3E-6,6.0809769,0.11591018,0,0,2.1358761,0.00596,2.1358761,0.00596,12.080453,0.32395735,0,100,,,1,,,,6.5931E-6,0.6476944,36.97828,0,0
28498088.34,,5905,6.1456,6.242,0.174,9.3E-6,6.16831,0.11672877,0,0,2.2203929,0.006273,2.2203929,0.006273,11.337208,0.33071404,0,100,,,1,,,,6.7139E-6,0.6527166,38.048049,0,0
28498136.83,,5905,6.15146,6.2489,0.174,9.3E-6,6.1739027,0.11780202,0,0,2.2259234,0.006202,2.2259234,0.006202,13.370972,0.33216813,0,100,,,1,,,,6.7012E-6,0.6613893,38.117075,0,0
28498184.5,,5905,6.15594,6.255,0.174,9.3E-6,6.1790301,0.11789931,0,0,2.2308221,0.006516,2.2308221,0.006516,11.03983,0.33309408,0,100,,,1,,,,6.6973E-6,0.6612287,38.180412,0,0
28498232.23,,5905,6.15944,6.2565,0.174,9.3E-6,6.182614,0.11840426,0,0,2.2342866,0.006483,2.2342866,0.006483,8.0774642,0.33300217,0,100,,,1,,,,6.7095E-6,0.666839,38.224716,0,0
28498417.47,,5905,6.2468,6.3466,0.174,9.3E-6,6.2692443,0.11820141,0,0,2.3185278,0.006557,2.3185278,0.006557,8.3601262,0.33825319,0,100,,,1,,,,6.8544E-6,0.6633982,39.303425,0,0
28498465.33,,5905,6.25251,6.3516,0.174,9.4E-6,6.2764605,0.11997908,0,0,2.3255514,0.006576,2.3255514,0.006576,11.484731,0.33970076,0,100,,,1,,,,6.8459E-6,0.6787881,39.393956,0,0
28498514.13,,5905,6.25709,6.3547,0.174,9.3E-6,6.2813084,0.12032984,0,0,2.3310162,0.006785,2.3310162,0.006785,16.966637,0.3399216,0,100,,,1,,,,6.8575E-6,0.6823911,39.454836,0,0
28498561.89,,5905,6.26071,6.3597,0.174,9.4E-6,6.2842018,0.1203592,0,0,2.3352044,0.007201,2.3352044,0.007201,20.764684,0.34214596,0,100,,,1,,,,6.8252E-6,0.6799493,39.491192,0,0
28498747.53,,5905,6.34869,6.4497,0.174,9.3E-6,6.3711137,0.12042666,0,0,2.4201613,0.006477,2.4201613,0.006477,10.613714,0.34607769,0,100,,,1,,,,6.9931E-6,0.6809287,40.59109,0,0
28498795.41,,5905,6.35424,6.4555,0.174,9.4E-6,6.3787448,0.12205631,0,0,2.428614,0.00708,2.428614,0.00708,13.425183,0.34804965,0,100,,,1,,,,6.9778E-6,0.6944603,40.688386,0,0
28498843.17,,5905,6.35863,6.4579,0.174,9.3E-6,6.3831114,0.12224286,0,0,2.4338767,0.006945,2.4338767,0.006945,11.111195,0.34900866,0,100,,,1,,,,6.9737E-6,0.6945985,40.744111,0,0
28498890.89,,5905,6.36316,6.466,0.174,9.3E-6,6.3864623,0.12216449,0,0,2.4340518,0.006728,2.4340518,0.006728,11.362871,0.34754634,0,100,,,1,,,,7.0035E-6,0.6949149,40.7869,0,0
28499077.7,,5905,6.44977,6.5508,0.174,9.3E-6,6.4728505,0.12274384,0,0,2.5255595,0.007292,2.5255595,0.007292,12.48068,0.35397457,0,100,,,1,,,,7.1349E-6,0.6993383,41.897794,0,0
28499125.5,,5905,6.45602,6.5588,0.174,9.3E-6,6.4799955,0.12451293,0,0,2.5294052,0.007013,2.5294052,0.007013,15.144785,0.35485753,0,100,,,1,,,,7.1279E-6,0.713757,41.990341,0,0
28499173.48,,5905,6.46008,6.5637,0.174,9.4E-6,6.4838932,0.12386313,0,0,2.5338567,0.006968,2.5338567,0.006968,7.1740835,0.3538584,0,100,,,1,,,,7.1607E-6,0.708725,42.040872,0,0
28499221.36,,5905,6.46293,6.5649,0.174,9.4E-6,6.4878817,0.12466341,0,0,2.5448401,0.00788,2.5448401,0.00788,8.6916427,0.35715253,0,100,,,1,,,,7.1254E-6,0.715158,42.092609,0,0
28499410.97,,5905,6.55172,6.6562,0.174,9.4E-6,6.5757566,0.12468943,0,0,2.6328195,0.00742,2.6328195,0.00742,12.746709,0.36147036,0,100,,,1,,,,7.2836E-6,0.7140191,43.240575,0,0
28499459.88,,5905,6.55833,6.6593,0.174,9.3E-6,6.5829699,0.12616619,0,0,2.6402189,0.007428,2.6402189,0.007428,10.458848,0.36257901,0,100,,,1,,,,7.2818E-6,0.7273536,43.335493,0,0
28499507.89,,5905,6.56309,6.6653,0.174,9.3E-6,6.5870474,0.1262161,0,0,2.6489064,0.007809,2.6489064,0.007809,5.8460975,0.36458935,0,100,,,1,,,,7.2655E-6,0.726497,43.389194,0,0
28499555.77,,5905,6.56617,6.6661,0.174,9.3E-6,6.5904237,0.12600033,0,0,2.6534713,0.00765,2.6534713,0.00765,18.274354,0.36430723,0,100,,,1,,,,7.2836E-6,0.7251939,43.433685,0,0
28499741.56,,5905,6.65298,6.7544,0.174,9.3E-6,6.6776829,0.12637641,0,0,2.7470633,0.007889,2.7470633,0.007889,12.196217,0.37101862,0,100,,,1,,,,7.4041E-6,0.7255015,44.591449,0,0
28499789.48,,5905,6.66011,6.7623,0.174,9.3E-6,6.6846713,0.1283829,0,0,2.7573501,0.007822,2.7573501,0.007822,21.815762,0.37185103,0,100,,,1,,,,7.4152E-6,0.7456052,44.684831,0,0
28499837.36,,5905,6.66398,6.7648,0.174,9.3E-6,6.6894626,0.12828282,0,0,2.7614993,0.00761,2.7614993,0.00761,10.379964,0.37199478,0,100,,,1,,,,7.4235E-6,0.7441417,44.74891,0,0
28499885.52,,5905,6.66788,6.7694,0.174,9.3E-6,6.6925322,0.1284495,0,0,2.7650747,0.0076,2.7650747,0.0076,14.480112,0.37216385,0,100,,,1,,,,7.4297E-6,0.7452954,44.789987,0,0
28500071.84,,5905,6.75369,6.8549,0.174,9.3E-6,6.7787359,0.12862362,0,0,2.8614901,0.00826,2.8614901,0.00826,15.161509,0.37899915,0,100,,,1,,,,7.5501E-6,0.7443226,45.95126,0,0
28500120.95,,5905,6.76131,6.8637,0.174,9.3E-6,6.7869958,0.12992692,0,0,2.8708478,0.007605,2.8708478,0.007605,9.2817909,0.37841324,0,100,,,1,,,,7.5865E-6,0.7588556,46.063312,0,0
28500168.84,,5905,6.76518,6.8658,0.174,9.3E-6,6.7907652,0.13049326,0,0,2.8780355,0.008576,2.8780355,0.008576,19.248837,0.38104192,0,100,,,1,,,,7.5531E-6,0.7616453,46.114493,0,0
28500216.78,,5905,6.76847,6.8698,0.174,9.4E-6,6.7946917,0.13076951,0,0,2.8823836,0.009259,2.8823836,0.009259,11.236501,0.38139714,0,100,,,1,,,,7.5574E-6,0.7645399,46.167836,0,0
28500404.91,,5905,6.85695,6.9591,0.174,9.4E-6,6.8819265,0.1306995,0,0,2.9785714,0.00827,2.9785714,0.00827,8.6674185,0.38739269,0,100,,,1,,,,7.6888E-6,0.7598615,47.360913,0,0
28500452.86,,5905,6.86389,6.9637,0.174,9.4E-6,6.8884834,0.13232386,0,0,2.988241,0.008465,2.988241,0.008465,8.6166297,0.38969148,0,100,,,1,,,,7.6682E-6,0.7740125,47.451204,0,0
28500501.8,,5905,6.86777,6.9683,0.174,9.4E-6,6.8931399,0.13233901,0,0,2.9950614,0.008327,2.9950614,0.008327,13.935908,0.38921754,0,100,,,1,,,,7.6951E-6,0.7754704,47.515378,0,0
28500550.75,,5905,6.87074,6.9719,0.174,9.4E-6,6.8970309,0.13283757,0,0,2.9985134,0.00857,2.9985134,0.00857,10.02686,0.38966569,0,100,,,1,,,,7.6951E-6,0.7801926,47.569036,0,0
28500736.7,,5905,6.95803,7.058,0.174,9.3E-6,6.9840652,0.13286215,0,0,3.0998761,0.008998,3.0998761,0.008998,13.437388,0.39702566,0,100,,,1,,,,7.8077E-6,0.7761338,48.777167,0,0
28500784.61,,5905,6.96475,7.0663,0.174,9.3E-6,6.9908774,0.13402714,0,0,3.1045418,0.007925,3.1045418,0.007925,9.8898697,0.39414705,0,100,,,1,,,,7.8766E-6,0.7903917,48.872367,0,0
28500832.59,,5905,6.9695,7.0691,0.174,9.3E-6,6.9956425,0.13489625,0,0,3.1117651,0.009222,3.1117651,0.009222,12.18037,0.39725979,0,100,,,1,,,,7.8331E-6,0.7959154,48.939014,0,0
28500880.7,,5905,6.97231,7.0718,0.174,9.3E-6,6.9990269,0.13468135,0,0,3.1175891,0.008925,3.1175891,0.008925,12.113527,0.39683357,0,100,,,1,,,,7.8562E-6,0.7949659,48.986378,0,0
28501065.88,,5905,7.06024,7.1606,0.174,9.4E-6,7.0862964,0.13474088,0,0,3.2226271,0.008962,3.2226271,0.008962,9.3468007,0.40284914,0,100,,,1,,,,7.9996E-6,0.793443,50.215597,0,0
28501113.92,,5905,7.06596,7.1668,0.174,9.4E-6,7.0932681,0.13666766,0,0,3.2314708,0.009323,3.2314708,0.009323,16.30207,0.40575007,0,100,,,1,,,,7.9642E-6,0.8095983,50.314453,0,0
28501161.98,,5905,7.07024,7.1682,0.174,9.4E-6,7.0974168,0.13644673,0,0,3.2366967,0.0094,3.2366967,0.0094,7.6669748,0.40572406,0,100,,,1,,,,7.9776E-6,0.8073352,50.373326,0,0
28501210.05,,5905,7.07381,7.1706,0.174,9.4E-6,7.1007912,0.13633542,0,0,3.2402782,0.009124,3.2402782,0.009124,8.7931104,0.40500962,0,100,,,1,,,,8.0005E-6,0.8074512,50.421236,0,0
28501396.41,,5905,7.16141,7.2633,0.174,9.4E-6,7.1886182,0.13731023,0,0,3.3476004,0.009049,3.3476004,0.009049,9.9476873,0.41294394,0,100,,,1,,,,8.1067E-6,0.8129143,51.676232,0,0
28501444.59,,5905,7.16734,7.2694,0.174,9.3E-6,7.1955223,0.13875392,0,0,3.3582553,0.009086,3.3582553,0.009086,8.160887,0.41347386,0,100,,,1,,,,8.122E-6,0.8279809,51.775541,0,0
28501492.98,,5905,7.17193,7.2736,0.174,9.4E-6,7.1996785,0.13885447,0,0,3.364458,0.009576,3.364458,0.009576,13.487544,0.41343256,0,100,,,1,,,,8.1379E-6,0.8290525,51.835371,0,0
28501541.22,,5905,7.17617,7.2778,0.174,9.3E-6,7.2039595,0.13887726,0,0,3.3652732,0.009175,3.3652732,0.009175,6.5253907,0.41318539,0,100,,,1,,,,8.1447E-6,0.828307,51.897033,0,0
28501726.25,,5905,7.2627,7.3654,0.174,9.4E-6,7.2898935,0.13901589,0,0,3.4756521,0.009701,3.4756521,0.009701,8.6975356,0.42029904,0,100,,,1,,,,8.2695E-6,0.8270505,53.142547,0,0
28501774.59,,5905,7.26881,7.3722,0.174,9.3E-6,7.2963444,0.14084367,0,0,3.4860288,0.0099,3.4860288,0.0099,8.6909271,0.42179578,0,100,,,1,,,,8.2647E-6,0.8442829,53.236642,0,0
28501822.75,,5905,7.27352,7.3762,0.174,9.3E-6,7.3015902,0.14066358,0,0,3.495457,0.009993,3.495457,0.009993,10.300771,0.42234794,0,100,,,1,,,,8.2762E-6,0.8431209,53.313219,0,0
28501870.94,,5905,7.2773,7.3795,0.174,9.4E-6,7.3054907,0.14079785,0,0,3.4965918,0.009858,3.4965918,0.009858,7.4805252,0.42051168,0,100,,,1,,,,8.3151E-6,0.8460405,53.370194,0,0
[...]
28721012.38,,5905,106.615,106.586,89998.602,9.3E-6,107.51661,2.1255665,0,0,1994.4166,2.503,1994.4166,2.503,2.3678052,22.124018,0,100,,,1,,,,9.0147E-5,44.42199,11559.821,0,0
28721721.25,,5905,111.731,111.706,89998.602,9.3E-6,112.46814,2.0838719,0,0,2188.8958,3.711,2188.8958,3.711,0.18356164,23.851138,0,100,,,1,,,,9.1773E-5,44.24804,12649.084,0,0
28721910.58,,5905,111.701,111.682,89998.602,9.3E-6,112.63114,2.2436778,0,0,2192.7021,2.832,2192.7021,2.832,41.89188,23.56293,0,100,,,1,,,,9.3057E-5,47.70228,12685.775,0,0
28722098.98,,5905,111.718,111.675,89998.602,9.3E-6,112.64651,2.2280084,0,0,2192.9432,2.643,2192.9432,2.643,1.3494067,23.502204,0,100,,,1,,,,9.3308E-5,47.12586,12689.236,0,0
28722832.16,,5905,116.8,116.792,89998.602,9.3E-6,117.61402,2.1868599,0,0,2395.4658,3.92,2395.4658,3.92,0.20632506,25.177568,0,100,,,1,,,,9.5143E-5,47.00441,13833.058,0,0
28723032.92,,5905,116.789,116.778,89998.602,9.3E-6,117.76782,2.3443904,0,0,2398.5513,2.912,2398.5513,2.912,37.605151,24.865491,0,100,,,1,,,,9.6461E-5,50.35514,13869.258,0,0
28723229.66,,5905,116.793,116.765,89998.602,9.3E-6,117.78617,2.3284554,0,0,2397.778,2.764,2397.778,2.764,1.1976202,24.786828,0,100,,,1,,,,9.6736E-5,49.73098,13873.581,0,0
28723958.28,,5905,121.902,121.886,89998.602,9.3E-6,122.74431,2.2886348,0,0,2605.7463,4.105,2605.7463,4.105,0.1627205,26.479776,0,100,,,1,,,,9.8405E-5,49.57366,15066.167,0,0
28724166.73,,5905,121.894,121.859,89998.602,9.4E-6,122.90616,2.4459568,0,0,2608.3161,3.065,2608.3161,3.065,21.909092,26.126155,0,100,,,1,,,,9.9835E-5,52.95955,15105.925,0,0
28724372.97,,5905,121.881,121.853,89998.602,9.4E-6,122.91807,2.4265079,0,0,2608.4945,2.901,2608.4945,2.901,1.5474144,26.063558,0,100,,,1,,,,0.00010008,52.25231,15108.852,0,0
28725100.17,,5905,126.987,126.973,89998.602,9.4E-6,127.88802,2.3953677,0,0,2819.0584,4.527,2819.0584,4.527,0.16848878,27.716453,0,100,,,1,,,,0.00010171,52.12712,16355.346,0,0
28725317.19,,5905,126.977,126.953,89998.602,9.3E-6,128.04536,2.551593,0,0,2820.5924,3.173,2820.5924,3.173,8.3912074,27.330471,0,100,,,1,,,,0.0001032,55.43291,16395.615,0,0
28725531.88,,5905,126.957,126.944,89998.602,9.4E-6,128.05324,2.5266172,0,0,2820.482,3.012,2820.482,3.012,1.0595554,27.242038,0,100,,,1,,,,0.00010353,54.66094,16397.631,0,0
28726246.59,,5905,132.086,132.043,89998.602,9.3E-6,133.00042,2.4996748,0,0,3033.1751,4.672,3033.1751,4.672,0.15964784,28.933589,0,100,,,1,,,,0.00010483,54.48408,17689.111,0,0
28726471.66,,5905,132.061,132.013,89998.602,9.3E-6,133.15867,2.6512072,0,0,3034.4178,3.424,3034.4178,3.424,7.131002,28.45456,0,100,,,1,,,,0.00010664,57.86718,17731.23,0,0
28726693.45,,5905,132.057,132.005,89998.602,9.3E-6,133.16676,2.627314,0,0,3032.3071,3.163,3032.3071,3.163,0.68838104,28.346299,0,100,,,1,,,,0.00010697,56.90912,17733.387,0,0
28727424.3,,5905,137.158,137.156,89998.602,9.3E-6,138.17375,2.5952466,0,0,3248.3312,4.631,3248.3312,4.631,0.16421466,29.858053,0,100,,,1,,,,0.00010879,56.6926,19091.986,0,0
28727657.05,,5905,137.144,137.132,89998.602,9.4E-6,138.32198,2.7440028,0,0,3252.3893,3.539,3252.3893,3.539,14.424263,29.537358,0,100,,,1,,,,0.00011011,59.71611,19132.971,0,0
28727886.5,,5905,137.145,137.119,89998.602,9.4E-6,138.3346,2.7279249,0,0,3250.5679,3.266,3250.5679,3.266,0.54818029,29.408223,0,100,,,1,,,,0.00011053,59.07472,19136.461,0,0
28728598.78,,5905,142.251,142.242,89998.602,9.4E-6,143.30499,2.6972,0,0,3466.4604,4.969,3466.4604,4.969,0.13890884,30.914591,0,100,,,1,,,,0.00011213,58.81645,20536.32,0,0
28728839.56,,5905,142.237,142.224,89998.602,9.4E-6,143.45667,2.8478744,0,0,3468.2205,3.656,3468.2205,3.656,5.8093207,30.523539,0,100,,,1,,,,0.00011362,61.82918,20579.817,0,0
28729076.38,,5905,142.236,142.209,89998.602,9.4E-6,143.46752,2.8257754,0,0,3468.0833,3.539,3468.0833,3.539,0.86152696,30.45524,0,100,,,1,,,,0.00011387,61.04708,20582.929,0,0
28729772.84,,5905,147.335,147.324,89998.602,9.4E-6,148.41642,2.8012735,0,0,3687.0288,5.364,3687.0288,5.364,0.13162369,31.864896,0,100,,,1,,,,0.00011571,60.91048,22027.434,0,0
28730020.95,,5905,147.32,147.295,89998.602,9.4E-6,148.56346,2.9429028,0,0,3686.7897,3.626,3686.7897,3.626,1.0982662,31.367155,0,100,,,1,,,,0.00011754,63.72979,22071.102,0,0
28730264,,5905,147.322,147.28,89998.602,9.3E-6,148.57218,2.9179537,0,0,3686.644,3.545,3686.644,3.545,0.94036002,31.328631,0,100,,,1,,,,0.00011768,62.73431,22073.691,0,0
28730968.64,,5905,152.417,152.428,89998.602,9.4E-6,153.58792,2.8987079,0,0,3904.9773,5.223,3904.9773,5.223,0.14640254,32.670569,0,100,,,1,,,,0.00011953,62.65726,23589.248,0,0
28731220.33,,5905,152.419,152.411,89998.602,9.4E-6,153.73132,3.0410926,0,0,3906.0141,3.702,3906.0141,3.702,1.7506275,32.259712,0,100,,,1,,,,0.00012108,65.34114,23633.32,0,0
28731470.92,,5905,152.412,152.397,89998.602,9.4E-6,153.73261,3.018078,0,0,3905.2873,3.57,3905.2873,3.57,0.53864501,32.218448,0,100,,,1,,,,0.00012121,64.51942,23633.714,0,0
28732146.48,,5905,157.514,157.512,89998.602,9.4E-6,158.71796,3.0077899,0,0,4115.1436,5.541,4115.1436,5.541,0.11305549,33.482951,0,100,,,1,,,,0.0001229,64.4369,25191.392,0,0
28732404.09,,5905,157.509,157.486,89998.602,9.4E-6,158.86339,3.147268,0,0,4116.5803,3.675,4116.5803,3.675,1.0849548,33.024531,0,100,,,1,,,,0.00012465,66.9659,25237.577,0,0
28732658.03,,5905,157.516,157.474,89998.602,9.4E-6,158.86639,3.1235761,0,0,4117.2007,3.631,4117.2007,3.631,0.4363952,32.988834,0,100,,,1,,,,0.00012481,66.04906,25238.531,0,0
28733340.28,,5905,162.607,162.551,89998.602,9.4E-6,163.83356,3.110339,0,0,4326.4112,5.123,4326.4112,5.123,0.15713047,34.092497,0,100,,,1,,,,0.0001269,65.97767,26841.434,0,0
28733601.23,,5905,162.596,162.531,89998.602,9.4E-6,163.96369,3.2438714,0,0,4327.9395,3.979,4327.9395,3.979,1.2372119,33.713914,0,100,,,1,,,,0.00012837,68.18499,26884.09,0,0
28733860.22,,5905,162.591,162.519,89998.602,9.3E-6,163.95935,3.2191612,0,0,4325.7334,3.724,4325.7334,3.724,0.27026124,33.622472,0,100,,,1,,,,0.00012866,67.42783,26882.669,0,0
28734512.94,,5905,167.711,167.669,89998.602,9.3E-6,168.99129,3.2116867,0,0,4536.2607,5.462,4536.2607,5.462,0.11423735,34.760124,0,100,,,1,,,,0.0001305,67.24494,28558.055,0,0
28734778.98,,5905,167.684,167.629,89998.602,9.3E-6,169.11676,3.3438351,0,0,4539.9468,4.065,4539.9468,4.065,1.1485296,34.357072,0,100,,,1,,,,0.00013214,69.52025,28600.478,0,0
28735043.08,,5905,167.681,167.632,89998.602,9.4E-6,169.12178,3.3236613,0,0,4538.6591,4.024,4538.6591,4.024,0.47993052,34.326165,0,100,,,1,,,,0.00013222,68.71414,28602.177,0,0
28735662.64,,5905,172.803,172.746,89998.602,9.4E-6,174.11108,3.3231982,0,0,4746.3944,5.949,4746.3944,5.949,0.10841897,35.433148,0,100,,,1,,,,0.00013395,68.65233,30314.667,0,0
28735934.27,,5905,172.788,172.731,89998.602,9.4E-6,174.24626,3.4511581,0,0,4747.3064,4.101,4747.3064,4.101,0.69866665,34.938231,0,100,,,1,,,,0.00013588,70.8663,30361.761,0,0
28736203.86,,5905,172.775,172.731,89998.602,9.4E-6,174.2467,3.4219291,0,0,4746.6166,3.957,4746.6166,3.957,0.33210597,34.827398,0,100,,,1,,,,0.00013629,69.87646,30361.912,0,0
28736830.55,,5905,177.88,177.855,89998.602,9.4E-6,179.26039,3.4174414,0,0,4953.2555,5.688,4953.2555,5.688,0.12564534,35.799826,0,100,,,1,,,,0.00013836,69.6548,32134.287,0,0
28737105.41,,5905,177.87,177.824,89998.602,9.3E-6,179.38382,3.5415408,0,0,4956.3509,4.251,4956.3509,4.251,0.75547538,35.414117,0,100,,,1,,,,0.00013995,71.59965,32178.556,0,0
28737376.88,,5905,177.855,177.816,89998.602,9.4E-6,179.38556,3.5236685,0,0,4954.4229,4.186,4954.4229,4.186,0.33811963,35.381765,0,100,,,1,,,,0.00014003,70.82823,32179.178,0,0
28738010.94,,5905,182.957,182.927,89998.602,9.3E-6,184.41361,3.5227036,0,0,5157.5255,5.403,5157.5255,5.403,0.15572297,36.158974,0,100,,,1,,,,0.00014263,70.76353,34008.379,0,0
28738288.33,,5905,182.948,182.909,89998.602,9.4E-6,184.51998,3.637167,0,0,5158.3441,4.149,5158.3441,4.149,0.55765097,35.809968,0,100,,,1,,,,0.00014405,72.31795,34047.622,0,0
28738562.23,,5905,182.948,182.899,89998.602,9.4E-6,184.52068,3.6185205,0,0,5157.3428,4.182,5157.3428,4.182,0.29811246,35.770927,0,100,,,1,,,,0.00014418,71.61994,34047.883,0,0
28739157.8,,5905,188.057,187.98,89998.602,9.3E-6,189.50337,3.6220595,0,0,5357.6579,5.696,5357.6579,5.696,0.10846223,36.555545,0,100,,,1,,,,0.00014656,71.54185,35911.528,0,0
28739437.8,,5905,188.043,187.956,89998.602,9.4E-6,189.61993,3.7363656,0,0,5356.3987,4.281,5356.3987,4.281,0.63720629,36.158654,0,100,,,1,,,,0.00014814,73.11109,35955.719,0,0
28739714.42,,5905,188.034,187.96,89998.602,9.3E-6,189.61797,3.7154863,0,0,5357.8205,4.197,5357.8205,4.197,0.33936084,36.166828,0,100,,,1,,,,0.00014814,72.31731,35954.973,0,0
28740313.22,,5905,193.147,193.103,89998.602,9.3E-6,194.68686,3.7240563,0,0,5552.4013,5.557,5552.4013,5.557,0.11653409,36.81773,0,100,,,1,,,,0.00015081,72.33366,37902.975,0,0
28740594.45,,5905,193.119,193.08,89998.602,9.3E-6,194.78519,3.8330537,0,0,5551.712,4.182,5551.712,4.182,0.30146356,36.466882,0,100,,,1,,,,0.00015224,73.63546,37941.27,0,0
28740873.63,,5905,193.127,193.067,89998.602,9.3E-6,194.79059,3.8149754,0,0,5548.2479,4.009,5548.2479,4.009,0.27945779,36.405185,0,100,,,1,,,,0.0001524,72.93376,37943.375,0,0
28741430.81,,5905,198.244,198.136,89998.602,9.4E-6,199.77602,3.8218673,0,0,5744.0674,6.105,5744.0674,6.105,0.097953413,37.128047,0,100,,,1,,,,0.00015471,72.81037,39910.458,0,0
28741713.91,,5905,198.217,198.121,89998.602,9.3E-6,199.88703,3.9336817,0,0,5743.1616,4.514,5743.1616,4.514,0.5037846,36.695525,0,100,,,1,,,,0.00015651,74.25609,39954.827,0,0
28741993.91,,5905,198.215,198.113,89998.602,9.3E-6,199.88671,3.9042758,0,0,5743.6064,4.341,5743.6064,4.341,0.31787291,36.614115,0,100,,,1,,,,0.00015687,73.39105,39954.695,0,0
28742551.91,,5905,203.343,203.263,89998.602,9.4E-6,204.95996,3.913679,0,0,5937.0174,6.012,5937.0174,6.012,0.14550668,37.18186,0,100,,,1,,,,0.00015968,73.22823,42008.584,0,0
28742836.31,,5905,203.311,203.258,89998.602,9.3E-6,205.05483,4.0176467,0,0,5936.7601,4.703,5936.7601,4.703,0.3174242,36.868662,0,100,,,1,,,,0.00016102,74.36372,42047.483,0,0
28743117.39,,5905,203.291,203.233,89998.602,9.4E-6,205.05472,3.9979263,0,0,5934.451,4.359,5934.451,4.359,0.17531914,36.731933,0,100,,,1,,,,0.00016156,73.73732,42047.44,0,0
28743637.69,,5905,208.415,208.32,89998.602,9.3E-6,210.04356,4.0126907,0,0,6117.8133,6.31,6117.8133,6.31,0.11490216,37.391745,0,100,,,1,,,,0.00016361,73.46387,44118.298,0,0
28743922.92,,5905,208.399,208.299,89998.602,9.3E-6,210.15419,4.121912,0,0,6117.4354,4.477,6117.4354,4.477,0.28235574,37.080758,0,100,,,1,,,,0.00016498,74.78349,44164.784,0,0
28744206.16,,5905,208.397,208.288,89998.602,9.3E-6,210.15334,4.1000538,0,0,6120.0186,4.43,6120.0186,4.43,0.22261969,37.022753,0,100,,,1,,,,0.0001653,74.16152,44164.428,0,0
28744728.69,,5905,213.504,213.438,89998.602,9.4E-6,215.22007,4.1223178,0,0,6299.5196,5.984,6299.5196,5.984,0.11089593,37.510318,0,100,,,1,,,,0.00016794,74.04551,46319.68,0,0
28745015.34,,5905,213.49,213.419,89998.602,9.3E-6,215.32113,4.2220107,0,0,6299.5559,4.556,6299.5559,4.556,0.33890493,37.186621,0,100,,,1,,,,0.0001694,75.02064,46363.187,0,0
28745300.41,,5905,213.488,213.399,89998.602,9.4E-6,215.32017,4.1990748,0,0,6300.5868,4.279,6300.5868,4.279,0.23602432,37.108001,0,100,,,1,,,,0.00016979,74.37324,46362.777,0,0
28745823.97,,5905,218.574,218.537,89998.602,9.3E-6,220.36415,4.2178058,0,0,6480.6613,6.162,6480.6613,6.162,0.16998144,37.550662,0,100,,,1,,,,0.00017258,74.216,48560.361,0,0
28746110.5,,5905,218.577,218.514,89998.602,9.3E-6,220.45661,4.3144814,0,0,6479.5281,4.83,6479.5281,4.83,0.29956157,37.18509,0,100,,,1,,,,0.00017425,75.10132,48601.119,0,0
28746394.92,,5905,218.571,218.497,89998.602,9.4E-6,220.4544,4.2938406,0,0,6479.5264,4.825,6479.5264,4.825,0.22600776,37.209339,0,100,,,1,,,,0.00017414,74.37018,48600.143,0,0
28746914.8,,5905,223.691,223.623,89998.602,9.3E-6,225.50724,4.3169592,0,0,6657.1933,5.77,6657.1933,5.77,0.20115632,37.506993,0,100,,,1,,,,0.00017749,74.41868,50853.514,0,0
28747201.27,,5905,223.653,223.611,89998.602,9.3E-6,225.59053,4.4040996,0,0,6658.122,4.638,6658.122,4.638,0.50515874,37.198255,0,100,,,1,,,,0.00017899,75.01399,50891.087,0,0
28747485.47,,5905,223.644,223.584,89998.602,9.3E-6,225.59428,4.3879863,0,0,6656.5273,4.711,6656.5273,4.711,0.29134872,37.172628,0,100,,,1,,,,0.00017907,74.39651,50892.779,0,0
28747998.34,,5905,228.761,228.732,89998.602,9.3E-6,230.64506,4.4136011,0,0,6823.1832,5.854,6823.1832,5.854,0.22252518,37.446783,0,100,,,1,,,,0.00018221,74.34526,53197.143,0,0
28748283.7,,5905,228.75,228.689,89998.602,9.4E-6,230.72596,4.5056739,0,0,6832.3185,4.652,6832.3185,4.652,0.36850153,37.273706,0,100,,,1,,,,0.0001833,74.89357,53234.467,0,0
28748567.81,,5905,228.759,228.676,89998.602,9.4E-6,230.73254,4.4908185,0,0,6832.5462,4.629,6832.5462,4.629,0.26745082,37.201876,0,100,,,1,,,,0.00018366,74.54741,53237.504,0,0
28749078.25,,5905,233.857,233.74,89998.602,9.3E-6,235.74507,4.508096,0,0,6990.5217,5.604,6990.5217,5.604,0.5332189,37.233425,0,100,,,1,,,,0.00018775,74.40375,55575.739,0,0
28749362.73,,5905,233.846,233.732,89998.602,9.3E-6,235.81302,4.5913062,0,0,6990.4936,4.964,6990.4936,4.964,0.11656685,37.119701,0,100,,,1,,,,0.00018832,74.46685,55607.782,0,0
28749645.94,,5905,233.841,233.715,89998.602,9.4E-6,235.81336,4.5827214,0,0,6992.6649,4.561,6992.6649,4.561,0.17411584,37.106368,0,100,,,1,,,,0.00018845,74.2394,55607.942,0,0
28750159.16,,5905,238.947,238.882,89998.602,9.3E-6,240.90926,4.6156836,0,0,7148.474,5.942,7148.474,5.942,0.32045728,37.235594,0,100,,,1,,,,0.00019198,74.21274,58037.271,0,0
28750443.22,,5905,238.945,238.868,89998.602,9.4E-6,240.98491,4.7050949,0,0,7148.5566,5.272,7148.5566,5.272,0.16185908,37.076913,0,100,,,1,,,,0.0001928,74.47119,58073.727,0,0
28750726.33,,5905,238.942,238.842,89998.602,9.4E-6,240.98965,4.6895048,0,0,7144.3254,4.763,7144.3254,4.763,0.33494946,36.93718,0,100,,,1,,,,0.00019342,74.15383,58076.011,0,0
28751264.31,,5905,244.036,243.943,89998.602,9.4E-6,246.0171,4.7046657,0,0,7309.6071,4.695,7309.6071,4.695,0.7452256,37.009821,0,100,,,1,,,,0.0001975,73.87436,60524.412,0,0
28751547.67,,5905,244.022,243.912,89998.602,9.4E-6,246.06955,4.7919337,0,0,7309.4799,4.68,7309.4799,4.68,0.11211625,36.934187,0,100,,,1,,,,0.00019791,74.01964,60550.224,0,0
28751828.69,,5905,244.028,243.881,89998.602,9.3E-6,246.0839,4.7836986,0,0,7305.5129,4.685,7305.5129,4.685,0.35275035,36.820567,0,100,,,1,,,,0.00019841,73.86837,60557.287,0,0
28752360.89,,5905,249.107,249.054,89998.602,9.3E-6,251.17769,4.8118695,0,0,7450.6344,5.041,7450.6344,5.041,0.57249047,36.814338,0,100,,,1,,,,0.00020238,73.64113,63090.23,0,0
28752642.02,,5905,249.106,249.015,89998.602,9.3E-6,251.245,4.8841715,0,0,7462.9397,4.785,7462.9397,4.785,0.19858813,36.702937,0,100,,,1,,,,0.00020333,73.62868,63124.05,0,0
28752923,,5905,249.093,249.022,89998.602,9.3E-6,251.25284,4.8806187,0,0,7461.1307,4.84,7461.1307,4.84,0.16467742,36.693793,0,100,,,1,,,,0.00020333,73.40587,63127.992,0,0
28753468.83,,5905,254.227,254.13,89998.602,9.3E-6,256.29136,4.9058219,0,0,7609.0559,5.289,7609.0559,5.289,0.28906828,36.624619,0,100,,,1,,,,0.00020776,73.38759,65685.262,0,0
28753748.84,,5905,254.198,254.102,89998.602,9.4E-6,256.36723,4.9815388,0,0,7612.2879,4.543,7612.2879,4.543,0.25419286,36.47344,0,100,,,1,,,,0.00020871,73.24924,65724.155,0,0
28754028.02,,5905,254.184,254.097,89998.602,9.3E-6,256.37415,4.9800338,0,0,7609.0853,4.491,7609.0853,4.491,0.14461421,36.559447,0,100,,,1,,,,0.00020813,72.94688,65727.704,0,0
28754566.39,,5905,259.299,259.149,89998.602,9.3E-6,261.37346,5.0138841,0,0,7732.5533,4.431,7732.5533,4.431,0.28157324,36.255988,0,100,,,1,,,,0.00021328,73.11889,68316.084,0,0
28754843.64,,5905,259.293,259.138,89998.602,9.4E-6,261.43756,5.0743868,0,0,7746.4437,4.607,7746.4437,4.607,0.19220879,36.28754,0,100,,,1,,,,0.00021347,72.51198,68349.6,0,0
28755120.47,,5905,259.29,259.13,89998.602,9.3E-6,261.4573,5.0794193,0,0,7741.2466,4.595,7741.2466,4.595,0.11194214,36.204788,0,100,,,1,,,,0.00021382,72.57508,68359.92,0,0
28755691.31,,5905,264.402,264.258,89998.602,9.4E-6,266.55706,5.1055291,0,0,7879.5889,5.483,7879.5889,5.483,5.1316372,36.055421,0,100,,,1,,,,0.00021854,72.40958,71052.664,0,0
28755967.02,,5905,264.38,264.253,89998.602,9.3E-6,266.61798,5.1862441,0,0,7875.5704,4.89,7875.5704,4.89,0.13419157,35.996433,0,100,,,1,,,,0.00021879,72.11084,71085.149,0,0
28756243.09,,5905,264.376,264.239,89998.602,9.4E-6,266.62779,5.1827861,0,0,7878.0046,5.094,7878.0046,5.094,0.20816077,36.036523,0,100,,,1,,,,0.00021861,71.99287,71090.379,0,0
28756813.56,,5905,269.516,269.347,89998.602,9.3E-6,271.69108,5.2212817,0,0,8013.5214,6.186,8013.5214,6.186,25.225059,35.923045,0,100,,,1,,,,0.00022307,72.07305,73816.041,0,0
28757088.22,,5905,269.458,269.33,89998.602,9.4E-6,271.75557,5.2936018,0,0,8015.281,5.139,8015.281,5.139,0.17658492,35.749039,0,100,,,1,,,,0.00022421,71.84609,73851.091,0,0
28757363.02,,5905,269.468,269.331,89998.602,9.4E-6,271.76566,5.2809189,0,0,8013.8122,5.207,8013.8122,5.207,0.19469864,35.729989,0,100,,,1,,,,0.00022429,71.49808,73856.573,0,0
28757899.19,,5905,274.573,274.372,89998.602,9.3E-6,276.77441,5.2999882,0,0,8158.1716,5.931,8158.1716,5.931,0.52258475,35.551088,0,100,,,1,,,,0.00022948,71.45998,76604.075,0,0
28758171.66,,5905,274.569,274.362,89998.602,9.3E-6,276.83391,5.3846479,0,0,8150.1549,5.53,8150.1549,5.53,0.2267338,35.489313,0,100,,,1,,,,0.00022965,71.10218,76637.016,0,0
28758443.38,,5905,274.559,274.337,89998.602,9.4E-6,276.84273,5.3759389,0,0,8152.3274,5.649,8152.3274,5.649,0.33436885,35.474718,0,100,,,1,,,,0.00022981,70.97863,76641.896,0,0
28759013.14,,5905,279.666,279.518,89998.602,9.3E-6,281.95449,5.4104179,0,0,8277.4322,5.704,8277.4322,5.704,2.9171799,35.242365,0,100,,,1,,,,0.00023487,70.94944,79498.334,0,0
28759282.83,,5905,279.638,279.494,89998.602,9.3E-6,282.00902,5.4816735,0,0,8286.0309,5.424,8286.0309,5.424,0.23826762,35.236248,0,100,,,1,,,,0.00023516,70.48473,79529.086,0,0
28759552.48,,5905,279.626,279.472,89998.602,9.4E-6,282.02873,5.4846734,0,0,8276.1361,5.564,8276.1361,5.564,0.25851894,35.148561,0,100,,,1,,,,0.00023546,70.4725,79540.202,0,0
28760085.14,,5905,284.745,284.585,89998.602,9.3E-6,287.07471,5.4967725,0,0,8425.0977,7.132,8425.0977,7.132,4.4193928,35.021145,0,100,,,1,,,,0.00024057,70.29712,82411.889,0,0
28760353.94,,5905,284.724,284.57,89998.602,9.3E-6,287.15326,5.581723,0,0,8414.3815,5.613,8414.3815,5.613,0.25754578,34.814996,0,100,,,1,,,,0.00024169,70.04229,82456.995,0,0
28760621.14,,5905,284.723,284.569,89998.602,9.3E-6,287.1571,5.5748508,0,0,8408.4876,5.547,8408.4876,5.547,0.20480873,34.871447,0,100,,,1,,,,0.00024113,69.62999,82459.202,0,0
28761156.28,,5905,289.843,289.629,89998.602,9.4E-6,292.16397,5.5999539,0,0,8528.9244,6.614,8528.9244,6.614,4.6539041,34.550623,0,100,,,1,,,,0.00024685,69.74289,85359.783,0,0
28761421.55,,5905,289.826,289.597,89998.602,9.4E-6,292.22303,5.6771956,0,0,8526.9037,5.258,8526.9037,5.258,0.27624029,34.565549,0,100,,,1,,,,0.00024669,69.10125,85394.299,0,0
28761686.88,,5905,289.823,289.579,89998.602,9.3E-6,292.22821,5.6753024,0,0,8529.3651,5.425,8529.3651,5.425,0.21254642,34.53251,0,100,,,1,,,,0.000247,69.1311,85397.327,0,0
28762217.59,,5905,294.933,294.769,89998.602,9.4E-6,297.34707,5.7206837,0,0,8622.2996,6.139,8622.2996,6.139,5.4037475,34.250479,0,100,,,1,,,,0.00025174,69.06502,88415.279,0,0
28762479.89,,5905,294.918,294.72,89998.602,9.4E-6,297.40937,5.7907941,0,0,8630.9761,5.374,8630.9761,5.374,0.14865415,34.205046,0,100,,,1,,,,0.00025233,68.50096,88452.332,0,0
28762742.17,,5905,294.917,294.712,89998.602,9.4E-6,297.41939,5.7859259,0,0,8636.89,5.62,8636.89,5.62,0.16082772,34.223427,0,100,,,1,,,,0.00025237,68.41009,88458.294,0,0
28763275.77,,5905,300.05,299.848,89998.602,9.3E-6,302.48278,5.8283047,0,0,8722.5128,5.928,8722.5128,5.928,11.708472,33.81513,0,100,,,1,,,,0.00025795,68.44685,91495.831,0,0
28763534.83,,5905,300.001,299.802,89998.602,9.3E-6,302.53544,5.886383,0,0,8735.0776,5.47,8735.0776,5.47,0.217725,33.824359,0,100,,,1,,,,0.00025825,67.63026,91527.693,0,0
28763794.83,,5905,300.023,299.808,89998.602,9.3E-6,302.55176,5.8907121,0,0,8739.2719,5.181,8739.2719,5.181,0.15675389,33.834819,0,100,,,1,,,,0.00025829,67.64872,91537.565,0,0