File: ppms-mpms/Bi-O-S_bestsample_Add2.dat
[Header]
TITLE,Bi-O-S_bestsample_Add2.dat
BYAPP,HeatCapacity,3.8.6,1.7
INFO,,MASS:Sample Mass (mg)
INFO,,MASSERR:Sample Mass Error (mg)
INFO,,MOLWGHT:Formula Weight (g/mole)
INFO,,ATOMS:Atoms per Formula Unit
INFO,PPMS Heat Capacity Option 3.8.6 Build 1,APPNAME
DATATYPE,TIME,1
DATATYPE,COMMENT,2
STARTUPAXIS, X, 8, LINEAR, AUTO
STARTUPAXIS, Y1, 12, LINEAR, AUTO
[Data]
Time Stamp (Seconds),Comment (),System Status (Code),Puck Temp (Kelvin),System Temp (Kelvin),Field (Oersted),Pressure (Torr),Sample Temp (Kelvin),Temp Rise (Kelvin),Samp HC (µJ/K),Samp HC Err (µJ/K),Addenda HC (µJ/K),Addenda HC Err (µJ/K),Total HC (µJ/K),Total HC Err (µJ/K),Fit Deviation (ChiSquare),Time Const tau1 (seconds),Time Const tau2 (seconds),Sample Coupling (Percent),Debye Temp (Kelvin),Debye Temp Err (Kelvin),Cal Correction (Factor),Therm Resist (Ohms),Htr Resist (Ohms),Puck Resist (Ohms),Wire Cond (W/K),Meas Time (seconds),Temp Squared (K^2),Samp HC/Temp (µJ/K/K),Addenda Offset HC (µJ/K)
36014062.94,CALFILE: Puck1074_1.cal
36014063,,5905,1.79976,1.7936,0.131,9.3E-6,1.818241,0.034310175,0,0,0.11270678,0.0009701,0.11270678,0.0009701,53.572168,0.069796691,0,100,,,1,,,,1.6148E-6,0.1537051,3.3060003,0,0
36014109.77,,5905,1.79952,1.7935,0.131,9.3E-6,1.8169785,0.031748561,0,0,0.11202623,0.001106,0.11202623,0.001106,45.384462,0.068691793,0,100,,,1,,,,1.6309E-6,0.1381652,3.3014109,0,0
36014155.97,,5905,1.79967,1.7937,0.131,9.4E-6,1.8163742,0.031737604,0,0,0.11251568,0.001115,0.11251568,0.001115,31.798309,0.069284235,0,100,,,1,,,,1.624E-6,0.1377072,3.2992151,0,0
36014205.02,,5905,1.79943,1.7933,0.131,9.4E-6,1.8167174,0.031723213,0,0,0.11248683,0.001142,0.11248683,0.001142,109.60264,0.068889508,0,100,,,1,,,,1.6329E-6,0.1381491,3.3004621,0,0
36014408.3,,5905,1.90473,1.8977,0.131,9.2E-6,1.9244516,0.032309559,0,0,0.12618075,0.001247,0.12618075,0.001247,98.155452,0.072461388,0,100,,,1,,,,1.7414E-6,0.137023,3.703514,0,0
36014455.8,,5905,1.9038,1.8972,0.131,9.3E-6,1.9259601,0.034449964,0,0,0.12693231,0.001238,0.12693231,0.001238,17.247916,0.07383798,0,100,,,1,,,,1.7191E-6,0.1480993,3.7093224,0,0
36014502.19,,5905,1.90337,1.8966,0.131,9.3E-6,1.9246479,0.034312556,0,0,0.12674672,0.001153,0.12674672,0.001153,40.874371,0.0736345,0,100,,,1,,,,1.7213E-6,0.147149,3.7042695,0,0
36014548.47,,5905,1.903,1.8962,0.131,9.4E-6,1.9249198,0.034313475,0,0,0.12703277,0.001177,0.12703277,0.001177,103.48208,0.074385391,0,100,,,1,,,,1.7078E-6,0.1467594,3.7053161,0,0
36014761.44,,5905,2.00128,2.0044,0.131,9.3E-6,2.0272937,0.03489776,0,0,0.14129671,0.001767,0.14129671,0.001767,1.1387408,0.077137127,0,100,,,1,,,,1.8318E-6,0.1474689,4.1099197,0,0
36014810.44,,5905,2.00181,2.0066,0.131,9.3E-6,2.0281765,0.035895311,0,0,0.14131284,0.001244,0.14131284,0.001244,64.656549,0.07712003,0,100,,,1,,,,1.8324E-6,0.154424,4.1135001,0,0
36014862.33,,5905,2.00259,2.0074,0.131,9.4E-6,2.0274978,0.035928137,0,0,0.14142,0.001293,0.14142,0.001293,24.583105,0.077444145,0,100,,,1,,,,1.8261E-6,0.1543067,4.1107472,0,0
36014911.19,,5905,2.00218,2.0071,0.131,9.3E-6,2.028533,0.035880991,0,0,0.14112171,0.001194,0.14112171,0.001194,83.740762,0.076896526,0,100,,,1,,,,1.8352E-6,0.1542788,4.1149462,0,0
36015113.89,,5905,2.10182,2.1118,0.131,9.3E-6,2.1293804,0.036509552,0,0,0.15690607,0.001426,0.15690607,0.001426,24.742015,0.081068796,0,100,,,1,,,,1.9355E-6,0.1546484,4.534261,0,0
36015160.34,,5905,2.10365,2.1132,0.131,9.4E-6,2.1305772,0.038229298,0,0,0.15736337,0.001164,0.15736337,0.001164,55.873073,0.081632335,0,100,,,1,,,,1.9277E-6,0.1633027,4.5393593,0,0
36015208.41,,5905,2.10307,2.1125,0.131,9.2E-6,2.131148,0.038140583,0,0,0.15751571,0.001165,0.15751571,0.001165,35.695821,0.081683108,0,100,,,1,,,,1.9284E-6,0.1630879,4.5417918,0,0
36015257.44,,5905,2.10336,2.1142,0.131,9.4E-6,2.131367,0.038258928,0,0,0.15739977,0.002143,0.15739977,0.002143,0.69091606,0.081704365,0,100,,,1,,,,1.9265E-6,0.1635552,4.5427255,0,0
36015467.55,,5905,2.20467,2.2124,0.131,9.4E-6,2.231642,0.038842573,0,0,0.17330466,0.001273,0.17330466,0.001273,21.558881,0.08533122,0,100,,,1,,,,2.031E-6,0.1633937,4.9802261,0,0
36015513.75,,5905,2.20515,2.2128,0.131,9.4E-6,2.2324873,0.039825828,0,0,0.17389326,0.001329,0.17389326,0.001329,78.418048,0.085512593,0,100,,,1,,,,2.0335E-6,0.1713551,4.9839993,0,0
36015560.06,,5905,2.20691,2.2117,0.131,9.3E-6,2.2328656,0.040067965,0,0,0.17420565,0.001392,0.17420565,0.001392,7.7974382,0.085588661,0,100,,,1,,,,2.0354E-6,0.1731156,4.9856889,0,0
36015606.55,,5905,2.20647,2.2115,0.131,9.2E-6,2.232413,0.039873446,0,0,0.17389523,0.00142,0.17389523,0.00142,8.4511363,0.085518854,0,100,,,1,,,,2.0334E-6,0.1711876,4.9836677,0,0
36015813.72,,5905,2.30575,2.3129,0.131,9.4E-6,2.3323211,0.040312422,0,0,0.19183116,0.001778,0.19183116,0.001778,2.496965,0.089418623,0,100,,,1,,,,2.1453E-6,0.1713393,5.4397219,0,0
36015863.05,,5905,2.30598,2.3142,0.131,9.3E-6,2.334089,0.041762865,0,0,0.1928334,0.001839,0.1928334,0.001839,1.6453766,0.089664139,0,100,,,1,,,,2.1506E-6,0.1804668,5.4479714,0,0
36015909.52,,5905,2.30706,2.3143,0.131,9.4E-6,2.3333564,0.041803469,0,0,0.19162404,0.001448,0.19162404,0.001448,1.7980151,0.089500719,0,100,,,1,,,,2.141E-6,0.1787364,5.444552,0,0
36015961.81,,5905,2.30569,2.3126,0.131,9.3E-6,2.3333823,0.041988733,0,0,0.19210294,0.002718,0.19210294,0.002718,1.0058497,0.08989467,0,100,,,1,,,,2.137E-6,0.1800748,5.4446728,0,0
36016171.06,,5905,2.40749,2.4183,0.131,9.2E-6,2.4360411,0.042608631,0,0,0.21184239,0.001383,0.21184239,0.001383,16.488633,0.094926082,0,100,,,1,,,,2.2317E-6,0.1810317,5.9342961,0,0
36016217.41,,5905,2.40822,2.4191,0.131,9.2E-6,2.4367993,0.043868252,0,0,0.21196985,0.001568,0.21196985,0.001568,57.971333,0.094606718,0,100,,,1,,,,2.2405E-6,0.1906157,5.9379906,0,0
36016266.59,,5905,2.40781,2.4184,0.131,9.2E-6,2.438072,0.043965493,0,0,0.21268056,0.001521,0.21268056,0.001521,6.726163,0.095986854,0,100,,,1,,,,2.2157E-6,0.1904933,5.944195,0,0
36016313.8,,5905,2.40821,2.4188,0.131,9.3E-6,2.4367401,0.043716221,0,0,0.21192493,0.001453,0.21192493,0.001453,15.155293,0.094943166,0,100,,,1,,,,2.2321E-6,0.1891495,5.9377023,0,0
36016526.13,,5905,2.50584,2.519,0.131,9.4E-6,2.5367423,0.044594037,0,0,0.23285726,0.00171,0.23285726,0.00171,18.046657,0.10077486,0,100,,,1,,,,2.3107E-6,0.1914294,6.4350617,0,0
36016577.97,,5905,2.50861,2.5218,0.131,9.3E-6,2.5382126,0.046482486,0,0,0.23374829,0.001329,0.23374829,0.001329,17.204714,0.10000228,0,100,,,1,,,,2.3374E-6,0.2043309,6.4425232,0,0
36016631.14,,5905,2.50872,2.5222,0.131,9.3E-6,2.5396536,0.046067282,0,0,0.23388766,0.001416,0.23388766,0.001416,12.414326,0.10002416,0,100,,,1,,,,2.3383E-6,0.2008401,6.4498405,0,0
36016680.47,,5905,2.50934,2.5224,0.131,9.3E-6,2.5388391,0.046131448,0,0,0.23310699,0.002865,0.23310699,0.002865,0.86290462,0.10030333,0,100,,,1,,,,2.324E-6,0.1998112,6.4457041,0,0
36016898.88,,5905,2.61224,2.6185,0.131,9.4E-6,2.6442801,0.047232956,0,0,0.25660396,0.001957,0.25660396,0.001957,0.62049804,0.10570018,0,100,,,1,,,,2.4277E-6,0.2040345,6.9922173,0,0
36016958.28,,5905,2.61103,2.6102,0.131,9.4E-6,2.6410811,0.047880517,0,0,0.25762951,0.001872,0.25762951,0.001872,0.80978892,0.10698458,0,100,,,1,,,,2.4081E-6,0.2082935,6.9753096,0,0
36017013.83,,5905,2.6126,2.6182,0.131,9.2E-6,2.64431,0.047373476,0,0,0.25691953,0.002721,0.25691953,0.002721,0.78290512,0.10347059,0,100,,,1,,,,2.483E-6,0.2083991,6.9923753,0,0
36017067.53,,5905,2.61364,2.6183,0.131,9.4E-6,2.6446125,0.047122014,0,0,0.2572207,0.002111,0.2572207,0.002111,0.57336318,0.10342262,0,100,,,1,,,,2.4871E-6,0.2073491,6.9939754,0,0
36017280.5,,5905,2.7146,2.7225,0.131,9.4E-6,2.7423266,0.048013476,0,0,0.2808112,0.00186,0.2808112,0.00186,1.2010535,0.110614,0,100,,,1,,,,2.5387E-6,0.2075415,7.5203551,0,0
36017334.56,,5905,2.71532,2.7213,0.131,9.2E-6,2.7445664,0.051147643,0,0,0.28083911,0.002609,0.28083911,0.002609,0.297594,0.10943064,0,100,,,1,,,,2.5664E-6,0.2278248,7.5326447,0,0
36017382.73,,5905,2.71636,2.7225,0.131,9.4E-6,2.7448167,0.051087723,0,0,0.28107203,0.001784,0.28107203,0.001784,1.3074637,0.11035073,0,100,,,1,,,,2.5471E-6,0.2278907,7.5340188,0,0
36017436.8,,5905,2.71244,2.7135,0.131,9.3E-6,2.7490082,0.051356686,0,0,0.28286487,0.00533,0.28286487,0.00533,0.21352831,0.11316208,0,100,,,1,,,,2.4996E-6,0.2267393,7.5570462,0,0
36017661.53,,5905,2.81536,2.8215,0.131,9.3E-6,2.8461036,0.050871415,0,0,0.30652225,0.001924,0.30652225,0.001924,4.9484384,0.11553519,0,100,,,1,,,,2.6531E-6,0.224267,8.1003057,0,0
36017715.36,,5905,2.81597,2.8213,0.131,9.3E-6,2.8459304,0.052809068,0,0,0.30591025,0.001959,0.30591025,0.001959,3.9198214,0.11623001,0,100,,,1,,,,2.6319E-6,0.2349952,8.0993196,0,0
36017767.59,,5905,2.8145,2.8192,0.131,9.4E-6,2.8474719,0.052333737,0,0,0.30758541,0.002778,0.30758541,0.002778,1.7407361,0.11639919,0,100,,,1,,,,2.6425E-6,0.2331404,8.1080965,0,0
36017822.38,,5905,2.80126,2.8358,0.131,9.2E-6,2.8324454,0.053031357,0,0,0.30342142,0.001633,0.30342142,0.001633,21.151869,0.11669213,0,100,,,1,,,,2.6002E-6,0.2344991,8.022747,0,0
36018029.2,,5905,2.90787,2.9441,0.131,9.2E-6,2.9429082,0.052682203,0,0,0.33376215,0.004298,0.33376215,0.004298,0.42149117,0.12150011,0,100,,,1,,,,2.747E-6,0.2341562,8.6607087,0,0
36018078.59,,5905,2.9108,2.9477,0.131,9.3E-6,2.9468126,0.054313253,0,0,0.3339539,0.001529,0.3339539,0.001529,2.3714002,0.12122931,0,100,,,1,,,,2.7547E-6,0.2448446,8.6837047,0,0
36018125.48,,5905,2.91195,2.9481,0.131,9.2E-6,2.9479235,0.05440789,0,0,0.33477032,0.00208,0.33477032,0.00208,2.4915724,0.12171821,0,100,,,1,,,,2.7504E-6,0.2453098,8.6902532,0,0
36018171.91,,5905,2.91414,2.9511,0.131,9.3E-6,2.9497849,0.054540322,0,0,0.33663412,0.001758,0.33663412,0.001758,51.782649,0.12315568,0,100,,,1,,,,2.7334E-6,0.2453263,8.7012312,0,0
36018386.7,,5905,3.01224,3.0489,0.131,9.2E-6,3.0484651,0.054823213,0,0,0.36404379,0.001728,0.36404379,0.001728,11.545622,0.12688357,0,100,,,1,,,,2.8691E-6,0.2466783,9.2931392,0,0
36018436.09,,5905,3.01282,3.0524,0.131,9.4E-6,3.0490745,0.057078093,0,0,0.36451675,0.001614,0.36451675,0.001614,4.5540184,0.12846008,0,100,,,1,,,,2.8376E-6,0.260285,9.2968555,0,0
36018482.81,,5905,3.01356,3.0519,0.131,9.3E-6,3.050464,0.056018571,0,0,0.36487941,0.001905,0.36487941,0.001905,22.312059,0.12832255,0,100,,,1,,,,2.8435E-6,0.2534163,9.3053309,0,0
36018529.19,,5905,3.0137,3.0536,0.131,9.2E-6,3.0512688,0.056459634,0,0,0.36665714,0.002975,0.36665714,0.002975,1.0326577,0.13057144,0,100,,,1,,,,2.8081E-6,0.2550001,9.3102413,0,0
36018730.45,,5905,3.11027,3.1507,0.131,9.2E-6,3.148969,0.05768321,0,0,0.39632633,0.002778,0.39632633,0.002778,0.72312116,0.13426297,0,100,,,1,,,,2.9519E-6,0.262347,9.9160057,0,0
36018777.08,,5905,3.11249,3.1557,0.131,9.4E-6,3.152534,0.058253359,0,0,0.39718813,0.00204,0.39718813,0.00204,4.7139399,0.133708,0,100,,,1,,,,2.9706E-6,0.2680106,9.9384707,0,0
36018824.19,,5905,3.11431,3.1547,0.131,9.2E-6,3.1523659,0.058509136,0,0,0.39845945,0.002519,0.39845945,0.002519,1.596341,0.13752477,0,100,,,1,,,,2.8974E-6,0.2660569,9.9374108,0,0
36018871.83,,5905,3.11717,3.1583,0.131,9.2E-6,3.1565134,0.059385324,0,0,0.39701914,0.001846,0.39701914,0.001846,0.82142917,0.13373049,0,100,,,1,,,,2.9688E-6,0.2746569,9.9635771,0,0
36019080.05,,5905,3.21274,3.2552,0.131,9.3E-6,3.2513104,0.058552435,0,0,0.43109708,0.001929,0.43109708,0.001929,23.741664,0.14139709,0,100,,,1,,,,3.0488E-6,0.2674991,10.571019,0,0
36019126.97,,5905,3.215,3.2573,0.131,9.3E-6,3.2547297,0.060671959,0,0,0.43159993,0.002066,0.43159993,0.002066,7.0584905,0.14028168,0,100,,,1,,,,3.0767E-6,0.2838407,10.593265,0,0
36019176.48,,5905,3.2157,3.2574,0.131,9.2E-6,3.2585524,0.061034062,0,0,0.4309893,0.0016,0.4309893,0.0016,17.141346,0.13999095,0,100,,,1,,,,3.0787E-6,0.285299,10.618164,0,0
36019228.83,,5905,3.21773,3.2599,0.131,9.4E-6,3.2596386,0.060274714,0,0,0.43264268,0.001901,0.43264268,0.001901,10.846559,0.14085478,0,100,,,1,,,,3.0716E-6,0.2795998,10.625244,0,0
36019424.97,,5905,3.31299,3.3575,0.131,9.3E-6,3.3523426,0.060754694,0,0,0.46616095,0.00207,0.46616095,0.00207,5.0031812,0.14581073,0,100,,,1,,,,3.197E-6,0.2829597,11.238201,0,0
36019472.36,,5905,3.31685,3.3625,0.131,9.3E-6,3.3581032,0.062655365,0,0,0.46635369,0.003156,0.46635369,0.003156,0.40040942,0.14486927,0,100,,,1,,,,3.2191E-6,0.2971231,11.276857,0,0
36019519.39,,5905,3.31662,3.3609,0.131,9.2E-6,3.3586906,0.063456313,0,0,0.46890653,0.002299,0.46890653,0.002299,1.1053598,0.14962292,0,100,,,1,,,,3.1339E-6,0.2987949,11.280802,0,0
36019566.31,,5905,3.32073,3.3659,0.131,9.2E-6,3.3609981,0.062706467,0,0,0.46865066,0.002994,0.46865066,0.002994,0.30494989,0.14529629,0,100,,,1,,,,3.2255E-6,0.2975372,11.296308,0,0
36019757.45,,5905,3.41364,3.4602,0.131,9.4E-6,3.4551601,0.062447925,0,0,0.50532311,0.002306,0.50532311,0.002306,29.598499,0.15424693,0,100,,,1,,,,3.2761E-6,0.2908179,11.938132,0,0
36019804.11,,5905,3.4159,3.4624,0.131,9.2E-6,3.4595953,0.064742902,0,0,0.50609006,0.005227,0.50609006,0.005227,0.30035732,0.15346003,0,100,,,1,,,,3.2979E-6,0.3085695,11.9688,0,0
36019854.36,,5905,3.41814,3.464,0.131,9.3E-6,3.4628518,0.064752819,0,0,0.50692961,0.002518,0.50692961,0.002518,15.272978,0.15605357,0,100,,,1,,,,3.2484E-6,0.3071413,11.991342,0,0
36019904.06,,5905,3.42078,3.4657,0.131,9.3E-6,3.4621758,0.06427605,0,0,0.50759378,0.00231,0.50759378,0.00231,10.281919,0.15403685,0,100,,,1,,,,3.2953E-6,0.3060044,11.986661,0,0
36020098.73,,5905,3.51398,3.562,0.131,9.3E-6,3.557196,0.064949098,0,0,0.54726869,0.002563,0.54726869,0.002563,1.1289587,0.16157698,0,100,,,1,,,,3.387E-6,0.3088202,12.653643,0,0
36020148.47,,5905,3.51863,3.5663,0.131,9.3E-6,3.5617083,0.065819786,0,0,0.54628191,0.002154,0.54628191,0.002154,1.0041698,0.15941003,0,100,,,1,,,,3.4269E-6,0.3166812,12.685766,0,0
36020199.92,,5905,3.5209,3.5713,0.131,9.2E-6,3.5659384,0.066428797,0,0,0.54767879,0.002791,0.54767879,0.002791,1.0668054,0.16067711,0,100,,,1,,,,3.4086E-6,0.3199075,12.715917,0,0
36020250.42,,5905,3.52104,3.5698,0.131,9.2E-6,3.566175,0.067491121,0,0,0.54964259,0.002371,0.54964259,0.002371,2.8491472,0.16193016,0,100,,,1,,,,3.3943E-6,0.3274535,12.717604,0,0
36020445.3,,5905,3.61634,3.6663,0.131,9.2E-6,3.6606347,0.066112253,0,0,0.58961508,0.002486,0.58961508,0.002486,1.3734222,0.1695587,0,100,,,1,,,,3.4774E-6,0.3148515,13.400246,0,0
36020492.02,,5905,3.62008,3.6701,0.131,9.3E-6,3.6647749,0.068941041,0,0,0.59081831,0.002277,0.59081831,0.002277,11.003798,0.16756929,0,100,,,1,,,,3.5258E-6,0.3390348,13.430575,0,0
36020545.22,,5905,3.62235,3.6735,0.131,9.3E-6,3.6661099,0.068683077,0,0,0.59250124,0.002577,0.59250124,0.002577,7.7856492,0.1682106,0,100,,,1,,,,3.5224E-6,0.336613,13.440362,0,0
36020593.11,,5905,3.62415,3.6745,0.131,9.2E-6,3.6688223,0.067609135,0,0,0.59255148,0.002375,0.59255148,0.002375,6.3943843,0.16770226,0,100,,,1,,,,3.5334E-6,0.3274705,13.460257,0,0
36020788.52,,5905,3.71731,3.7685,0.131,9.4E-6,3.7625446,0.068904117,0,0,0.63353151,0.004029,0.63353151,0.004029,0.80466028,0.17260719,0,100,,,1,,,,3.6704E-6,0.3386321,14.156742,0,0
36020835.5,,5905,3.72032,3.7742,0.131,9.3E-6,3.7661807,0.071270755,0,0,0.63810503,0.002907,0.63810503,0.002907,3.9512491,0.17689196,0,100,,,1,,,,3.6073E-6,0.3546308,14.184117,0,0
36020886.41,,5905,3.72258,3.776,0.131,9.4E-6,3.7691634,0.070561186,0,0,0.63680635,0.002836,0.63680635,0.002836,4.1184759,0.17609591,0,100,,,1,,,,3.6162E-6,0.3477135,14.206592,0,0
36020938.92,,5905,3.72575,3.7778,0.131,9.2E-6,3.7710446,0.070967183,0,0,0.63814191,0.003617,0.63814191,0.003617,0.79437601,0.17575218,0,100,,,1,,,,3.6309E-6,0.3523874,14.220777,0,0
36021133.48,,5905,3.8216,3.8706,0.131,9.4E-6,3.8666376,0.071257369,0,0,0.68271763,0.003024,0.68271763,0.003024,5.8849943,0.18253804,0,100,,,1,,,,3.7401E-6,0.3530315,14.950887,0,0
36021180.8,,5905,3.8246,3.8752,0.131,9.4E-6,3.8687727,0.072381883,0,0,0.68481813,0.002586,0.68481813,0.002586,6.0430696,0.18178301,0,100,,,1,,,,3.7672E-6,0.363313,14.967402,0,0
36021228.75,,5905,3.82477,3.8751,0.131,9.2E-6,3.8717129,0.07142376,0,0,0.68465511,0.002786,0.68465511,0.002786,5.4911297,0.18220308,0,100,,,1,,,,3.7576E-6,0.3551582,14.99016,0,0
36021276.72,,5905,3.82694,3.8798,0.131,9.4E-6,3.8743238,0.073066947,0,0,0.68777944,0.003209,0.68777944,0.003209,4.1146384,0.18549678,0,100,,,1,,,,3.7078E-6,0.3656317,15.010385,0,0
36021470.25,,5905,3.9213,3.9739,0.131,9.4E-6,3.9665109,0.073419039,0,0,0.73040642,0.002955,0.73040642,0.002955,3.006056,0.1884167,0,100,,,1,,,,3.8765E-6,0.369715,15.733209,0,0
36021522.94,,5905,3.92309,3.9743,0.131,9.2E-6,3.9717227,0.0743637,0,0,0.73231808,0.003089,0.73231808,0.003089,0.71306715,0.18912202,0,100,,,1,,,,3.8722E-6,0.375402,15.774581,0,0
36021572.7,,5905,3.92585,3.9765,0.131,9.3E-6,3.9753789,0.074351882,0,0,0.73426138,0.003862,0.73426138,0.003862,1.3709523,0.18875199,0,100,,,1,,,,3.8901E-6,0.3771523,15.803637,0,0
36021624.17,,5905,3.9278,3.9788,0.131,9.3E-6,3.975145,0.074179944,0,0,0.73368048,0.002261,0.73368048,0.002261,1.1264659,0.18772492,0,100,,,1,,,,3.9083E-6,0.3755417,15.801778,0,0
36021817.73,,5905,4.02195,4.0747,0.131,9.2E-6,4.0709577,0.07549707,0,0,0.78404988,0.003158,0.78404988,0.003158,7.0239734,0.19659098,0,100,,,1,,,,3.9882E-6,0.3845985,16.572696,0,0
36021864.64,,5905,4.02476,4.0776,0.131,9.2E-6,4.0745166,0.076528196,0,0,0.78576015,0.002805,0.78576015,0.002805,0.47424456,0.19643515,0,100,,,1,,,,4.0001E-6,0.39307,16.601685,0,0
36021914.72,,5905,4.02922,4.084,0.131,9.3E-6,4.0774202,0.076638262,0,0,0.78644128,0.003271,0.78644128,0.003271,1.3208301,0.19685758,0,100,,,1,,,,3.995E-6,0.3923537,16.625356,0,0
36021965.72,,5905,4.02966,4.0844,0.131,9.3E-6,4.0801087,0.077080418,0,0,0.79111835,0.003445,0.79111835,0.003445,1.1111471,0.20045011,0,100,,,1,,,,3.9467E-6,0.3946721,16.647287,0,0
36022174.48,,5905,4.12473,4.1791,0.131,9.4E-6,4.174118,0.076656741,0,0,0.83458772,0.002538,0.83458772,0.002538,3.4548351,0.19948451,0,100,,,1,,,,4.1837E-6,0.3939292,17.423261,0,0
36022224.61,,5905,4.12723,4.1794,0.131,9.4E-6,4.1775509,0.079117666,0,0,0.84127628,0.004459,0.84127628,0.004459,2.2286326,0.20617243,0,100,,,1,,,,4.0805E-6,0.4094096,17.451931,0,0
36022274.58,,5905,4.12974,4.1847,0.131,9.3E-6,4.1817126,0.078833736,0,0,0.83529469,0.002845,0.83529469,0.002845,4.9540511,0.20126066,0,100,,,1,,,,4.1503E-6,0.4086095,17.48672,0,0
36022325.28,,5905,4.13232,4.1862,0.131,9.4E-6,4.1826964,0.078610525,0,0,0.84245757,0.006703,0.84245757,0.006703,0.38056514,0.20398611,0,100,,,1,,,,4.13E-6,0.4075389,17.494949,0,0
36022529.48,,5905,4.22549,4.2793,0.131,9.4E-6,4.2768025,0.079463743,0,0,0.89527575,0.003749,0.89527575,0.003749,1.3584599,0.21375912,0,100,,,1,,,,4.1882E-6,0.4091064,18.29104,0,0
36022588,,5905,4.22999,4.2836,0.131,9.4E-6,4.2823927,0.081372455,0,0,0.89225357,0.00392,0.89225357,0.00392,0.97626195,0.20750826,0,100,,,1,,,,4.2998E-6,0.4295075,18.338887,0,0
36022639.73,,5905,4.23076,4.2847,0.131,9.4E-6,4.2823837,0.080635214,0,0,0.89856753,0.003614,0.89856753,0.003614,2.3518034,0.21441161,0,100,,,1,,,,4.1909E-6,0.4179688,18.33881,0,0
36022692.23,,5905,4.23366,4.2885,0.131,9.4E-6,4.2859155,0.080431893,0,0,0.89859526,0.005211,0.89859526,0.005211,0.70791092,0.2123944,0,100,,,1,,,,4.2308E-6,0.418318,18.369072,0,0
36022886.11,,5905,4.32657,4.3813,0.131,9.3E-6,4.381077,0.081719406,0,0,0.96082306,0.003844,0.96082306,0.003844,71.317466,0.22372283,0,100,,,1,,,,4.2947E-6,0.427023,19.193836,0,0
36022936.08,,5905,4.33254,4.3843,0.131,9.4E-6,4.3888329,0.082950659,0,0,0.95671471,0.002844,0.95671471,0.002844,22.887483,0.21842477,0,100,,,1,,,,4.3801E-6,0.4396842,19.261854,0,0
36022983.78,,5905,4.3334,4.3837,0.131,9.4E-6,4.3886518,0.083035286,0,0,0.95976158,0.00327,0.95976158,0.00327,8.1874448,0.22059613,0,100,,,1,,,,4.3508E-6,0.4390107,19.260264,0,0
36023031.91,,5905,4.3346,4.384,0.131,9.2E-6,4.3895131,0.083563702,0,0,0.9636761,0.003561,0.9636761,0.003561,5.0938034,0.22196181,0,100,,,1,,,,4.3416E-6,0.4453401,19.267825,0,0
36023229.83,,5905,4.42891,4.4809,0.131,9.4E-6,4.4838488,0.083726377,0,0,1.020199,0.003225,1.020199,0.003225,10.270639,0.22626979,0,100,,,1,,,,4.5088E-6,0.4467275,20.1049,0,0
36023285.52,,5905,4.43331,4.4851,0.131,9.2E-6,4.4896321,0.08494824,0,0,1.0189944,0.003321,1.0189944,0.003321,6.9765407,0.22656805,0,100,,,1,,,,4.4975E-6,0.4557669,20.156796,0,0
36023333.56,,5905,4.43462,4.4875,0.131,9.2E-6,4.491053,0.084175221,0,0,1.0232801,0.00316,1.0232801,0.00316,14.902485,0.22657915,0,100,,,1,,,,4.5162E-6,0.4507826,20.169557,0,0
36023381.86,,5905,4.43707,4.4906,0.131,9.2E-6,4.492781,0.085050598,0,0,1.0231317,0.003676,1.0231317,0.003676,9.0774572,0.22975191,0,100,,,1,,,,4.4532E-6,0.4532274,20.185081,0,0
36023574.8,,5905,4.53066,4.5831,0.131,9.2E-6,4.5855342,0.085386696,0,0,1.0766609,0.002991,1.0766609,0.002991,0.84919119,0.22959858,0,100,,,1,,,,4.6893E-6,0.4601425,21.027124,0,0
36023625.31,,5905,4.53327,4.586,0.131,9.4E-6,4.5890578,0.086458617,0,0,1.0828639,0,1.0828639,0,2.2166939,0.23456225,0,100,,,1,,,,4.6165E-6,0.4658222,21.059451,0,0
36023675.64,,5905,4.53462,4.5883,0.131,9.4E-6,4.5920828,0.086723147,0,0,1.0862324,0.003952,1.0862324,0.003952,7.3104117,0.2383123,0,100,,,1,,,,4.558E-6,0.4654246,21.087225,0,0
36023724,,5905,4.53722,4.5915,0.131,9.2E-6,4.5946018,0.086668362,0,0,1.08011,0.003195,1.08011,0.003195,1.2641319,0.22963131,0,100,,,1,,,,4.7037E-6,0.4709134,21.110365,0,0
36023919.73,,5905,4.63008,4.6845,0.131,9.3E-6,4.6879723,0.087832014,0,0,1.1452118,0.003645,1.1452118,0.003645,1.3888346,0.2438072,0,100,,,1,,,,4.6972E-6,0.4723512,21.977085,0,0
36023971,,5905,4.63449,4.6916,0.131,9.2E-6,4.6924742,0.087796343,0,0,1.1430012,0.003037,1.1430012,0.003037,27.068556,0.23761658,0,100,,,1,,,,4.8103E-6,0.4764926,22.019315,0,0
36024021.55,,5905,4.63736,4.693,0.131,9.2E-6,4.6945085,0.088759906,0,0,1.1481417,0.00319,1.1481417,0.00319,8.329226,0.2407324,0,100,,,1,,,,4.7694E-6,0.4839663,22.03841,0,0
36024071.89,,5905,4.64008,4.6964,0.131,9.2E-6,4.6971297,0.08953769,0,0,1.1469258,0.003176,1.1469258,0.003176,2.1187566,0.2381746,0,100,,,1,,,,4.8155E-6,0.4925243,22.063027,0,0
36024268.06,,5905,4.73262,4.7925,0.131,9.3E-6,4.7905874,0.089507918,0,0,1.2105047,0.003395,1.2105047,0.003395,9.1846539,0.24822979,0,100,,,1,,,,4.8765E-6,0.4868946,22.949727,0,0
36024316.63,,5905,4.73642,4.796,0.131,9.4E-6,4.7952859,0.090927369,0,0,1.2150753,0.006142,1.2150753,0.006142,0.93406812,0.24947178,0,100,,,1,,,,4.8706E-6,0.4998933,22.994767,0,0
36024367,,5905,4.73819,4.7979,0.131,9.2E-6,4.797261,0.091331442,0,0,1.2223535,0.00435,1.2223535,0.00435,6.1076964,0.25372708,0,100,,,1,,,,4.8176E-6,0.4999129,23.013713,0,0
36024415.81,,5905,4.74166,4.8015,0.131,9.2E-6,4.7987048,0.091376205,0,0,1.2245676,0.004005,1.2245676,0.004005,15.562111,0.25258217,0,100,,,1,,,,4.8482E-6,0.5030545,23.027567,0,0
36024607.92,,5905,4.83248,4.8953,0.131,9.4E-6,4.8922763,0.090998306,0,0,1.2818349,0.003457,1.2818349,0.003457,0.94375897,0.25248817,0,100,,,1,,,,5.0768E-6,0.5014291,23.934367,0,0
36024659,,5905,4.8372,4.9001,0.131,9.2E-6,4.8968038,0.092767291,0,0,1.2903839,0.003918,1.2903839,0.003918,15.301639,0.25758444,0,100,,,1,,,,5.0096E-6,0.514601,23.978688,0,0
36024706.75,,5905,4.83972,4.9017,0.131,9.3E-6,4.8989674,0.093145855,0,0,1.2971862,0.00474,1.2971862,0.00474,7.2613307,0.26269943,0,100,,,1,,,,4.9379E-6,0.5143159,23.999882,0,0
36024757.47,,5905,4.84224,4.9042,0.131,9.4E-6,4.9012563,0.092177466,0,0,1.2922149,0.003615,1.2922149,0.003615,12.338311,0.25649356,0,100,,,1,,,,5.038E-6,0.5089266,24.022314,0,0
36024959.95,,5905,4.93455,5.0005,0.131,9.2E-6,4.996007,0.09232314,0,0,1.3627006,0.004251,1.3627006,0.004251,2.4855146,0.26243744,0,100,,,1,,,,5.1925E-6,0.5121668,24.960086,0,0
36025011.25,,5905,4.93792,5.0051,0.131,9.2E-6,5.0007594,0.094428553,0,0,1.3660664,0.00472,1.3660664,0.00472,2.1700953,0.26392125,0,100,,,1,,,,5.176E-6,0.5288467,25.007595,0,0
36025061.63,,5905,4.9418,5.0055,0.131,9.2E-6,5.0027096,0.096062623,0,0,1.3739305,0.004542,1.3739305,0.004542,18.792802,0.26927656,0,100,,,1,,,,5.1023E-6,0.5395708,25.027104,0,0
36025114.89,,5905,4.94543,5.0129,0.131,9.4E-6,5.0064235,0.095627224,0,0,1.3701362,0.003927,1.3701362,0.003927,1.6543801,0.2653293,0,100,,,1,,,,5.1639E-6,0.5380894,25.064276,0,0
36025306.91,,5905,5.03514,5.1009,0.131,9.4E-6,5.0959052,0.09522132,0,0,1.4441123,0.005253,1.4441123,0.005253,11.634663,0.27848664,0,100,,,1,,,,5.1856E-6,0.526838,25.96825,0,0
36025356.56,,5905,5.03805,5.1026,0.131,9.3E-6,5.1018352,0.096792168,0,0,1.4438737,0.003933,1.4438737,0.003933,4.9917761,0.2727299,0,100,,,1,,,,5.2942E-6,0.5468176,26.028722,0,0
36025407.03,,5905,5.04066,5.1043,0.131,9.3E-6,5.1057771,0.097191928,0,0,1.4428395,0.004777,1.4428395,0.004777,2.1951922,0.27070593,0,100,,,1,,,,5.3299E-6,0.5513123,26.06896,0,0
36025457.52,,5905,5.04455,5.1133,0.131,9.3E-6,5.1073275,0.096688266,0,0,1.4441993,0.004114,1.4441993,0.004114,3.2123403,0.2707713,0,100,,,1,,,,5.3337E-6,0.547238,26.084794,0,0
36025648.88,,5905,5.13756,5.2025,0.131,9.4E-6,5.1982019,0.097425276,0,0,1.5222236,0.005198,1.5222236,0.005198,3.6662683,0.28354073,0,100,,,1,,,,5.3686E-6,0.5470294,27.021303,0,0
36025699.56,,5905,5.14067,5.2074,0.131,9.3E-6,5.2040826,0.099364262,0,0,1.5195205,0.003662,1.5195205,0.003662,4.4864227,0.27606615,0,100,,,1,,,,5.5042E-6,0.5709813,27.082476,0,0
36025750.25,,5905,5.14408,5.2121,0.131,9.3E-6,5.2066539,0.099074878,0,0,1.5290139,0.004357,1.5290139,0.004357,11.19978,0.28220837,0,100,,,1,,,,5.418E-6,0.5638322,27.109245,0,0
36025803.5,,5905,5.14705,5.2141,0.131,9.4E-6,5.2097246,0.099442293,0,0,1.5339893,0.005051,1.5339893,0.005051,15.133884,0.28537801,0,100,,,1,,,,5.3753E-6,0.5650914,27.141231,0,0
36025993.2,,5905,5.2386,5.3069,0.131,9.4E-6,5.3025728,0.099727959,0,0,1.6051436,0.005042,1.6051436,0.005042,29.175652,0.28982717,0,100,,,1,,,,5.5383E-6,0.5661239,28.117278,0,0
36026041.06,,5905,5.24225,5.3097,0.131,9.2E-6,5.3047416,0.10169952,0,0,1.6130272,0.005094,1.6130272,0.005094,14.081265,0.29250618,0,100,,,1,,,,5.5145E-6,0.5840061,28.140284,0,0
36026089.02,,5905,5.24496,5.3145,0.131,9.3E-6,5.3096493,0.10226217,0,0,1.6097937,0.004542,1.6097937,0.004542,18.622154,0.29138515,0,100,,,1,,,,5.5246E-6,0.5867382,28.192376,0,0
36026136.47,,5905,5.24663,5.3146,0.131,9.3E-6,5.3132893,0.10099759,0,0,1.6107076,0.004449,1.6107076,0.004449,2.5431304,0.2894102,0,100,,,1,,,,5.5655E-6,0.5777372,28.231043,0,0
36026325.95,,5905,5.34049,5.4098,0.131,9.2E-6,5.4031777,0.10101196,0,0,1.6848193,0.004543,1.6848193,0.004543,2.6063892,0.29182929,0,100,,,1,,,,5.7733E-6,0.5799374,29.194329,0,0
36026379.38,,5905,5.34465,5.4138,0.131,9.2E-6,5.4100156,0.10413213,0,0,1.6911984,0.004566,1.6911984,0.004566,4.8983727,0.29782002,0,100,,,1,,,,5.6786E-6,0.602384,29.268269,0,0
36026428.14,,5905,5.34763,5.4143,0.131,9.4E-6,5.4127527,0.10372892,0,0,1.6943731,0.004569,1.6943731,0.004569,11.148388,0.29808726,0,100,,,1,,,,5.6842E-6,0.5983775,29.297891,0,0
36026476.73,,5905,5.34943,5.4176,0.131,9.3E-6,5.4152071,0.10453983,0,0,1.696725,0.004879,1.696725,0.004879,19.050517,0.30085806,0,100,,,1,,,,5.6396E-6,0.6032063,29.324468,0,0
36026670.48,,5905,5.44179,5.5089,0.131,9.3E-6,5.5065984,0.10367263,0,0,1.7824616,0.005506,1.7824616,0.005506,7.9868351,0.30580051,0,100,,,1,,,,5.8288E-6,0.5980485,30.322626,0,0
36026721.31,,5905,5.44607,5.5142,0.131,9.4E-6,5.511415,0.10524404,0,0,1.7818386,0.00486,1.7818386,0.00486,11.742416,0.3063325,0,100,,,1,,,,5.8167E-6,0.6103154,30.375696,0,0
36026769.34,,5905,5.44937,5.5166,0.131,9.3E-6,5.5155502,0.10506061,0,0,1.7814892,0.004382,1.7814892,0.004382,8.3405992,0.30192359,0,100,,,1,,,,5.9005E-6,0.613184,30.421294,0,0
36026820.22,,5905,5.45083,5.5175,0.131,9.2E-6,5.5192674,0.10623799,0,0,1.7837161,0,1.7837161,0,22.417112,0.3051674,0,100,,,1,,,,5.845E-6,0.6191483,30.462313,0,0
36027012.69,,5905,5.54345,5.6106,0.131,9.3E-6,5.6095161,0.10599065,0,0,1.8656474,0.004582,1.8656474,0.004582,20.95045,0.31020646,0,100,,,1,,,,6.0142E-6,0.6180871,31.466671,0,0
36027060.97,,5905,5.54818,5.6162,0.131,9.4E-6,5.6161992,0.10826011,0,0,1.8793165,0.005624,1.8793165,0.005624,18.944908,0.31750873,0,100,,,1,,,,5.9189E-6,0.6345878,31.541693,0,0
36027108.94,,5905,5.55044,5.6171,0.131,9.4E-6,5.6190693,0.10844801,0,0,1.882315,0.005745,1.882315,0.005745,1.9528335,0.31841938,0,100,,,1,,,,5.9114E-6,0.6350589,31.57394,0,0
36027156.86,,5905,5.55227,5.6184,0.131,9.4E-6,5.620766,0.10796917,0,0,1.8787702,0.005328,1.8787702,0.005328,13.035565,0.31658736,0,100,,,1,,,,5.9344E-6,0.6306337,31.593011,0,0
36027356.34,,5905,5.6445,5.7106,0.131,9.2E-6,5.713543,0.10839409,0,0,1.9611062,0.005252,1.9611062,0.005252,5.7446901,0.32118887,0,100,,,1,,,,6.1058E-6,0.6336164,32.644573,0,0
36027404.25,,5905,5.6486,5.7148,0.131,9.4E-6,5.716098,0.10960633,0,0,1.9745687,0.00638,1.9745687,0.00638,1.5087467,0.32638012,0,100,,,1,,,,6.0499E-6,0.6435687,32.673777,0,0
36027452.25,,5905,5.65262,5.7178,0.131,9.3E-6,5.7196719,0.10945677,0,0,1.9745895,0.00629,1.9745895,0.00629,24.126288,0.32777747,0,100,,,1,,,,6.0242E-6,0.6387596,32.714647,0,0
36027500.06,,5905,5.6547,5.7199,0.131,9.3E-6,5.7235861,0.10999238,0,0,1.9738183,0.005717,1.9738183,0.005717,12.074727,0.32464041,0,100,,,1,,,,6.08E-6,0.6470126,32.759437,0,0
36027695.45,,5905,5.74677,5.8119,0.131,9.3E-6,5.8138761,0.11060751,0,0,2.0662905,0.007018,2.0662905,0.007018,4.1827077,0.33388386,0,100,,,1,,,,6.1887E-6,0.6494595,33.801155,0,0
36027743.47,,5905,5.75115,5.8176,0.131,9.3E-6,5.8195782,0.11154931,0,0,2.0656834,0.005935,2.0656834,0.005935,10.093695,0.33390486,0,100,,,1,,,,6.1864E-6,0.656924,33.867491,0,0
36027791.8,,5905,5.75471,5.82,0.131,9.3E-6,5.8231126,0.11121096,0,0,2.0676401,0.00599,2.0676401,0.00599,2.5950843,0.33259712,0,100,,,1,,,,6.2167E-6,0.6547858,33.90864,0,0
36027840.08,,5905,5.75612,5.8228,0.131,9.2E-6,5.8257232,0.11274982,0,0,2.0723288,0.006066,2.0723288,0.006066,3.7149309,0.33524409,0,100,,,1,,,,6.1816E-6,0.6674699,33.939051,0,0
36028032.83,,5905,5.84748,5.9149,0.131,9.3E-6,5.917241,0.11230352,0,0,2.1593541,0.006645,2.1593541,0.006645,14.623269,0.34403469,0,100,,,1,,,,6.2766E-6,0.6568046,35.013741,0,0
36028081.25,,5905,5.85308,5.9211,0.131,9.2E-6,5.9219996,0.11421593,0,0,2.1676863,0.006976,2.1676863,0.006976,3.6597993,0.34218038,0,100,,,1,,,,6.3349E-6,0.6800721,35.070079,0,0
36028129.77,,5905,5.85515,5.9225,0.131,9.4E-6,5.9246054,0.11386285,0,0,2.1651554,0.005764,2.1651554,0.005764,7.6167521,0.33922726,0,100,,,1,,,,6.3826E-6,0.6790301,35.100949,0,0
36028178.31,,5905,5.85761,5.925,0.131,9.4E-6,5.9287297,0.11416555,0,0,2.1675864,0.005637,2.1675864,0.005637,6.6149303,0.3386607,0,100,,,1,,,,6.4005E-6,0.6822953,35.149836,0,0
36028370.86,,5905,5.94887,6.0173,0.131,9.4E-6,6.0191675,0.11605936,0,0,2.2629511,0.007542,2.2629511,0.007542,2.7818987,0.35133278,0,100,,,1,,,,6.441E-6,0.6928794,36.230378,0,0
36028420.88,,5905,5.95271,6.0212,0.131,9.2E-6,6.0236095,0.11590171,0,0,2.2686201,0.007164,2.2686201,0.007164,4.956754,0.35174265,0,100,,,1,,,,6.4497E-6,0.6912473,36.283872,0,0
36028469.28,,5905,5.95663,6.0263,0.131,9.4E-6,6.0266112,0.11580281,0,0,2.2682682,0.006247,2.2682682,0.006247,9.8979234,0.34499897,0,100,,,1,,,,6.5747E-6,0.6980271,36.320043,0,0
36028517.61,,5905,5.95965,6.0268,0.131,9.2E-6,6.0302312,0.11542184,0,0,2.2632057,0.005487,2.2632057,0.005487,5.1772384,0.34382156,0,100,,,1,,,,6.5825E-6,0.6917776,36.363688,0,0
36028710.27,,5905,6.05135,6.1225,0.131,9.2E-6,6.1220924,0.11651255,0,0,2.3656858,0.006172,2.3656858,0.006172,6.7975121,0.35273138,0,100,,,1,,,,6.7068E-6,0.7021395,37.480016,0,0
36028761.13,,5905,6.05602,6.1283,0.131,9.3E-6,6.1272486,0.11907912,0,0,2.3693119,0.006692,2.3693119,0.006692,18.359095,0.35584313,0,100,,,1,,,,6.6583E-6,0.7240744,37.543176,0,0
36028813.11,,5905,6.05917,6.1313,0.131,9.4E-6,6.1305129,0.11777416,0,0,2.3671684,0.005998,2.3671684,0.005998,4.3253538,0.35466854,0,100,,,1,,,,6.6743E-6,0.7096057,37.583189,0,0
36028863.94,,5905,6.06157,6.1346,0.131,9.2E-6,6.1330522,0.11932077,0,0,2.3813133,0.007231,2.3813133,0.007231,2.6746688,0.36308689,0,100,,,1,,,,6.5585E-6,0.7198535,37.614329,0,0
36029057.06,,5905,6.14878,6.223,0.131,9.4E-6,6.2210539,0.11864832,0,0,2.4686163,0.007499,2.4686163,0.007499,2.1753231,0.36687793,0,100,,,1,,,,6.7287E-6,0.7112827,38.701512,0,0
36029105.17,,5905,6.15436,6.2316,0.131,9.3E-6,6.2278106,0.12010277,0,0,2.4698202,0.006418,2.4698202,0.006418,1.5098167,0.36101446,0,100,,,1,,,,6.8413E-6,0.732474,38.785625,0,0
36029153.38,,5905,6.15736,6.2352,0.131,9.4E-6,6.2304481,0.11905228,0,0,2.471531,0.006015,2.471531,0.006015,12.734019,0.3612351,0,100,,,1,,,,6.8419E-6,0.7193047,38.818483,0,0
36029201.22,,5905,6.16134,6.2386,0.131,9.2E-6,6.2328126,0.11949539,0,0,2.4793265,0.006609,2.4793265,0.006609,6.505427,0.36533082,0,100,,,1,,,,6.7865E-6,0.7207433,38.847952,0,0
36029469.5,,5905,6.26924,6.3457,0.131,9.3E-6,6.3447855,0.11943618,0,0,2.5906436,0.008155,2.5906436,0.008155,0.3103165,0.37013913,0,100,,,1,,,,6.9991E-6,0.7210553,40.256303,0,0
36029518.67,,5905,6.26488,6.3406,0.131,9.2E-6,6.3381788,0.12232722,0,0,2.5931531,0.006804,2.5931531,0.006804,9.242479,0.37515433,0,100,,,1,,,,6.9122E-6,0.7445,40.172511,0,0
36029567.33,,5905,6.26604,6.3418,0.131,9.4E-6,6.3397944,0.12334959,0,0,2.5882125,0.006905,2.5882125,0.006905,11.733428,0.37655088,0,100,,,1,,,,6.8735E-6,0.7499579,40.192993,0,0
36029615.58,,5905,6.26611,6.3426,0.131,9.3E-6,6.3416805,0.12296244,0,0,2.5919181,0.007114,2.5919181,0.007114,3.6618625,0.37565219,0,100,,,1,,,,6.8998E-6,0.7482751,40.216911,0,0
36029803.38,,5905,6.35312,6.4328,0.131,9.3E-6,6.4271018,0.12261465,0,0,2.6822477,0.006744,2.6822477,0.006744,10.783243,0.37928987,0,100,,,1,,,,7.0718E-6,0.7449606,41.307637,0,0
36029851.61,,5905,6.35724,6.4376,0.131,9.4E-6,6.4337283,0.12429535,0,0,2.6910118,0.006557,2.6910118,0.006557,3.9492846,0.38140977,0,100,,,1,,,,7.0554E-6,0.7610201,41.39286,0,0
36029899.83,,5905,6.36013,6.44,0.131,9.2E-6,6.4360957,0.12505573,0,0,2.7042558,0.007173,2.7042558,0.007173,13.642948,0.38431477,0,100,,,1,,,,7.0366E-6,0.767618,41.423328,0,0
36029949.19,,5905,6.36365,6.4447,0.131,9.3E-6,6.4410712,0.12501083,0,0,2.7060146,0.007246,2.7060146,0.007246,12.445758,0.38428329,0,100,,,1,,,,7.0417E-6,0.7668321,41.487398,0,0
36030135.5,,5905,6.45266,6.5375,0.131,9.4E-6,6.5293214,0.12574884,0,0,2.8116081,0.009273,2.8116081,0.009273,3.1854047,0.39570585,0,100,,,1,,,,7.1053E-6,0.7675515,42.632038,0,0
36030183.88,,5905,6.45732,6.5408,0.131,9.3E-6,6.5339574,0.12598858,0,0,2.8195861,0.008497,2.8195861,0.008497,15.435197,0.39699812,0,100,,,1,,,,7.1023E-6,0.7699149,42.6926,0,0
36030232.14,,5905,6.46272,6.5474,0.131,9.2E-6,6.5397807,0.12674298,0,0,2.8086549,0.007143,2.8086549,0.007143,3.8521217,0.38691916,0,100,,,1,,,,7.259E-6,0.7842328,42.768732,0,0
36030280.3,,5905,6.46418,6.5472,0.131,9.4E-6,6.5419662,0.12693386,0,0,2.8179478,0.008032,2.8179478,0.008032,14.676259,0.39318812,0,100,,,1,,,,7.1669E-6,0.7814272,42.797321,0,0
36030466.73,,5905,6.55336,6.6378,0.131,9.3E-6,6.6328213,0.12580866,0,0,2.9234557,0.007731,2.9234557,0.007731,8.5320523,0.39674342,0,100,,,1,,,,7.3686E-6,0.7710759,43.994318,0,0
36030514.91,,5905,6.55954,6.6425,0.131,9.2E-6,6.6380648,0.12897675,0,0,2.9394325,0.008648,2.9394325,0.008648,10.597978,0.39948619,0,100,,,1,,,,7.358E-6,0.8045915,44.063904,0,0
36030564.92,,5905,6.56493,6.6482,0.131,9.3E-6,6.6423335,0.12834116,0,0,2.9410468,0.008789,2.9410468,0.008789,16.680592,0.39940122,0,100,,,1,,,,7.3636E-6,0.7965773,44.120594,0,0
36030613.98,,5905,6.56658,6.6503,0.131,9.3E-6,6.6458871,0.12830807,0,0,2.9426052,0.008808,2.9426052,0.008808,2.400631,0.39962538,0,100,,,1,,,,7.3634E-6,0.7960813,44.167815,0,0
36030804.78,,5905,6.65843,6.7435,0.131,9.4E-6,6.7355234,0.12829009,0,0,3.0448647,0.008212,3.0448647,0.008212,6.3670364,0.40386555,0,100,,,1,,,,7.5393E-6,0.795539,45.367276,0,0
36030853,,5905,6.66284,6.7474,0.131,9.2E-6,6.7414521,0.13069367,0,0,3.058493,0.009587,3.058493,0.009587,5.5099465,0.41091933,0,100,,,1,,,,7.443E-6,0.8130388,45.447177,0,0
36030904.06,,5905,6.66729,6.7494,0.131,9.4E-6,6.7464253,0.13107788,0,0,3.0623532,0.008466,3.0623532,0.008466,6.4375384,0.40912069,0,100,,,1,,,,7.4852E-6,0.8187474,45.514254,0,0
36030955.27,,5905,6.67059,6.7558,0.131,9.4E-6,6.7480354,0.13015074,0,0,3.0728107,0.009308,3.0728107,0.009308,17.133064,0.4133451,0,100,,,1,,,,7.434E-6,0.8074053,45.535982,0,0
36031139.8,,5905,6.75814,6.8419,0.131,9.2E-6,6.8372455,0.13114245,0,0,3.1695305,0.008195,3.1695305,0.008195,9.2534243,0.41519841,0,100,,,1,,,,7.6338E-6,0.8162188,46.747926,0,0
36031188.77,,5905,6.7637,6.8465,0.131,9.4E-6,6.8419743,0.1332965,0,0,3.1832059,0.008664,3.1832059,0.008664,2.2170243,0.42012653,0,100,,,1,,,,7.5768E-6,0.8357233,46.812613,0,0
36031237.3,,5905,6.76799,6.8513,0.131,9.4E-6,6.8473667,0.13307907,0,0,3.1872512,0.008395,3.1872512,0.008395,2.8432174,0.42057434,0,100,,,1,,,,7.5783E-6,0.8320205,46.886431,0,0
36031285.66,,5905,6.77005,6.8523,0.131,9.2E-6,6.8498055,0.13289107,0,0,3.1965688,0.009451,3.1965688,0.009451,8.8665436,0.42039068,0,100,,,1,,,,7.6038E-6,0.8324975,46.919836,0,0
36031471.91,,5905,6.86063,6.9414,0.131,9.2E-6,6.9420661,0.13264436,0,0,3.2997223,0.009172,3.2997223,0.009172,9.4959792,0.42439287,0,100,,,1,,,,7.7752E-6,0.8283402,48.192281,0,0
36031520.39,,5905,6.86516,6.9455,0.131,9.3E-6,6.9469454,0.13588067,0,0,3.3115574,0.009831,3.3115574,0.009831,12.929899,0.42907771,0,100,,,1,,,,7.7179E-6,0.858571,48.260051,0,0
36031568.84,,5905,6.87036,6.9517,0.131,9.4E-6,6.9513174,0.13495266,0,0,3.3138619,0.00865,3.3138619,0.00865,7.3661324,0.42527973,0,100,,,1,,,,7.7922E-6,0.8520795,48.320813,0,0
36031617.2,,5905,6.87127,6.9531,0.131,9.4E-6,6.9536628,0.1355195,0,0,3.3186231,0.008839,3.3186231,0.008839,6.1374418,0.4280168,0,100,,,1,,,,7.7535E-6,0.8547918,48.353427,0,0
36031804.53,,5905,6.96282,7.0445,0.131,9.3E-6,7.0436156,0.13644374,0,0,3.435732,0.009684,3.435732,0.009684,4.903195,0.43629395,0,100,,,1,,,,7.8748E-6,0.8620862,49.612521,0,0
36031853.77,,5905,6.9682,7.0496,0.131,9.4E-6,7.0510013,0.13722037,0,0,3.4379582,0.009638,3.4379582,0.009638,9.0223213,0.43687735,0,100,,,1,,,,7.8694E-6,0.8680281,49.716619,0,0
36031902.3,,5905,6.9715,7.0535,0.131,9.3E-6,7.0543598,0.13774553,0,0,3.4473003,0.009923,3.4473003,0.009923,7.0216448,0.43520678,0,100,,,1,,,,7.9211E-6,0.8767347,49.763993,0,0
36031951.45,,5905,6.97468,7.0563,0.131,9.3E-6,7.0566906,0.137564,0,0,3.4475458,0.009338,3.4475458,0.009338,8.2483309,0.43581121,0,100,,,1,,,,7.9106E-6,0.8722949,49.796883,0,0
36032137.98,,5905,7.06401,7.1468,0.131,9.2E-6,7.1447206,0.13676209,0,0,3.5564368,0.009276,3.5564368,0.009276,5.6970318,0.44238304,0,100,,,1,,,,8.0393E-6,0.8608519,51.047033,0,0
36032189.2,,5905,7.07014,7.1518,0.131,9.2E-6,7.1515061,0.13829724,0,0,3.5594189,0.008288,3.5594189,0.008288,4.4699162,0.4386046,0,100,,,1,,,,8.1153E-6,0.8794181,51.14404,0,0
36032238.5,,5905,7.07162,7.154,0.131,9.2E-6,7.1551752,0.13859526,0,0,3.5728402,0.009925,3.5728402,0.009925,12.644811,0.44557375,0,100,,,1,,,,8.0185E-6,0.8771868,51.196533,0,0
36032287.34,,5905,7.07576,7.1573,0.131,9.4E-6,7.1585583,0.13984058,0,0,3.578938,0.009372,3.578938,0.009372,10.145202,0.44493976,0,100,,,1,,,,8.0436E-6,0.8919349,51.244957,0,0
36032480.69,,5905,7.16536,7.25,0.131,9.4E-6,7.2529669,0.14004474,0,0,3.713118,0.01078,3.713118,0.01078,46.315963,0.45654303,0,100,,,1,,,,8.1331E-6,0.8894796,52.60553,0,0
36032529.23,,5905,7.17104,7.2565,0.131,9.3E-6,7.2574218,0.14072343,0,0,3.7073967,0.008612,3.7073967,0.008612,21.228106,0.44907821,0,100,,,1,,,,8.2556E-6,0.9016302,52.670172,0,0
36032578.73,,5905,7.17499,7.2592,0.131,9.2E-6,7.2615417,0.14049454,0,0,3.7222168,0.008795,3.7222168,0.008795,10.680346,0.45019078,0,100,,,1,,,,8.2681E-6,0.9022327,52.729988,0,0
36032627.16,,5905,7.17805,7.2607,0.131,9.3E-6,7.2665134,0.14214496,0,0,3.7212004,0.009013,3.7212004,0.009013,14.705308,0.45236529,0,100,,,1,,,,8.2261E-6,0.9148988,52.802217,0,0
36032813.59,,5905,7.26902,7.351,0.131,9.3E-6,7.354744,0.14107772,0,0,3.8465564,0.009536,3.8465564,0.009536,5.1559477,0.45888732,0,100,,,1,,,,8.3824E-6,0.9006049,54.092259,0,0
36032864.83,,5905,7.27394,7.3536,0.131,9.4E-6,7.3617992,0.14329403,0,0,3.8602072,0.01077,3.8602072,0.01077,13.914663,0.46445077,0,100,,,1,,,,8.3113E-6,0.9214091,54.196087,0,0
36032917.02,,5905,7.27771,7.3601,0.131,9.3E-6,7.3646705,0.14253094,0,0,3.864159,0.01101,3.864159,0.01101,5.0555074,0.46471354,0,100,,,1,,,,8.3151E-6,0.9120255,54.238371,0,0
36032966.45,,5905,7.27961,7.3609,0.131,9.2E-6,7.3674213,0.142619,0,0,3.8749871,0.01019,3.8749871,0.01019,45.477755,0.46303978,0,100,,,1,,,,8.3686E-6,0.9184987,54.278896,0,0
[...]
36226676.41,,5905,12.6636,12.7026,89999.219,9.4E-6,12.797924,0.25507362,0,0,16.379159,0.04851,16.379159,0.04851,21.478606,0.98863503,0,100,,,1,,,,1.6567E-5,1.976032,163.78685,0,0
36226696.09,,5905,12.6643,12.7026,89999.219,9.2E-6,12.798441,0.25515467,0,0,16.378513,0.04695,16.378513,0.04695,23.191643,0.98788633,0,100,,,1,,,,1.6579E-5,1.97727,163.80008,0,0
36226716.69,,5905,12.6637,12.7029,89999.219,9.3E-6,12.799321,0.25494089,0,0,16.385374,0.04825,16.385374,0.04825,13.038823,0.98838653,0,100,,,1,,,,1.6578E-5,1.975773,163.82261,0,0
36226736.31,,5905,12.664,12.7035,89999.219,9.3E-6,12.799313,0.25509637,0,0,16.383844,0.04618,16.383844,0.04618,23.156685,0.98799705,0,100,,,1,,,,1.6583E-5,1.976773,163.82241,0,0
36226755.98,,5905,12.6639,12.7037,89999.219,9.4E-6,12.80019,0.25489896,0,0,16.38476,0.04541,16.38476,0.04541,17.965396,0.98634132,0,100,,,1,,,,1.6612E-5,1.975994,163.84485,0,0
36226932.03,,5905,12.9177,12.9499,89999.219,9.3E-6,13.051645,0.25547927,0,0,17.231632,0.05232,17.231632,0.05232,20.65497,1.0150426,0,100,,,1,,,,1.6976E-5,1.972683,170.34544,0,0
36226951.88,,5905,12.9185,12.9515,89999.219,9.2E-6,13.054926,0.26027086,0,0,17.231298,0.04913,17.231298,0.04913,12.850085,1.0158179,0,100,,,1,,,,1.6963E-5,2.030085,170.4311,0,0
36226971.66,,5905,12.9203,12.9516,89999.219,9.4E-6,13.056026,0.26032205,0,0,17.233392,0.04803,17.233392,0.04803,19.737356,1.0149979,0,100,,,1,,,,1.6979E-5,2.031636,170.45982,0,0
36226991.56,,5905,12.9211,12.9538,89999.219,9.3E-6,13.055888,0.26019785,0,0,17.238865,0.05002,17.238865,0.05002,24.534906,1.01619,0,100,,,1,,,,1.6964E-5,2.029996,170.45622,0,0
36227011.31,,5905,12.9215,12.9527,89999.219,9.2E-6,13.056453,0.26027927,0,0,17.241091,0.04975,17.241091,0.04975,17.624988,1.0158112,0,100,,,1,,,,1.6973E-5,2.03238,170.47097,0,0
36227031.17,,5905,12.9212,12.9544,89999.219,9.4E-6,13.056279,0.26035728,0,0,17.241522,0.04983,17.241522,0.04983,21.063038,1.0166576,0,100,,,1,,,,1.6959E-5,2.031622,170.46642,0,0
36227050.97,,5905,12.9216,12.9544,89999.219,9.2E-6,13.057735,0.26036668,0,0,17.241152,0.04938,17.241152,0.04938,23.774562,1.0150761,0,100,,,1,,,,1.6985E-5,2.033315,170.50445,0,0
36227070.86,,5905,12.9226,12.9553,89999.219,9.3E-6,13.058315,0.26015653,0,0,17.254096,0.04839,17.254096,0.04839,14.300678,1.0163845,0,100,,,1,,,,1.6976E-5,2.030152,170.51959,0,0
36227090.66,,5905,12.9225,12.9554,89999.219,9.4E-6,13.058696,0.26035119,0,0,17.252761,0.04881,17.252761,0.04881,16.51786,1.0166841,0,100,,,1,,,,1.697E-5,2.032769,170.52955,0,0
36227110.38,,5905,12.9229,12.9558,89999.219,9.4E-6,13.059235,0.26043225,0,0,17.254294,0.05007,17.254294,0.05007,15.710671,1.0161499,0,100,,,1,,,,1.698E-5,2.033368,170.54361,0,0
36227131.05,,5905,12.9234,12.9566,89999.219,9.3E-6,13.059553,0.2602331,0,0,17.24858,0.04785,17.24858,0.04785,12.817309,1.0149575,0,100,,,1,,,,1.6994E-5,2.0323,170.55191,0,0
36227151.72,,5905,12.924,12.9567,89999.219,9.2E-6,13.060314,0.26014478,0,0,17.250853,0.04973,17.250853,0.04973,24.035595,1.0157932,0,100,,,1,,,,1.6983E-5,2.029915,170.57179,0,0
36227329.02,,5905,13.1774,13.2086,89999.219,9.4E-6,13.314483,0.26102586,0,0,18.130514,0.05341,18.130514,0.05341,23.121582,1.0439805,0,100,,,1,,,,1.7367E-5,2.031586,177.27547,0,0
36227348.89,,5905,13.1787,13.2097,89999.219,9.3E-6,13.317882,0.26554293,0,0,18.143218,0.05325,18.143218,0.05325,21.014986,1.045588,0,100,,,1,,,,1.7352E-5,2.087961,177.36598,0,0
36227368.67,,5905,13.1795,13.2098,89999.219,9.4E-6,13.318902,0.26575842,0,0,18.15022,0.05248,18.15022,0.05248,24.862025,1.0453158,0,100,,,1,,,,1.7363E-5,2.091176,177.39315,0,0
36227388.48,,5905,13.1796,13.2105,89999.219,9.4E-6,13.319682,0.26572917,0,0,18.149342,0.05307,18.149342,0.05307,18.243222,1.0449414,0,100,,,1,,,,1.7369E-5,2.090632,177.41392,0,0
36227408.5,,5905,13.1804,13.2106,89999.219,9.4E-6,13.320163,0.26546892,0,0,18.151241,0.05324,18.151241,0.05324,21.325095,1.0443221,0,100,,,1,,,,1.7381E-5,2.089883,177.42674,0,0
36227428.45,,5905,13.1813,13.2106,89999.219,9.2E-6,13.320431,0.265374,0,0,18.151233,0.05309,18.151233,0.05309,20.085248,1.0434695,0,100,,,1,,,,1.7395E-5,2.088644,177.43389,0,0
36227448.31,,5905,13.1825,13.2117,89999.219,9.3E-6,13.320384,0.26534746,0,0,18.15016,0.05296,18.15016,0.05296,19.67082,1.0446473,0,100,,,1,,,,1.7374E-5,2.086939,177.43262,0,0
36227468.2,,5905,13.183,13.2127,89999.219,9.2E-6,13.32122,0.26575225,0,0,18.151229,0.05391,18.151229,0.05391,19.814949,1.0457743,0,100,,,1,,,,1.7357E-5,2.089295,177.45491,0,0
36227488.11,,5905,13.1809,13.2134,89999.219,9.3E-6,13.321747,0.26578387,0,0,18.161835,0.05302,18.161835,0.05302,16.717041,1.0457534,0,100,,,1,,,,1.7367E-5,2.091549,177.46894,0,0
36227508.05,,5905,13.1829,13.2142,89999.219,9.3E-6,13.322501,0.26583483,0,0,18.158605,0.05129,18.158605,0.05129,10.649548,1.04588,0,100,,,1,,,,1.7362E-5,2.091507,177.48904,0,0
36227528.05,,5905,13.1824,13.2137,89999.219,9.3E-6,13.322704,0.26581329,0,0,18.1527,0.05315,18.1527,0.05315,18.782495,1.0448895,0,100,,,1,,,,1.7373E-5,2.09176,177.49443,0,0
36227547.92,,5905,13.1827,13.2137,89999.219,9.4E-6,13.323125,0.26574031,0,0,18.155959,0.05389,18.155959,0.05389,12.748123,1.0460379,0,100,,,1,,,,1.7357E-5,2.089779,177.50566,0,0
36227725.47,,5905,13.4357,13.4663,89999.219,9.3E-6,13.575791,0.26633583,0,0,19.076938,0.05919,19.076938,0.05919,23.876297,1.0739107,0,100,,,1,,,,1.7764E-5,2.092076,184.3021,0,0
36227745.33,,5905,13.437,13.4668,89999.219,9.2E-6,13.579436,0.27080193,0,0,19.069421,0.05629,19.069421,0.05629,19.600308,1.0727682,0,100,,,1,,,,1.7776E-5,2.147821,184.40109,0,0
36227765.2,,5905,13.438,13.4664,89999.219,9.4E-6,13.579987,0.27047568,0,0,19.080439,0.0566,19.080439,0.0566,21.386154,1.0727083,0,100,,,1,,,,1.7787E-5,2.145536,184.41604,0,0
36227784.94,,5905,13.4392,13.4681,89999.219,9.2E-6,13.580852,0.27049576,0,0,19.08796,0.05837,19.08796,0.05837,22.056348,1.0740384,0,100,,,1,,,,1.7772E-5,2.145417,184.43955,0,0
36227804.72,,5905,13.4394,13.4687,89999.219,9.4E-6,13.581593,0.2707474,0,0,19.082096,0.05703,19.082096,0.05703,18.983761,1.0727501,0,100,,,1,,,,1.7788E-5,2.148077,184.45967,0,0
36227824.66,,5905,13.4391,13.4689,89999.219,9.3E-6,13.581251,0.27039462,0,0,19.094527,0.05836,19.094527,0.05836,13.41606,1.0740434,0,100,,,1,,,,1.7778E-5,2.1455,184.45037,0,0
36227844.52,,5905,13.4414,13.4693,89999.219,9.2E-6,13.582071,0.27069213,0,0,19.093741,0.05691,19.093741,0.05691,15.709652,1.0737935,0,100,,,1,,,,1.7782E-5,2.148087,184.47264,0,0
36227864.52,,5905,13.4407,13.4693,89999.219,9.3E-6,13.582085,0.27057217,0,0,19.102644,0.05628,19.102644,0.05628,23.554414,1.0736582,0,100,,,1,,,,1.7792E-5,2.147587,184.47304,0,0
36227884.53,,5905,13.4407,13.4699,89999.219,9.2E-6,13.582534,0.27046815,0,0,19.092359,0.05762,19.092359,0.05762,18.306154,1.0726814,0,100,,,1,,,,1.7799E-5,2.147316,184.48522,0,0
36227904.42,,5905,13.4405,13.4701,89999.219,9.2E-6,13.582917,0.27051262,0,0,19.097496,0.05785,19.097496,0.05785,19.724089,1.0739091,0,100,,,1,,,,1.7783E-5,2.145363,184.49562,0,0
36227924.38,,5905,13.4418,13.4705,89999.219,9.2E-6,13.583596,0.27053096,0,0,19.107516,0.05866,19.107516,0.05866,21.391323,1.0741163,0,100,,,1,,,,1.7789E-5,2.147818,184.51408,0,0
36227944.23,,5905,13.4431,13.4701,89999.219,9.4E-6,13.583772,0.2706126,0,0,19.092683,0.05843,19.092683,0.05843,22.978517,1.0727155,0,100,,,1,,,,1.7798E-5,2.148233,184.51887,0,0
36228120.5,,5905,13.6969,13.7246,89999.219,9.3E-6,13.836724,0.27098262,0,0,20.023847,0.06204,20.023847,0.06204,23.512096,1.1019297,0,100,,,1,,,,1.8172E-5,2.145431,191.45494,0,0
36228140.41,,5905,13.6973,13.7257,89999.219,9.3E-6,13.840276,0.27557723,0,0,20.026063,0.06131,20.026063,0.06131,23.05155,1.1007683,0,100,,,1,,,,1.8193E-5,2.203859,191.55323,0,0
36228160.25,,5905,13.6983,13.7276,89999.219,9.4E-6,13.840839,0.2753819,0,0,20.033131,0.06248,20.033131,0.06248,20.697444,1.1013005,0,100,,,1,,,,1.819E-5,2.201537,191.56883,0,0
36228180.14,,5905,13.6987,13.7279,89999.219,9.3E-6,13.841671,0.27538889,0,0,20.039929,0.06014,20.039929,0.06014,17.274082,1.1006916,0,100,,,1,,,,1.8207E-5,2.202601,191.59186,0,0
36228200.06,,5905,13.6993,13.728,89999.219,9.3E-6,13.842129,0.27524434,0,0,20.045821,0.06208,20.045821,0.06208,21.602815,1.1019463,0,100,,,1,,,,1.8191E-5,2.201383,191.60454,0,0
36228219.86,,5905,13.7,13.728,89999.219,9.2E-6,13.843062,0.27567898,0,0,20.042221,0.06226,20.042221,0.06226,23.832002,1.1022749,0,100,,,1,,,,1.8183E-5,2.203893,191.63036,0,0
36228239.64,,5905,13.7009,13.7293,89999.219,9.2E-6,13.843413,0.27563288,0,0,20.047538,0.06273,20.047538,0.06273,21.141181,1.102682,0,100,,,1,,,,1.8181E-5,2.20455,191.64009,0,0
36228260.5,,5905,13.7023,13.7306,89999.219,9.2E-6,13.844201,0.27559972,0,0,20.054269,0.06215,20.054269,0.06215,14.578687,1.1016649,0,100,,,1,,,,1.8204E-5,2.205364,191.6619,0,0
36228281.31,,5905,13.7017,13.729,89999.219,9.3E-6,13.843972,0.27540431,0,0,20.055535,0.06249,20.055535,0.06249,29.0947,1.1014938,0,100,,,1,,,,1.8208E-5,2.20333,191.65555,0,0
36228301.09,,5905,13.7014,13.7295,89999.219,9.3E-6,13.843995,0.27540048,0,0,20.045995,0.06169,20.045995,0.06169,23.48985,1.1001938,0,100,,,1,,,,1.822E-5,2.202988,191.65621,0,0
36228321.16,,5905,13.7013,13.7307,89999.219,9.3E-6,13.843737,0.27533675,0,0,20.045257,0.06316,20.045257,0.06316,22.340968,1.1026214,0,100,,,1,,,,1.818E-5,2.200388,191.64907,0,0
36228341.11,,5905,13.7018,13.7306,89999.219,9.2E-6,13.844698,0.27577097,0,0,20.051379,0.06248,20.051379,0.06248,18.513055,1.10284,0,100,,,1,,,,1.8182E-5,2.205243,191.67567,0,0
36228519.42,,5905,13.9537,13.9898,89999.219,9.3E-6,14.098851,0.27614852,0,0,20.989953,0.06725,20.989953,0.06725,27.957405,1.1297192,0,100,,,1,,,,1.858E-5,2.20568,198.77761,0,0
36228539.83,,5905,13.9559,13.9897,89999.219,9.2E-6,14.102147,0.28056348,0,0,21.002315,0.0691,21.002315,0.0691,17.596173,1.1303422,0,100,,,1,,,,1.858E-5,2.259438,198.87055,0,0
36228560.19,,5905,13.9562,13.9925,89999.219,9.2E-6,14.101946,0.28045327,0,0,21.001453,0.06504,21.001453,0.06504,16.365471,1.1289022,0,100,,,1,,,,1.8603E-5,2.260684,198.86487,0,0
36228580.5,,5905,13.9572,13.9924,89999.219,9.3E-6,14.102424,0.28028648,0,0,21.017597,0.06722,21.017597,0.06722,17.539373,1.130963,0,100,,,1,,,,1.8584E-5,2.257804,198.87836,0,0
36228601.06,,5905,13.9561,13.9939,89999.219,9.4E-6,14.103607,0.28060865,0,0,21.016655,0.06575,21.016655,0.06575,19.06456,1.1311012,0,100,,,1,,,,1.8581E-5,2.261926,198.91174,0,0
36228621.39,,5905,13.9569,13.9941,89999.219,9.3E-6,14.104606,0.28074188,0,0,21.021517,0.06774,21.021517,0.06774,19.679009,1.1315978,0,100,,,1,,,,1.8577E-5,2.262202,198.93992,0,0
36228641.75,,5905,13.9576,13.995,89999.219,9.2E-6,14.105325,0.28088501,0,0,21.014362,0.06889,21.014362,0.06889,21.278875,1.1317701,0,100,,,1,,,,1.8568E-5,2.263196,198.96018,0,0
36228662.14,,5905,13.9593,13.9947,89999.219,9.3E-6,14.105641,0.28101542,0,0,21.013104,0.06745,21.013104,0.06745,19.31425,1.1313182,0,100,,,1,,,,1.8574E-5,2.26354,198.96909,0,0
36228682.47,,5905,13.9585,13.996,89999.219,9.3E-6,14.106219,0.2806142,0,0,21.023194,0.06691,21.023194,0.06691,19.861187,1.1286826,0,100,,,1,,,,1.8626E-5,2.262636,198.98543,0,0
36228702.67,,5905,13.9593,13.9956,89999.219,9.3E-6,14.106285,0.28056373,0,0,21.00289,0.06789,21.00289,0.06789,16.357237,1.1302731,0,100,,,1,,,,1.8582E-5,2.257365,198.98728,0,0
36228722.97,,5905,13.9602,13.9971,89999.219,9.4E-6,14.106741,0.28079491,0,0,21.013335,0.06832,21.013335,0.06832,17.374542,1.1306411,0,100,,,1,,,,1.8585E-5,2.260546,199.00013,0,0
36228743.23,,5905,13.9604,13.9976,89999.219,9.3E-6,14.106437,0.28087988,0,0,21.011279,0.06718,21.011279,0.06718,20.8344,1.1314991,0,100,,,1,,,,1.8569E-5,2.261282,198.99158,0,0
36228920.19,,5905,14.2118,14.2529,89999.219,9.2E-6,14.357779,0.2810578,0,0,21.981522,0.07257,21.981522,0.07257,25.97082,1.1583877,0,100,,,1,,,,1.8976E-5,2.262998,206.14583,0,0
36228940.56,,5905,14.213,14.2525,89999.219,9.2E-6,14.361301,0.28542383,0,0,22.001982,0.07471,22.001982,0.07471,19.13549,1.1597003,0,100,,,1,,,,1.8972E-5,2.316775,206.24696,0,0
36228960.83,,5905,14.2151,14.2543,89999.219,9.3E-6,14.362356,0.28562152,0,0,22.007194,0.07308,22.007194,0.07308,22.503741,1.1592568,0,100,,,1,,,,1.8984E-5,2.319401,206.27727,0,0
36228981.3,,5905,14.2149,14.2545,89999.219,9.2E-6,14.362738,0.28568457,0,0,22.001162,0.0756,22.001162,0.0756,20.540806,1.1590914,0,100,,,1,,,,1.8981E-5,2.318514,206.28825,0,0
36229001.66,,5905,14.2158,14.2556,89999.219,9.2E-6,14.363306,0.28561202,0,0,22.009706,0.07381,22.009706,0.07381,19.03749,1.1594496,0,100,,,1,,,,1.8983E-5,2.318183,206.30457,0,0
36229022.16,,5905,14.2161,14.2559,89999.219,9.4E-6,14.364074,0.28545339,0,0,22.010772,0.07087,22.010772,0.07087,14.695006,1.1580463,0,100,,,1,,,,1.9007E-5,2.318899,206.32662,0,0
36229042.47,,5905,14.217,14.257,89999.219,9.3E-6,14.364439,0.28528697,0,0,22.014561,0.07386,22.014561,0.07386,18.37528,1.1584559,0,100,,,1,,,,1.9003E-5,2.316093,206.33712,0,0
36229062.91,,5905,14.2177,14.2568,89999.219,9.4E-6,14.365358,0.28542115,0,0,22.016829,0.07315,22.016829,0.07315,26.31849,1.1584933,0,100,,,1,,,,1.9005E-5,2.316912,206.3635,0,0
36229084.06,,5905,14.2176,14.2583,89999.219,9.2E-6,14.365679,0.28542025,0,0,22.022026,0.07229,22.022026,0.07229,19.598618,1.1591465,0,100,,,1,,,,1.8998E-5,2.316987,206.37275,0,0
36229104.39,,5905,14.218,14.2584,89999.219,9.2E-6,14.366353,0.28556303,0,0,22.021881,0.07449,22.021881,0.07449,16.241383,1.1590349,0,100,,,1,,,,1.9E-5,2.318293,206.39211,0,0
36229124.64,,5905,14.2188,14.2591,89999.219,9.3E-6,14.366993,0.28563533,0,0,22.017291,0.07413,22.017291,0.07413,14.54203,1.159252,0,100,,,1,,,,1.8993E-5,2.31807,206.41048,0,0
36229145.06,,5905,14.2189,14.2591,89999.219,9.3E-6,14.367091,0.28552819,0,0,22.02491,0.0727,22.02491,0.0727,27.554335,1.1591498,0,100,,,1,,,,1.9001E-5,2.318504,206.4133,0,0
36229322.66,,5905,14.4681,14.5174,89999.219,9.3E-6,14.618258,0.28563887,0,0,23.010819,0.07891,23.010819,0.07891,22.242217,1.1871761,0,100,,,1,,,,1.9383E-5,2.3183,213.69348,0,0
36229342.94,,5905,14.4703,14.5184,89999.219,9.2E-6,14.622066,0.29047274,0,0,23.029599,0.08123,23.029599,0.08123,25.389123,1.1888329,0,100,,,1,,,,1.9372E-5,2.374352,213.80481,0,0
36229363.34,,5905,14.4714,14.5195,89999.219,9.3E-6,14.623838,0.29058201,0,0,23.036228,0.08036,23.036228,0.08036,18.744854,1.187534,0,100,,,1,,,,1.9398E-5,2.377666,213.85665,0,0
36229383.61,,5905,14.4731,14.5202,89999.219,9.3E-6,14.624638,0.29041698,0,0,23.046699,0.08065,23.046699,0.08065,22.83474,1.1888359,0,100,,,1,,,,1.9386E-5,2.375068,213.88003,0,0
36229403.88,,5905,14.4752,14.5212,89999.219,9.3E-6,14.626039,0.29082452,0,0,23.046381,0.08165,23.046381,0.08165,21.855017,1.1898327,0,100,,,1,,,,1.9369E-5,2.377672,213.92103,0,0
36229424.34,,5905,14.475,14.5217,89999.219,9.4E-6,14.626703,0.29084901,0,0,23.043567,0.0799,23.043567,0.0799,21.645944,1.1881031,0,100,,,1,,,,1.9395E-5,2.379665,213.94045,0,0
36229444.72,,5905,14.4761,14.5223,89999.219,9.2E-6,14.626908,0.29051545,0,0,23.052855,0.07965,23.052855,0.07965,31.327091,1.1888286,0,100,,,1,,,,1.9391E-5,2.376206,213.94643,0,0
36229465.14,,5905,14.4756,14.5227,89999.219,9.3E-6,14.627881,0.29049378,0,0,23.060662,0.08049,23.060662,0.08049,21.865163,1.1883753,0,100,,,1,,,,1.9405E-5,2.377657,213.9749,0,0
36229485.52,,5905,14.4766,14.5236,89999.219,9.3E-6,14.627951,0.29044599,0,0,23.062216,0.07763,23.062216,0.07763,15.572457,1.1878385,0,100,,,1,,,,1.9415E-5,2.376751,213.97694,0,0
36229505.83,,5905,14.4774,14.5245,89999.219,9.3E-6,14.628886,0.29029925,0,0,23.073937,0.08048,23.073937,0.08048,31.40458,1.1894711,0,100,,,1,,,,1.9398E-5,2.375677,214.0043,0,0
36229526.25,,5905,14.4763,14.5245,89999.219,9.3E-6,14.629313,0.29070564,0,0,23.061889,0.08137,23.061889,0.08137,22.692539,1.1890277,0,100,,,1,,,,1.9396E-5,2.378942,214.01679,0,0
36229546.72,,5905,14.4786,14.525,89999.219,9.3E-6,14.630053,0.29057717,0,0,23.072518,0.07959,23.072518,0.07959,15.88172,1.1891057,0,100,,,1,,,,1.9403E-5,2.378055,214.03846,0,0
36229722.13,,5905,14.7296,14.777,89999.219,9.2E-6,14.881139,0.290708,0,0,24.083683,0.08619,24.083683,0.08619,31.233874,1.217274,0,100,,,1,,,,1.9785E-5,2.378211,221.4483,0,0
36229742.34,,5905,14.7307,14.777,89999.219,9.4E-6,14.884644,0.29533389,0,0,24.110613,0.08603,24.110613,0.08603,26.230523,1.2181544,0,100,,,1,,,,1.9793E-5,2.434548,221.55264,0,0
36229762.7,,5905,14.7319,14.7795,89999.219,9.2E-6,14.885951,0.29531045,0,0,24.121083,0.08507,24.121083,0.08507,27.942749,1.2176789,0,100,,,1,,,,1.9809E-5,2.436309,221.59154,0,0
36229783.13,,5905,14.7321,14.7798,89999.219,9.4E-6,14.887391,0.29533355,0,0,24.1158,0.08759,24.1158,0.08759,24.339228,1.2173677,0,100,,,1,,,,1.981E-5,2.435358,221.63442,0,0
36229803.38,,5905,14.7341,14.7811,89999.219,9.2E-6,14.887923,0.29516731,0,0,24.125941,0.08659,24.125941,0.08659,25.378559,1.2168595,0,100,,,1,,,,1.9826E-5,2.434735,221.65025,0,0
36229824.59,,5905,14.7354,14.7815,89999.219,9.2E-6,14.889284,0.29512323,0,0,24.128998,0.08586,24.128998,0.08586,25.247243,1.218232,0,100,,,1,,,,1.9807E-5,2.433719,221.69079,0,0
36229844.8,,5905,14.7343,14.7817,89999.219,9.4E-6,14.889892,0.29561053,0,0,24.118428,0.08453,24.118428,0.08453,21.969629,1.2172746,0,100,,,1,,,,1.9813E-5,2.436464,221.70888,0,0
36229865.25,,5905,14.736,14.7825,89999.219,9.3E-6,14.890218,0.29514905,0,0,24.136407,0.08561,24.136407,0.08561,20.695063,1.218115,0,100,,,1,,,,1.9815E-5,2.434549,221.71859,0,0
36229885.58,,5905,14.7355,14.7832,89999.219,9.3E-6,14.890717,0.29529945,0,0,24.133002,0.08803,24.133002,0.08803,21.780585,1.2174914,0,100,,,1,,,,1.9822E-5,2.43623,221.73345,0,0
36229906.03,,5905,14.7382,14.7835,89999.219,9.3E-6,14.891665,0.2952977,0,0,24.138316,0.08527,24.138316,0.08527,27.41774,1.2182709,0,100,,,1,,,,1.9814E-5,2.434983,221.7617,0,0
36229926.28,,5905,14.7375,14.7849,89999.219,9.3E-6,14.892093,0.29534127,0,0,24.14416,0.08708,24.14416,0.08708,23.267184,1.2178857,0,100,,,1,,,,1.9825E-5,2.436542,221.77443,0,0
36229946.55,,5905,14.7372,14.7853,89999.219,9.2E-6,14.892361,0.29538737,0,0,24.138151,0.08779,24.138151,0.08779,27.836074,1.2175421,0,100,,,1,,,,1.9825E-5,2.435771,221.78242,0,0
36230123.17,,5905,14.9881,15.0365,89999.219,9.3E-6,15.140982,0.29497466,0,0,25.193669,0.09421,25.193669,0.09421,18.793895,1.2465757,0,100,,,1,,,,2.021E-5,2.435084,229.24933,0,0
36230143.42,,5905,14.9899,15.0369,89999.219,9.3E-6,15.144617,0.29999627,0,0,25.211128,0.0955,25.211128,0.0955,23.387217,1.2478799,0,100,,,1,,,,2.0203E-5,2.493151,229.35944,0,0
36230163.94,,5905,14.9906,15.038,89999.219,9.4E-6,15.146115,0.30004738,0,0,25.228973,0.09183,25.228973,0.09183,23.55366,1.2475693,0,100,,,1,,,,2.0223E-5,2.49576,229.40479,0,0
36230184.25,,5905,14.9918,15.0383,89999.219,9.3E-6,15.147441,0.29988395,0,0,25.237866,0.09364,25.237866,0.09364,25.32281,1.2466405,0,100,,,1,,,,2.0245E-5,2.495139,229.44496,0,0
36230204.67,,5905,14.993,15.0393,89999.219,9.2E-6,15.148496,0.29980483,0,0,25.237489,0.0955,25.237489,0.0955,27.868942,1.2474597,0,100,,,1,,,,2.0231E-5,2.493281,229.47693,0,0
36230225,,5905,14.9932,15.039,89999.219,9.3E-6,15.149291,0.29974631,0,0,25.254613,0.09611,25.254613,0.09611,31.681962,1.2473965,0,100,,,1,,,,2.0246E-5,2.494919,229.50101,0,0
36230245.19,,5905,14.9942,15.04,89999.219,9.3E-6,15.150158,0.2998256,0,0,25.242085,0.09411,25.242085,0.09411,21.961779,1.246948,0,100,,,1,,,,2.0243E-5,2.494793,229.52729,0,0
36230265.39,,5905,14.9952,15.0409,89999.219,9.4E-6,15.150813,0.29995164,0,0,25.23061,0.09231,25.23061,0.09231,26.009465,1.2466324,0,100,,,1,,,,2.0239E-5,2.493896,229.54714,0,0
36230285.64,,5905,14.9961,15.0405,89999.219,9.3E-6,15.151146,0.29988828,0,0,25.243207,0.09453,25.243207,0.09453,20.793584,1.2473188,0,100,,,1,,,,2.0238E-5,2.493265,229.55722,0,0
36230306.16,,5905,14.9961,15.0417,89999.219,9.3E-6,15.151194,0.30002058,0,0,25.238801,0.09428,25.238801,0.09428,19.512837,1.2470419,0,100,,,1,,,,2.0239E-5,2.494638,229.55868,0,0
36230326.5,,5905,14.9967,15.0423,89999.219,9.3E-6,15.151793,0.29977589,0,0,25.260828,0.09305,25.260828,0.09305,29.870517,1.2470694,0,100,,,1,,,,2.0256E-5,2.494084,229.57682,0,0
36230346.84,,5905,14.9967,15.0426,89999.219,9.2E-6,15.152493,0.29999801,0,0,25.252332,0.09361,25.252332,0.09361,21.488684,1.2483772,0,100,,,1,,,,2.0228E-5,2.494139,229.59804,0,0