File: ppms-mpms/Heat capacity example file.dat
[Header]
TITLE,ML_WLH_20231013_1_AMF-Ag(pyz)2S2O8_T5_plus_remainder_of_(ML_WLH_20230922_AMF-Ag(pyz)S2O8_T4)-pressed_pellet_2p71mg_HC_2-300K.dat
BYAPP,HeatCapacity,3.9.11,1.7
INFO,2.71,MASS:Sample Mass (mg)
INFO,0.03,MASSERR:Sample Mass Error (mg)
INFO,,MOLWGHT:Formula Weight (g/mole)
INFO,,ATOMS:Atoms per Formula Unit
INFO,PPMS Heat Capacity Option 3.9.11 Build 2,APPNAME
DATATYPE,TIME,1
DATATYPE,COMMENT,2
STARTUPAXIS, X, 8, LINEAR, AUTO
STARTUPAXIS, Y1, 10, LINEAR, AUTO
[Data]
Time Stamp (Seconds),Comment (),System Status (Code),Puck Temp (Kelvin),System Temp (Kelvin),Field (Oersted),Pressure (Torr),Sample Temp (Kelvin),Temp Rise (Kelvin),Samp HC (µJ/K),Samp HC Err (µJ/K),Addenda HC (µJ/K),Addenda HC Err (µJ/K),Total HC (µJ/K),Total HC Err (µJ/K),Fit Deviation (ChiSquare),Time Const tau1 (seconds),Time Const tau2 (seconds),Sample Coupling (Percent),Debye Temp (Kelvin),Debye Temp Err (Kelvin),Cal Correction (Factor),Therm Resist (Ohms),Htr Resist (Ohms),Puck Resist (Ohms),Wire Cond (W/K),Meas Time (seconds),Temp Squared (K^2),Samp HC/Temp (µJ/K/K),Addenda Offset HC (µJ/K)
3250083.2,Error: Temperature of platform does not match the system temperature : System = 2 K;  Platform = 2.3654 K
3250632.59,CALFILE: C:\QdPpms\HEATCA~1\TempCal\Standard\Puck1983.cal|Addenda #46 measured on 2/1/2024 from 3.1287 to 149.82 K
3250632.98,,5905,,2.0011,-0.267,9.4E-6,2.3155856,0.025337637,0.31463227,0.001814,0.3065078,0.0007381,0.62114006,0.001814,1.3066288,0.32504426,0.021376051,76.328844,,,1,,,,2.074688E-6,1.0461367,5.3619366,0.1358759,0
3250684.34,,5905,,2.0002,-0.267,9.3E-6,2.3097678,0.024358347,0.3074965,0.00171,0.3048306,0.0007316,0.6123271,0.00171,2.5075382,0.31230621,0.019982533,76.976409,,,1,,,,2.1195394E-6,0.97170559,5.3350272,0.13312875,0
3250885.83,,5905,,2.3453,-0.267,9.3E-6,2.5721921,0.026966078,0.4164592,0.002003,0.39618755,0.001041,0.81264675,0.002003,0.89126586,0.35333146,0.020841013,78.510206,,,1,,,,2.4765046E-6,1.1552794,6.616172,0.16190828,0
3251075.45,,5905,,2.691,-0.267,9.3E-6,2.8748351,0.027022684,0.5614365,0.003269,0.54033517,0.00143,1.1017717,0.003269,2.3451068,0.42696307,0.025266082,78.482485,,,1,,,,2.7766908E-6,1.0633525,8.2646766,0.19529347,0
3251141.5,,5905,,2.6882,-0.267,9.4E-6,2.8719542,0.030554487,0.5573636,0.00308,0.53847515,0.001425,1.0958387,0.00308,1.2093682,0.42859965,0.025331093,78.519264,,,1,,,,2.7500192E-6,1.3601519,8.2481208,0.1940712,0
3251320.59,,5905,,3.0324,-0.267,9.4E-6,3.1682002,0.032728269,0.75093595,0.003531,0.71905333,0.001838,1.4699893,0.003531,1.3039569,0.51072452,0.031955003,77.329291,,,1,,,,3.1144384E-6,1.5331028,10.037492,0.23702289,0
3251503.58,,5905,,3.38,-0.267,9.4E-6,3.4790457,0.033007981,0.95721376,0.004224,0.95162183,0.002309,1.9088356,0.004224,4.1878457,0.58213845,0.035812072,77.799966,,,1,,,,3.5309854E-6,1.5177681,12.103759,0.27513688,0
3251575.33,,5905,,3.3813,-0.267,9.3E-6,3.4773031,0.036727969,0.98662077,0.00374,0.94987773,0.002306,1.9364985,0.00374,1.8179845,0.60441976,0.037565095,77.487608,,,1,,,,3.4629172E-6,1.8942112,12.091637,0.2837316,0
3251757.2,,5905,,3.7258,-0.267,9.4E-6,3.7913673,0.038245079,1.31694,0.004964,1.2298797,0.002824,2.5468197,0.004964,1.8017987,0.72380513,0.045712315,77.038748,,,1,,,,3.819707E-6,2.0225405,14.374466,0.34735226,0
3251939.19,,5905,,4.0708,-0.267,9.4E-6,4.0926889,0.040360534,1.6445909,0.006589,1.5414858,0.003363,3.1860766,0.006589,1.6184909,0.80488536,0.050069926,77.372115,,,1,,,,4.2891669E-6,2.2625158,16.750102,0.40183628,0
3251996.28,,5905,,4.0718,-0.267,9.4E-6,4.0906109,0.042048758,1.6523451,0.006766,1.5394182,0.00336,3.1917634,0.006766,1.535871,0.80911683,0.050147493,77.426477,,,1,,,,4.27517E-6,2.4719382,16.733097,0.40393603,0
3252183.3,,5905,,4.4132,-0.267,9.4E-6,4.4216639,0.045392383,2.054887,0.008765,1.9282813,0.003999,3.9831684,0.008765,1.597527,0.92271185,0.057303829,77.411423,,,1,,,,4.6762337E-6,2.7151812,19.551111,0.46473162,0
3252369.38,,5905,,4.7593,-0.267,9.4E-6,4.7471593,0.045455017,2.6186124,0.01202,2.3631942,0.004686,4.9818066,0.01202,1.7299956,1.0342733,0.063157307,77.609631,,,1,,,,5.2279169E-6,2.7228569,22.535521,0.55161672,0
3252429.91,,5905,,4.7585,-0.267,9.4E-6,4.7467759,0.04865327,2.6536943,0.01054,2.3635724,0.004686,5.0172667,0.01054,3.2316278,1.0878568,0.071111471,76.079552,,,1,,,,5.0489943E-6,3.1523298,22.531881,0.55905195,0
3252616.09,,5905,,5.1045,-0.267,9.4E-6,5.0747756,0.050982461,3.2957173,0.01416,2.8534937,0.005437,6.149211,0.01416,1.7392483,1.2081891,0.07727701,76.42175,,,1,,,,5.5746567E-6,3.4856213,25.753348,0.64943114,0
3252804.36,,5905,,5.4485,-0.267,9.4E-6,5.414343,0.049831073,4.0813491,0.01812,3.4146272,0.006277,7.4959763,0.01812,2.3660692,1.3082809,0.085604769,75.720793,,,1,,,,6.3166048E-6,3.4522138,29.315111,0.7538032,0
3252867.98,,5905,,5.4474,-0.267,9.4E-6,5.4112734,0.054465678,3.983134,0.0152,3.4067299,0.006265,7.3898639,0.0152,2.3557592,1.3293644,0.087489779,75.714264,,,1,,,,6.1174075E-6,3.8688954,29.281879,0.73608073,0
3253056.61,,5905,,5.7925,-0.267,9.3E-6,5.7523944,0.057007885,4.935686,0.02025,4.0266704,0.007178,8.9623564,0.02025,2.6503505,1.4463311,0.092869584,76.00161,,,1,,,,6.8352727E-6,4.3987072,33.090041,0.85802287,0
3253250.5,,5905,,6.1475,-0.267,9.3E-6,6.1052017,0.058662817,4.658314,0.04194,4.7247643,0.008195,9.3830782,0.04194,15.166688,1.2933987,0.088529535,75.590981,,,1,,,,7.8783329E-6,4.3073112,37.273488,0.76300739,0
3253336.38,,5905,,6.1382,-0.267,9.4E-6,6.0878427,0.060805254,5.8986205,0.02282,4.6893314,0.008143,10.587952,0.02282,5.7280674,1.6195742,0.1040579,75.82465,,,1,,,,7.2339234E-6,4.7499595,37.061829,0.96891803,0
3253529.41,,5905,,6.4843,-0.267,9.3E-6,6.4204716,0.064828161,7.0990564,0.02855,5.4049679,0.009179,12.504024,0.02855,1.4555519,1.8033733,0.11687527,75.322709,,,1,,,,7.7228665E-6,5.4081223,41.222455,1.1056908,0
3253724.48,,5905,,6.8281,-0.267,9.4E-6,6.7595452,0.064848783,8.4040963,0.03537,6.1900351,0.01031,14.594131,0.03537,4.4673313,1.9404972,0.12292997,75.614714,,,1,,,,8.3862429E-6,5.380336,45.691452,1.2432932,0
3253801.34,,5905,,6.8285,-0.267,9.3E-6,6.7600277,0.068539114,8.3094266,0.03155,6.1882753,0.01031,14.497702,0.03155,3.3465898,1.9528232,0.12591788,75.278487,,,1,,,,8.2869983E-6,5.8925064,45.697975,1.2292001,0
3253999.38,,5905,,7.1724,-0.267,9.3E-6,7.0993262,0.070926751,9.9260206,0.03911,7.0327597,0.01152,16.95878,0.03911,4.2054693,2.1489739,0.13930925,74.741323,,,1,,,,8.877074E-6,6.3616656,50.400433,1.3981638,0
3254197.19,,5905,,7.5178,-0.267,9.4E-6,7.4337896,0.071527846,11.392039,0.04987,7.9207437,0.01279,19.312783,0.04987,2.7281025,2.2788621,0.14603166,74.86204,,,1,,,,9.5419111E-6,6.3886086,55.261228,1.5324672,0
3254273.13,,5905,,7.517,-0.267,9.3E-6,7.4355755,0.07490819,11.33563,0.04478,7.922451,0.01279,19.258081,0.04478,1.2786588,2.2968259,0.1456078,75.171422,,,1,,,,9.4177205E-6,6.8431525,55.287783,1.5245128,0
3254481.16,,5905,,7.8592,-0.267,9.3E-6,7.7709226,0.078439778,13.400429,0.05431,8.8718836,0.01414,22.272313,0.05431,2.2382541,2.5520969,0.16363526,74.389251,,,1,,,,9.900025E-6,7.5523196,60.387238,1.7244322,0
3254682.73,,5905,,8.2064,-0.267,9.4E-6,8.1105834,0.078887763,15.095723,0.0642,9.8892551,0.01557,24.984978,0.0642,4.1762954,2.6987601,0.172699,74.334363,,,1,,,,1.0516298E-5,7.4721839,65.781563,1.8612376,0
3254769.59,,5905,,8.2067,-0.267,9.3E-6,8.1115134,0.082661471,15.168895,0.05705,9.8888854,0.01557,25.057781,0.05705,3.3211733,2.7224759,0.17294994,74.47201,,,1,,,,1.0450094E-5,8.1349176,65.79665,1.870045,0
3254977.28,,5905,,8.5526,-0.267,9.3E-6,8.4570597,0.085467164,17.153745,0.07153,10.984736,0.01709,28.138481,0.07153,4.7009228,2.8942328,0.18450405,74.198997,,,1,,,,1.1077044E-5,8.6059914,71.521858,2.0283344,0
3255184.33,,5905,,8.8981,-0.267,9.4E-6,8.7981028,0.085824258,19.184528,0.0851,12.124722,0.01867,31.309251,0.0851,6.629436,3.0437701,0.19372711,74.101108,,,1,,,,1.1741906E-5,8.5507397,77.406613,2.1805301,0
3255280.05,,5905,,8.8988,-0.267,9.3E-6,8.7988746,0.08975622,19.170226,0.07869,12.124103,0.01867,31.294329,0.07869,2.9565153,3.0693165,0.19651403,73.953445,,,1,,,,1.1649754E-5,9.2352609,77.420194,2.1787134,0
3255495.08,,5905,,9.2423,-0.267,9.3E-6,9.1389387,0.092934889,21.373507,0.08325,13.320695,0.0203,34.694202,0.08325,7.050935,3.2339228,0.20648855,73.864478,,,1,,,,1.2282486E-5,9.7891947,83.5202,2.3387297,0
3255715.78,,5905,,9.5856,-0.267,9.4E-6,9.4758146,0.092898629,24.017261,0.09503,14.563747,0.02198,38.581008,0.09503,16.424524,3.4369333,0.21797812,73.732327,,,1,,,,1.2896983E-5,9.7364642,89.791063,2.5345853,0
3255799.72,,5905,,9.5879,-0.267,9.3E-6,9.4774448,0.095948339,23.866462,0.09512,14.565508,0.02198,38.431969,0.09512,4.9807165,3.4243391,0.21701669,73.826384,,,1,,,,1.2877986E-5,10.237197,89.82196,2.518238,0
3256026.7,,5905,,9.9319,-0.267,9.2E-6,9.8207507,0.09968608,26.543202,0.1062,15.893007,0.02375,42.436209,0.1062,17.916935,3.6120237,0.22969691,73.510882,,,1,,,,1.3535826E-5,11.003469,96.447145,2.7027671,0
3256401.38,,5905,,10.2745,-0.267,9.4E-6,10.179688,0.098450169,30.596952,0.1209,17.346711,0.02566,47.943662,0.1209,8.2244914,3.9852638,0.25641777,72.485407,,,1,,,,1.4041106E-5,10.893982,103.62604,3.0056867,0
3256506.72,,5905,,10.2761,-0.267,9.3E-6,10.187011,0.10601467,30.074565,0.1008,17.367825,0.02569,47.44239,0.1008,3.8748714,3.9416084,0.24707173,73.459866,,,1,,,,1.3920365E-5,12.130138,103.77519,2.9522463,0
3256738.27,,5905,,10.6227,-0.267,9.4E-6,10.540778,0.10849906,32.643409,0.1218,18.863691,0.02763,51.5071,0.1218,20.143274,4.0965959,0.25906373,73.224932,,,1,,,,1.4565722E-5,12.377587,111.10799,3.0968692,0
3256972.78,,5905,,10.9665,-0.267,9.3E-6,10.884443,0.10873145,35.687612,0.135,20.378272,0.02957,56.065884,0.135,17.514292,4.2916251,0.27148002,73.062546,,,1,,,,1.5170275E-5,12.237453,118.4711,3.2787724,0
3257080.81,,5905,,10.9656,-0.267,9.3E-6,10.88752,0.11167545,35.571713,0.1384,20.392921,0.02958,55.964634,0.1384,14.255242,4.2715913,0.26967126,73.170058,,,1,,,,1.5195784E-5,12.879213,118.53809,3.2672008,0
3257317.28,,5905,,11.31,-0.267,9.4E-6,11.228091,0.11537806,38.818608,0.1469,21.949782,0.03155,60.76839,0.1469,19.809242,4.4683833,0.28159718,73.039336,,,1,,,,1.5810027E-5,13.535386,126.07004,3.4572758,0
3257554.8,,5905,,11.6547,-0.267,9.3E-6,11.56522,0.11573172,42.139298,0.1603,23.55355,0.03358,65.692849,0.1603,21.186107,4.667521,0.29478373,72.823225,,,1,,,,1.6407445E-5,13.473917,133.75432,3.6436226,0
3257669.48,,5905,,11.6545,-0.267,9.4E-6,11.567449,0.1180923,42.407657,0.1601,23.565993,0.03359,65.97365,0.1601,11.755799,4.7062846,0.29523566,72.935294,,,1,,,,1.6337075E-5,13.97218,133.80587,3.6661201,0
3257912.16,,5905,,11.9999,-0.267,9.4E-6,11.907206,0.12195494,45.497696,0.1704,25.235465,0.03572,70.733162,0.1704,11.410074,4.8595424,0.30582036,72.819279,,,1,,,,1.6981529E-5,14.601171,141.78156,3.8210219,0
3258554.33,,5905,,20.0079,-0.267,9.4E-6,19.876532,0.2080647,151.99827,0.5051,80.107325,0.1435,232.1056,0.5051,14.863752,9.6184276,0.62048306,71.331208,,,1,,,,2.8635406E-5,28.871345,395.07652,7.6471225,0
3258755.97,,5905,,20.0001,-0.267,9.3E-6,19.883646,0.20473398,150.16126,0.5429,80.169755,0.1436,230.33102,0.5429,14.763706,9.4332445,0.61009851,71.456136,,,1,,,,2.8906155E-5,27.884607,395.35938,7.5519983,0
3259131.84,,5905,,21.0193,-0.267,9.4E-6,20.908659,0.21904245,166.44568,0.589,89.144348,0.1661,255.59003,0.589,13.400415,10.062234,0.65514192,71.300652,,,1,,,,3.0099379E-5,30.534914,437.17204,7.9606101,0
3259508.27,,5905,,22.0409,-0.267,9.4E-6,21.922535,0.22041488,184.39907,0.6818,98.406769,0.1878,282.80584,0.6818,2.0428174,10.773597,0.69867895,71.366433,,,1,,,,3.1100215E-5,29.714177,480.59752,8.4113936,0
3259725.42,,5905,,22.041,-0.267,9.3E-6,21.931742,0.22848885,182.27289,0.6187,98.47313,0.188,280.74601,0.6187,19.347162,10.58698,0.69159841,71.334197,,,1,,,,3.1386294E-5,31.636167,481.00132,8.3109168,0
3260117.06,,5905,,23.0619,-0.267,9.2E-6,22.952577,0.24312179,197.88412,0.6733,108.11823,0.2074,306.00235,0.6733,6.5015883,11.128733,0.73313564,71.250101,,,1,,,,3.2528597E-5,34.166025,526.82081,8.6214333,0
3260539.52,,5905,,24.0823,-0.267,9.4E-6,23.963368,0.24441168,215.20777,0.7564,118.03305,0.2227,333.24081,0.7564,3.1480563,11.783116,0.77901282,71.19962,,,1,,,,3.345713E-5,33.194759,574.243,8.9806979,0
3260772.84,,5905,,24.0822,-0.267,9.2E-6,23.971844,0.2509535,213.37336,0.7497,118.10696,0.2228,331.48032,0.7497,11.215904,11.599696,0.77065833,71.189594,,,1,,,,3.3776919E-5,34.84564,574.64931,8.900999,0
3261192.64,,5905,,25.1022,-0.267,9.4E-6,24.995334,0.26537626,229.66283,0.7406,128.43937,0.2339,358.10219,0.7406,21.738559,12.140514,0.81198982,71.141223,,,1,,,,3.484006E-5,37.298967,624.76674,9.1882278,0
3261629.42,,5905,,26.1221,-0.267,9.3E-6,26.006782,0.26634629,248.42127,0.8222,139.00303,0.2429,387.4243,0.8222,3.2454018,12.858095,0.86031168,71.137464,,,1,,,,3.558839E-5,36.32041,676.35269,9.5521727,0
3261872.78,,5905,,26.1219,-0.267,9.4E-6,26.015715,0.27242383,245.59792,0.803,139.08426,0.2429,384.68218,0.803,13.371314,12.615811,0.85084057,71.074293,,,1,,,,3.5987806E-5,37.727645,676.81741,9.4403681,0
3262322.73,,5905,,27.1436,-0.267,9.4E-6,27.037902,0.28503197,259.03544,0.8635,150.03896,0.2527,409.07439,0.8635,5.1211503,12.865609,0.87661546,71.093922,,,1,,,,3.7431757E-5,39.982491,731.04814,9.5804562,0
3262789.72,,5905,,28.1629,-0.267,9.4E-6,28.045859,0.28647901,281.08673,0.9616,161.19779,0.2656,442.28452,0.9616,2.1909706,13.89513,0.94636407,70.960893,,,1,,,,3.755099E-5,38.953186,786.5702,10.022397,0
3263047.53,,5905,,28.1612,-0.267,9.4E-6,28.056072,0.29387004,276.8525,0.8975,161.28359,0.2657,438.13609,0.8975,14.433873,13.563467,0.93154938,70.935132,,,1,,,,3.8052616E-5,40.587681,787.14317,9.8678282,0
3263529.69,,5905,,29.1841,-0.267,9.4E-6,29.073011,0.30795775,292.6158,0.9232,172.80303,0.2839,465.41883,0.9232,23.94533,14.037531,0.9704874,70.930556,,,1,,,,3.9001915E-5,43.018612,845.23999,10.06486,0
3263997.56,,5905,,30.2043,-0.267,9.4E-6,30.065749,0.30921497,313.31361,1.046,184.37058,0.3062,497.68419,1.046,1.6588852,14.902447,1.0303198,70.87852,,,1,,,,3.9316064E-5,42.063308,903.94928,10.420948,0
3264274.86,,5905,,30.2036,-0.267,9.3E-6,30.078792,0.31562147,306.92906,0.9818,184.48732,0.3064,491.41638,0.9818,19.109573,14.410357,1.0077624,70.832468,,,1,,,,4.0070011E-5,43.520874,904.73371,10.204169,0
3264755.59,,5905,,31.2249,-0.267,9.4E-6,31.110275,0.33074451,323.8787,0.997,196.75935,0.333,520.63805,0.997,18.367131,14.937399,1.0470391,70.91099,,,1,,,,4.088346E-5,46.133875,967.84922,10.410666,0
3265260.75,,5905,,32.2451,-0.267,9.3E-6,32.122581,0.32986189,343.13838,1.106,209.10715,0.3616,552.24553,1.106,4.0553383,15.634764,1.1017485,70.793408,,,1,,,,4.1454934E-5,44.814517,1031.8602,10.682154,0
3265544,,5905,,32.2459,-0.267,9.4E-6,32.134641,0.33620032,339.06287,1.064,209.23682,0.3619,548.29969,1.064,11.570961,15.315538,1.0841116,70.830312,,,1,,,,4.1948106E-5,46.100371,1032.6352,10.55132,0
3266059.59,,5905,,33.2651,-0.267,9.4E-6,33.145767,0.35082132,355.1126,1.081,221.80618,0.3915,576.91878,1.081,6.4994588,15.821372,1.1312602,70.68987,,,1,,,,4.2716614E-5,48.630888,1098.6419,10.713664,0
3266576.7,,5905,,34.2855,-0.267,9.3E-6,34.156676,0.35063,375.58326,1.222,234.65896,0.4212,610.24222,1.222,1.4923179,16.65225,1.1924431,70.648641,,,1,,,,4.2941635E-5,47.290019,1166.6785,10.995896,0
3266872.16,,5905,,34.2899,-0.267,9.3E-6,34.171266,0.3574654,369.44729,1.162,234.81968,0.4216,604.26698,1.162,9.5314165,16.174047,1.1640206,70.726743,,,1,,,,4.3671439E-5,48.73406,1167.6754,10.811636,0
3267403.5,,5905,,35.3034,-0.267,9.4E-6,35.186856,0.37439265,385.87953,1.179,247.92441,0.45,633.80394,1.179,9.6451803,16.732024,1.2143087,70.616374,,,1,,,,4.4263597E-5,51.699021,1238.1148,10.966582,0
3267956.64,,5905,,36.3255,-0.267,9.4E-6,36.194698,0.3725375,406.7164,1.304,261.19506,0.4758,667.91147,1.304,1.743624,17.582303,1.2784834,70.552266,,,1,,,,4.4413332E-5,49.835341,1310.0562,11.236906,0
3268265.22,,5905,,36.3255,-0.267,9.4E-6,36.20934,0.37901712,400.45631,1.228,261.36215,0.4761,661.81846,1.228,7.5205919,17.108692,1.2524207,70.56011,,,1,,,,4.5144398E-5,51.229753,1311.1163,11.059476,0
3268832.08,,5905,,37.3482,-0.267,9.3E-6,37.234164,0.39651874,415.03066,1.236,275.01811,0.4984,690.04877,1.236,19.270619,17.555588,1.2919335,70.594899,,,1,,,,4.5784412E-5,54.228175,1386.383,11.146501,0
3269399.97,,5905,,38.3672,-0.267,9.4E-6,38.230089,0.39326526,438.32453,1.408,288.59097,0.5168,726.9155,1.408,1.2060621,18.549469,1.3655937,70.50209,,,1,,,,4.5709596E-5,52.132642,1461.5397,11.465433,0
3269723,,5905,,38.3674,-0.267,9.4E-6,38.250695,0.40146928,430.10517,1.31,288.8441,0.5171,718.94927,1.31,12.272925,17.996928,1.3373317,70.47157,,,1,,,,4.6506486E-5,53.83402,1463.1157,11.244375,0
3270323.84,,5905,,39.3908,-0.267,9.4E-6,39.276145,0.41672936,441.04218,1.298,303.03644,0.5341,744.07861,1.298,12.798547,18.216247,1.3657435,70.484877,,,1,,,,4.7429417E-5,56.311843,1542.6156,11.229263,0
3270925.84,,5905,,40.4079,-0.267,9.3E-6,40.276125,0.41541554,463.9334,1.439,317.3245,0.5508,781.2579,1.439,1.3926443,19.203491,1.4416301,70.391531,,,1,,,,4.7294471E-5,54.820552,1622.1663,11.518819,0
3271261.72,,5905,,40.4083,-0.267,9.3E-6,40.29615,0.42275894,457.10395,1.347,317.56819,0.5511,774.67214,1.347,5.7265546,18.734529,1.415205,70.393399,,,1,,,,4.7986959E-5,56.102895,1623.7797,11.343613,0
3271879.19,,5905,,41.4269,-0.267,9.4E-6,41.320786,0.43862466,471.86819,1.349,332.57747,0.5698,804.44566,1.349,6.9285308,19.173053,1.4609822,70.304302,,,1,,,,4.8645703E-5,58.944009,1707.4074,11.419632,0
3272500.75,,5905,,42.4495,-0.267,9.2E-6,42.317305,0.43739894,492.06592,1.492,347.67245,0.5905,839.73837,1.492,1.218847,20.029909,1.5310801,70.239681,,,1,,,,4.8616743E-5,57.426705,1790.7543,11.628007,0
3272845.77,,5905,,42.4493,-0.267,9.2E-6,42.344408,0.44499084,484.41156,1.378,348.05353,0.5911,832.46509,1.378,10.99397,19.489799,1.497271,70.284277,,,1,,,,4.9424292E-5,58.923474,1793.0489,11.4398,0
3273481.69,,5905,,43.4717,-0.267,9.4E-6,43.36535,0.46053374,503.60722,1.378,363.91206,0.6137,867.51927,1.378,18.649351,20.182891,1.5569923,70.225378,,,1,,,,4.9726209E-5,61.468269,1880.5536,11.613125,0
3274119.73,,5905,,44.4909,-0.267,9.4E-6,44.356988,0.4563449,520.42574,1.582,379.77088,0.6361,900.19662,1.582,1.0429733,20.846592,1.6236108,70.05275,,,1,,,,4.9962895E-5,59.483643,1967.5424,11.732666,0
3274476.97,,5905,,44.4909,-0.267,9.3E-6,44.391016,0.46743835,510.56085,1.419,380.26436,0.6367,890.82522,1.419,7.8071164,20.199036,1.5813175,70.125377,,,1,,,,5.0886823E-5,61.908983,1970.5623,11.501446,0
3275126.64,,5905,,45.508,-0.267,9.4E-6,45.409679,0.48052035,527.21994,1.419,396.88789,0.6587,924.10783,1.419,11.778636,20.731789,1.6337165,70.046663,,,1,,,,5.1398681E-5,63.979882,2062.0389,11.610299,0
3275775.28,,5905,,46.5314,-0.267,9.4E-6,46.400528,0.47691219,549.13917,1.643,413.47667,0.6784,962.61584,1.643,1.1335281,21.704907,1.7207205,69.871031,,,1,,,,5.120073E-5,62.092621,2153.009,11.834761,0
3276144.09,,5905,,46.5313,-0.267,9.3E-6,46.432082,0.4855532,536.92844,1.476,413.93761,0.6789,950.86605,1.476,5.4055953,20.919923,1.6663888,69.979782,,,1,,,,5.2297155E-5,63.642789,2155.9382,11.563738,0
3276830.72,,5905,,47.5507,-0.267,9.3E-6,47.455332,0.5003768,549.96107,1.487,431.34692,0.6971,981.30799,1.487,8.8503239,21.342089,1.7132899,69.926758,,,1,,,,5.2821882E-5,65.991014,2252.0085,11.589026,0
3277517.45,,5905,,48.571,-0.267,9.3E-6,48.446885,0.49423794,574.06337,1.694,448.63798,0.7131,1022.7013,1.694,0.9455651,22.360706,1.8039574,69.745155,,,1,,,,5.262747E-5,63.753531,2347.1006,11.849335,0
3277895.25,,5905,,48.5708,-0.267,9.4E-6,48.468495,0.50274494,563.70893,1.588,448.96972,0.7134,1012.6786,1.588,3.6740408,21.684387,1.7563409,69.818434,,,1,,,,5.3597415E-5,65.206731,2349.195,11.63042,0
3278598.63,,5905,,49.5929,-0.267,9.2E-6,49.495948,0.52000436,576.44535,1.504,467.14395,0.7282,1043.5893,1.504,5.0586095,22.100495,1.8079524,69.695391,,,1,,,,5.4133018E-5,68.305517,2449.8488,11.646314,0
3279303.53,,5905,,50.6124,-0.267,9.4E-6,50.495225,0.51481934,600.08734,1.736,485.26986,0.7413,1085.3572,1.736,0.80679679,23.151807,1.8995337,69.588645,,,1,,,,5.3793728E-5,66.207816,2549.7677,11.884041,0
3279689.91,,5905,,50.6118,-0.267,9.4E-6,50.518893,0.52222254,587.72053,1.587,485.64566,0.7415,1073.3662,1.587,3.1465415,22.396338,1.8501352,69.593752,,,1,,,,5.4859423E-5,67.289008,2552.1586,11.633678,0
3280409.27,,5905,,51.6303,-0.267,9.3E-6,51.542106,0.54096357,600.7904,1.56,504.48672,0.754,1105.2771,1.56,7.4905843,22.840424,1.9008387,69.525189,,,1,,,,5.5317311E-5,70.644479,2656.5887,11.656303,0
3281151.06,,5905,,52.654,-0.267,9.4E-6,52.545248,0.5337983,625.04204,1.777,523.46712,0.7665,1148.5092,1.777,0.65982807,23.867005,1.9947357,69.376804,,,1,,,,5.50777E-5,68.3647,2761.0031,11.895311,0
3281550.48,,5905,,52.6532,-0.267,9.3E-6,52.568982,0.54181718,609.52078,1.602,523.85014,0.7667,1133.3709,1.602,2.6155041,22.949257,1.9274618,69.464748,,,1,,,,5.6329917E-5,69.499639,2763.4979,11.594685,0
3282279.2,,5905,,53.6732,-0.267,9.3E-6,53.582713,0.56037356,624.9078,1.555,543.38706,0.7803,1168.2949,1.555,5.0646234,23.514666,1.9831003,69.445469,,,1,,,,5.6602646E-5,72.771802,2871.1071,11.662489,0
3283009.92,,5905,,54.6937,-0.267,9.2E-6,54.584873,0.55183217,650.1881,1.861,563.28272,0.7956,1213.4708,1.861,0.57890937,24.669669,2.0959045,69.199265,,,1,,,,5.61494E-5,70.013261,2979.5083,11.911507,0
3283419.08,,5905,,54.6982,-0.267,9.4E-6,54.612693,0.56192391,633.85935,1.615,563.76462,0.796,1197.624,1.615,2.9068452,23.679917,2.0189061,69.31798,,,1,,,,5.751965E-5,71.779531,2982.5462,11.606447,0
3284168.31,,5905,,55.7131,-0.267,9.4E-6,55.627921,0.58071166,646.97893,1.554,584.28015,0.8136,1231.2591,1.554,6.2461673,24.164234,2.0741377,69.245581,,,1,,,,5.7877272E-5,75.084823,3094.4656,11.630471,0
3284937.83,,5905,,56.737,-0.267,9.4E-6,56.629965,0.57036639,672.05847,1.814,605.15056,0.8326,1277.209,1.814,0.67073657,25.285971,2.188476,68.98195,,,1,,,,5.748626E-5,72.041011,3206.9529,11.867542,0
3285354.42,,5905,,56.736,-0.267,9.4E-6,56.656703,0.58000402,656.4758,1.637,605.63095,0.833,1262.1068,1.637,2.1043151,24.314615,2.1027249,69.194698,,,1,,,,5.8838933E-5,73.575182,3209.982,11.586904,0
3286141.8,,5905,,57.7556,-0.267,9.2E-6,57.678768,0.59977703,670.13439,1.561,627.22347,0.8532,1297.3579,1.561,4.2774807,24.858835,2.1715182,69.013215,,,1,,,,5.9127853E-5,77.126219,3326.8402,11.618389,0
3286927.17,,5905,,58.7755,-0.267,9.3E-6,58.666544,0.58960154,695.24203,1.842,648.67104,0.8732,1343.9131,1.842,0.65862866,26.041734,2.2950271,68.734006,,,1,,,,5.8587058E-5,74.098146,3441.7633,11.850741,0
3287354.47,,5905,,58.7757,-0.267,9.4E-6,58.693262,0.59937081,677.14233,1.701,649.16222,0.8736,1326.3045,1.701,1.6253291,24.982228,2.1950381,69.017879,,,1,,,,5.9986669E-5,75.439603,3444.899,11.536969,0
3288152.94,,5905,,59.7974,-0.267,9.4E-6,59.721535,0.61920256,692.33282,1.638,671.74603,0.8943,1364.0789,1.638,4.2583392,25.498061,2.2537258,68.930239,,,1,,,,6.0397639E-5,79.186047,3566.6618,11.592683,0
3288952.66,,5905,,60.815,-0.267,9.4E-6,60.714037,0.60769958,719.18404,1.992,694.1776,0.9147,1413.3616,1.992,0.61869256,26.776042,2.3907619,68.603207,,,1,,,,5.974264E-5,76.015632,3686.1943,11.845433,0
3289389.52,,5905,,60.8162,-0.267,9.4E-6,60.742376,0.61953883,701.24555,1.725,694.70606,0.9151,1395.9516,1.725,1.3020271,25.763717,2.305251,68.71837,,,1,,,,6.1105527E-5,77.796149,3689.6362,11.544585,0
3290207.23,,5905,,61.8363,-0.267,9.3E-6,61.760575,0.64027197,713.07453,1.623,717.95236,0.9363,1431.0269,1.623,3.8741211,26.166509,2.3500359,68.714841,,,1,,,,6.156715E-5,81.574003,3814.3686,11.545788,0
3291021.84,,5905,,62.8588,-0.267,9.4E-6,62.749986,0.62800757,740.57889,1.969,741.19145,0.9578,1481.7703,1.969,0.49145455,27.465372,2.4915186,68.389657,,,1,,,,6.0889926E-5,78.126909,3937.5607,11.802057,0
3291469.72,,5905,,62.8576,-0.267,9.2E-6,62.779981,0.63817203,721.43613,1.72,741.79428,0.9583,1463.2304,1.72,1.7260917,26.343603,2.3803819,68.668659,,,1,,,,6.2400775E-5,79.589772,3941.326,11.4915,0
3292298.39,,5905,,63.8755,-0.267,9.3E-6,63.804017,0.65976014,735.15509,1.637,766.15321,0.9807,1501.3083,1.637,3.9016343,26.963101,2.4664075,68.398187,,,1,,,,6.2555236E-5,83.435844,4070.9525,11.522082,0
3293124.81,,5905,,64.8981,-0.267,9.4E-6,64.786251,0.64593582,761.87815,2.057,790.16642,0.9997,1552.0446,2.057,0.46307896,28.192024,2.6042962,68.087898,,,1,,,,6.1992116E-5,79.996113,4197.2583,11.759874,0
3293580.67,,5905,,64.898,-0.267,9.3E-6,64.820484,0.65793809,740.00237,1.759,790.85946,1,1530.8618,1.759,1.3463744,26.973159,2.4762161,68.434695,,,1,,,,6.3573022E-5,81.551439,4201.6952,11.416181,0
3294423.34,,5905,,65.9155,-0.267,9.4E-6,65.843953,0.67853603,755.62686,1.622,816.14075,1.013,1571.7676,1.622,4.3452524,27.579966,2.5521391,68.264664,,,1,,,,6.3820583E-5,85.427317,4335.4262,11.476025,0
3295263.97,,5905,,66.9403,-0.267,9.4E-6,66.833618,0.66482028,783.35702,2.109,841.16577,1.016,1624.5228,2.109,0.42533367,28.927357,2.7118077,67.862855,,,1,,,,6.3070232E-5,81.79387,4466.7325,11.721003,0
3295729.47,,5905,,66.94,-0.267,9.3E-6,66.865677,0.67762768,760.48455,1.776,841.8257,1.016,1602.3103,1.776,1.3224835,27.667205,2.5805301,68.16293,,,1,,,,6.471599E-5,83.576739,4471.0187,11.373317,0
3296613.34,,5905,,67.9587,-0.267,9.4E-6,67.887112,0.69798992,774.06442,1.585,867.87321,1.005,1641.9376,1.585,2.6467309,28.191892,2.6414693,68.09397,,,1,,,,6.5015043E-5,87.257848,4608.6599,11.402229,0
3297464.47,,5905,,68.9783,-0.267,9.3E-6,68.878154,0.68438161,802.99943,2.118,893.73153,0.9855,1696.731,2.118,0.31847207,29.592884,2.8104029,67.675762,,,1,,,,6.4199373E-5,83.794013,4744.2001,11.65826,0
3297936.83,,5905,,68.9795,-0.267,9.3E-6,68.914458,0.69762819,778.94587,1.73,894.51474,0.9849,1673.4606,1.73,0.90964381,28.255486,2.6613262,68.051107,,,1,,,,6.5956446E-5,85.625202,4749.2025,11.303083,0
3298807.22,,5905,,69.9968,-0.267,9.3E-6,69.939669,0.72042764,794.06315,1.51,921.48083,0.9621,1715.544,1.51,2.8536044,28.879151,2.73755,67.91408,,,1,,,,6.6126385E-5,89.858406,4891.5573,11.353545,0
3299411,,5905,,70.0011,-0.267,9.4E-6,69.905531,0.63365116,790.42396,1.992,920.97757,0.9625,1711.4015,1.992,0.7035623,28.514772,2.7182717,67.771856,,,1,,,,6.6829182E-5,70.003872,4886.7832,11.30703,0
3299908.2,,5905,,69.9982,-0.267,9.4E-6,69.941012,0.70354462,788.16222,1.713,921.56893,0.962,1709.7312,1.713,0.94769388,28.534224,2.7000241,67.993985,,,1,,,,6.6617053E-5,85.730481,4891.7451,11.268957,0
3301186.53,,5905,,75.3324,-0.267,9.4E-6,75.276565,0.772062,840.65639,1.49,1069.1129,0.9761,1909.7693,1.49,2.1488568,30.510579,2.9794877,67.386046,,,1,,,,6.9173821E-5,94.959951,5666.5612,11.167571,0
3302493.69,,5905,,80.6663,-0.267,9.3E-6,80.557389,0.76694174,904.815,2.302,1225.8153,1.025,2130.6303,2.302,0.19071092,33.249217,3.3640917,66.534209,,,1,,,,7.0622946E-5,90.892788,6489.4929,11.231931,0
3303018.14,,5905,,80.6712,-0.267,9.3E-6,80.613275,0.80973386,877.47642,1.675,1227.2898,1.026,2104.7662,1.675,0.61529977,31.800344,3.161943,67.062451,,,1,,,,7.2527765E-5,96.234529,6498.5001,10.885011,0
3304388.83,,5905,,86.0003,-0.267,9.3E-6,85.91899,0.8765488,922.95548,1.578,1398.1432,1.107,2321.0987,1.578,0.84944433,33.533294,3.406313,66.515604,,,1,,,,7.5412837E-5,105.03489,7382.0728,10.742159,0
3305786.34,,5905,,91.3349,-0.267,9.2E-6,91.120702,0.86071424,992.22633,2.546,1578.0731,1.129,2570.2994,2.546,0.14389449,36.516372,3.8793296,65.2636,,,1,,,,7.6701468E-5,99.914222,8302.9824,10.889143,0
3306354.47,,5905,,91.3321,-0.267,9.3E-6,91.185277,0.90946685,959.87705,1.828,1580.0032,1.13,2539.8803,1.828,0.36879655,34.884132,3.6016715,66.010941,,,1,,,,7.8837416E-5,105.5127,8314.7547,10.526667,0
3307815.13,,5905,,96.6667,-0.267,9.4E-6,96.466702,0.97655913,1002.2691,1.688,1772.1542,1.229,2774.4233,1.688,0.5909353,36.529607,3.836646,65.412783,,,1,,,,8.1859871E-5,113.97312,9305.8246,10.389793,0
3309256.84,,5905,,102.003,-0.267,9.4E-6,101.71971,0.96048357,1067.6174,3.133,1971.0001,1.211,3038.6175,3.133,0.092384141,39.443545,4.3361159,64.054777,,,1,,,,8.3091683E-5,108.84854,10346.9,10.495678,0
3309865.39,,5905,,102.003,-0.267,9.3E-6,101.79375,1.0110218,1033.3725,1.902,1973.4544,1.212,3006.8269,1.902,0.22897397,37.730128,3.9827519,65.046655,,,1,,,,8.5396117E-5,114.20081,10361.967,10.151631,0
3311362.92,,5905,,107.332,-0.267,9.4E-6,107.12863,1.0828486,1075.5561,1.778,2180.3145,1.365,3255.8705,1.778,0.46999894,39.409067,4.2271285,64.380856,,,1,,,,8.8250802E-5,122.66828,11476.542,10.039857,0
3312873.02,,5905,,112.666,-0.267,9.2E-6,112.39412,1.0602099,1135.592,3.38,2393.5042,1.463,3529.0963,3.38,0.094541147,42.106654,4.7621568,62.767413,,,1,,,,8.9669666E-5,116.7921,12632.437,10.103661,0
3313561.42,,5905,,112.67,-0.267,9.3E-6,112.46987,1.1148412,1101.1245,1.757,2396.1643,1.465,3497.2889,1.757,1.1553439,40.441311,4.3519327,63.946899,,,1,,,,9.1935742E-5,121.71231,12649.471,9.790396,0
3315129.23,,5905,,118,-0.267,9.4E-6,117.80684,1.1852212,1138.1893,2.098,2616.3851,1.552,3754.5744,2.098,0.23587431,41.723853,4.4935897,63.608116,,,1,,,,9.5326836E-5,129.61367,13878.452,9.6614872,0
3316661.11,,5905,,123.332,-0.267,9.4E-6,123.06616,1.1607379,1205.9928,3.994,2842.2072,1.633,4048.2,3.994,0.071624607,44.612399,5.1468149,61.601872,,,1,,,,9.6463105E-5,124.1173,15145.28,9.7995485,0
3317343.95,,5905,,123.333,-0.267,9.2E-6,123.14856,1.2165496,1163.0076,2.541,2845.2107,1.634,4008.2183,2.541,0.15885876,42.589128,4.5753344,63.26324,,,1,,,,9.930301E-5,128.8069,15165.567,9.4439402,0
3318930.2,,5905,,128.666,-0.267,9.4E-6,128.48973,1.2886727,1201.4413,2.089,3072.6608,1.637,4274.1021,2.089,0.28506331,43.969425,4.7736874,62.660877,,,1,,,,0.00010237408,136.27357,16509.61,9.3504851,0
3320481.91,,5905,,133.998,-0.267,9.3E-6,133.74919,1.2649507,1271.0701,4.489,3300.3399,1.735,4571.41,4.489,0.083382219,46.689081,5.4275065,60.714895,,,1,,,,0.00010349577,130.75754,17888.846,9.5033858,0
3321190.91,,5905,,133.999,-0.267,9.3E-6,133.83799,1.3169056,1220.7256,2.648,3303.713,1.74,4524.4386,2.648,0.12738013,44.499434,4.760176,62.598703,,,1,,,,0.00010665521,134.29171,17912.608,9.1209198,0
3322783.69,,5905,,139.334,-0.267,9.3E-6,139.17713,1.3931894,1258.6474,2.364,3534.925,1.798,4793.5724,2.364,0.16501723,45.708509,4.9258272,62.086949,,,1,,,,0.00010984954,142.22131,19370.273,9.0434931,0
3324375.06,,5905,,144.666,-0.267,9.3E-6,144.43787,1.3613704,1324.9331,4.279,3766.7205,1.704,5091.6536,4.279,0.076555186,48.045993,5.5405017,60.18032,,,1,,,,0.00011137742,135.66383,20862.297,9.1730313,0
3325101.09,,5905,,144.668,-0.267,9.4E-6,144.5263,1.4171733,1277.1478,2.718,3770.1116,1.705,5047.2594,2.718,0.091161989,46.096578,4.8773824,62.110163,,,1,,,,0.00011430098,139.00156,20887.852,8.8367848,0
3326680.78,,5905,,150,-0.267,9.4E-6,149.86269,1.4938178,1319.0711,2.589,4004.4251,1.832,5323.4962,2.589,0.10401027,47.177317,5.0377785,61.601898,,,1,,,,0.00011769984,146.92803,22458.826,8.8018643,0
3327044.02,,5905,,150,-0.267,9.4E-6,149.86749,1.4686899,1305.343,3.156,4004.7365,1.833,5310.0795,3.156,0.051866611,46.766268,4.8808074,62.092278,,,1,,,,0.00011824483,141.53195,22460.264,8.7099812,0
3327699.81,CALFILE: C:\QdPpms\HEATCA~1\TempCal\Standard\Puck1983.cal|Addenda #47 measured on 2/2/2024 from 149.87 to 300.19 K
3327700.02,,5905,,150,-0.267,9.2E-6,149.8578,1.4243915,1311.7122,2.934,3999.424,1.249,5311.1362,2.934,0.054878886,46.756323,4.8660241,62.226334,,,1,,,,0.0001183091,131.60362,22457.36,8.7530456,0
3328111.27,,5905,,149.999,-0.267,9.3E-6,149.88411,1.4637974,1309.2676,1.667,4000.2633,1.252,5309.5309,1.667,0.38959425,46.750308,4.8589658,62.239998,,,1,,,,0.00011827026,140.26897,22465.247,8.7351995,0
3328522.16,,5905,,150.001,-0.267,9.3E-6,149.89147,1.4641293,1307.4099,1.612,4000.615,1.253,5308.0249,1.612,0.52481622,46.770409,4.8743055,62.15486,,,1,,,,0.00011819383,140.25093,22467.452,8.7223771,0
3329738.55,,5905,,155.169,-0.267,9.2E-6,154.97584,1.4622214,1386.5058,4.73,4228.4511,1.825,5614.9569,4.73,0.083434951,49.442393,5.7056929,59.504427,,,1,,,,0.00011892597,140.31123,24017.512,8.9465934,0
3330116.84,,5905,,155.172,-0.267,9.3E-6,155.06167,1.5416766,1335.4891,2.449,4231.4829,1.829,5566.9719,2.449,0.11881083,47.497155,4.9718717,61.689134,,,1,,,,0.0001219072,148.32718,24044.122,8.6126316,0
3330482.61,,5905,,155.174,-0.267,9.4E-6,155.06114,1.511521,1327.4086,3.068,4231.5924,1.829,5559.001,3.068,0.060130937,47.234201,4.8809805,61.958853,,,1,,,,0.00012230593,142.49147,24043.956,8.5605499,0
3331658.45,,5905,,160.345,-0.267,9.4E-6,160.14897,1.5096796,1417.4994,5.468,4447.4019,1.965,5864.9013,5.468,0.081096584,50.004497,5.7449296,59.340736,,,1,,,,0.00012262275,141.7026,25647.694,8.8511302,0
3332040.98,,5905,,160.345,-0.267,9.4E-6,160.24255,1.5913063,1369.3779,2.683,4450.6588,1.967,5820.0367,2.683,0.11830499,48.172423,5.0630905,61.317822,,,1,,,,0.0001255535,150.01349,25677.675,8.5456573,0
3332463.63,,5905,,160.346,-0.267,9.3E-6,160.24316,1.5647153,1356.1374,2.187,4450.8224,1.967,5806.9598,2.187,0.61442225,47.913023,4.9425741,61.696311,,,1,,,,0.00012579382,144.51727,25677.871,8.462997,0
3333647.33,,5905,,165.517,-0.267,9.3E-6,165.33585,1.5614409,1438.0536,5.525,4667.487,2.105,6105.5406,5.525,0.083648567,50.329026,5.7666913,59.061375,,,1,,,,0.00012661097,143.73907,27335.944,8.6977724,0
3334032.53,,5905,,165.52,-0.267,9.4E-6,165.42727,1.6372341,1396.6727,2.751,4670.722,2.105,6067.3947,2.751,0.12970194,48.665256,5.0584922,61.297002,,,1,,,,0.00012935165,150.98708,27366.182,8.44282,0
3334406.03,,5905,,165.517,-0.267,9.2E-6,165.43108,1.6125937,1387.9654,3.676,4671.0134,2.105,6058.9789,3.676,0.038755147,48.316783,4.9143126,61.786274,,,1,,,,0.00012995057,145.99577,27367.443,8.389992,0
3335597.86,,5905,,170.687,-0.267,9.4E-6,170.52165,1.6075487,1469.9438,5.7,4886.8077,2.042,6356.7515,5.7,0.073517361,50.678269,5.7762079,58.94487,,,1,,,,0.00013073486,144.95035,29077.633,8.6202764,0
3335984.53,,5905,,170.69,-0.267,9.3E-6,170.61137,1.6839867,1419.3878,2.722,4889.8585,2.043,6309.2462,2.722,0.13187053,48.818298,4.9875974,61.410753,,,1,,,,0.00013383589,152.03481,29108.241,8.3194205,0
3336359.41,,5905,,170.69,-0.267,9.3E-6,170.61463,1.656135,1407.1013,3.518,4890.1168,2.043,6297.218,3.518,0.043898632,48.470775,4.852736,61.829993,,,1,,,,0.00013438491,146.4549,29109.353,8.2472485,0
3337550.38,,5905,,175.861,-0.267,9.4E-6,175.69954,1.6486949,1494.554,5.195,5104.3109,2.236,6598.8649,5.195,0.092857412,50.719975,5.6714522,59.155541,,,1,,,,0.00013531831,145.41233,30870.328,8.5063057,0
3337938.89,,5905,,175.862,-0.267,9.3E-6,175.79045,1.7283248,1444.4623,3.101,5107.5597,2.237,6552.022,3.101,0.10870579,49.036875,4.9207367,61.572892,,,1,,,,0.00013813618,152.15992,30902.281,8.2169556,0
3338313.75,,5905,,175.858,-0.267,9.4E-6,175.79371,1.6993151,1439.6202,3.646,5107.8595,2.238,6547.4797,3.646,0.054408443,48.786335,4.8467491,61.788785,,,1,,,,0.00013867867,147.11062,30903.427,8.1892592,0
3339513.11,,5905,,181.033,-0.267,9.4E-6,180.8858,1.6960998,1513.7876,5.725,5324.9388,2.261,6838.7264,5.725,0.091810374,50.819571,5.6739596,58.860257,,,1,,,,0.00013978188,146.359,32719.674,8.3687476,0
3339900.17,,5905,,181.033,-0.267,9.3E-6,180.97254,1.7711821,1475.7457,3.259,5327.9835,2.261,6803.7292,3.259,0.065377378,49.249408,4.8915775,61.591371,,,1,,,,0.00014266475,152.45871,32751.06,8.1545281,0
3340277.08,,5905,,181.035,-0.267,9.4E-6,180.97792,1.7438519,1459.381,3.804,5328.2585,2.261,6787.6395,3.804,0.042390561,48.828199,4.7511914,61.979375,,,1,,,,0.00014339249,147.74822,32753.007,8.0638623,0
3341425.88,,5905,,186.207,-0.267,9.4E-6,186.05812,1.7366343,1561.7615,6.593,5534.9349,2.371,7096.6963,6.593,0.097943973,51.247859,5.764141,58.578477,,,1,,,,0.00014384754,146.4846,34617.623,8.3939443,0
3341817.59,,5905,,186.205,-0.267,9.4E-6,186.15842,1.8214634,1503.5193,3.247,5538.2173,2.373,7041.7366,3.247,0.11856237,49.335913,4.8785669,61.46513,,,1,,,,0.00014727341,153.74358,34654.956,8.0765583,0
3342195.16,,5905,,186.207,-0.267,9.3E-6,186.16225,1.7884169,1495.2082,3.988,5538.5423,2.373,7033.7506,3.988,0.044183942,49.007943,4.7202378,62.064136,,,1,,,,0.0001479238,148.00774,34656.383,8.0317479,0
3343339.78,,5905,,191.379,-0.267,9.4E-6,191.24471,1.7868962,1584.7748,6.581,5743.8921,2.517,7328.667,6.581,0.10112045,51.374781,5.6922749,58.711943,,,1,,,,0.00014795103,147.02383,36574.54,8.2866336,0
3343733.75,,5905,,191.376,-0.267,9.5E-6,191.34638,1.8711671,1523.5263,3.233,5747.2071,2.521,7270.7334,3.233,0.17545361,49.413695,4.8141504,61.553395,,,1,,,,0.00015162573,154.12434,36613.437,7.9621383,0
3344111.44,,5905,,191.377,-0.267,9.4E-6,191.35118,1.8374019,1518.8108,3.868,5747.6015,2.522,7266.4122,3.868,0.065991559,49.178783,4.6859786,62.07521,,,1,,,,0.00015212781,148.24109,36615.276,7.9372948,0
3345265.88,,5905,,196.551,-0.267,9.4E-6,196.441,1.8374589,1605.3588,6.591,5950.1431,2.744,7555.5019,6.591,0.10846324,51.300226,5.6841612,58.442705,,,1,,,,0.00015262139,147.53635,38589.065,8.1722186,0
3345657.31,,5905,,196.553,-0.267,9.3E-6,196.54097,1.9144092,1555.937,3.596,5953.3032,2.745,7509.2401,3.596,0.12445222,49.49029,4.8181168,61.396889,,,1,,,,0.00015628392,153.90068,38628.352,7.9166037,0
3346037.09,,5905,,196.552,-0.267,9.4E-6,196.54313,1.8839263,1547.1695,4.566,5953.5111,2.745,7500.6806,4.566,0.030044341,49.205964,4.6527897,62.061472,,,1,,,,0.00015682639,148.47087,38629.202,7.8719086,0
3347192.2,,5905,,201.722,-0.267,9.3E-6,201.63214,1.8826163,1631.2171,6.333,6147.2168,2.691,7778.4339,6.333,0.11306611,51.082416,5.5647508,58.686163,,,1,,,,0.00015758558,147.61789,40655.52,8.0900651,0
3347582.31,,5905,,201.723,-0.267,9.4E-6,201.72876,1.959297,1584.0332,3.766,6150.29,2.691,7734.3231,3.766,0.096798398,49.442843,4.7287311,61.663027,,,1,,,,0.00016095423,153.24725,40694.492,7.8522923,0
3347960.67,,5905,,201.724,-0.267,9.4E-6,201.734,1.9320876,1573.7264,4.296,6150.6621,2.691,7724.3885,4.296,0.043395426,49.259991,4.6143728,62.102231,,,1,,,,0.0001612038,148.32853,40696.607,7.8009972,0
3349060.44,,5905,,206.899,-0.267,9.4E-6,206.80845,1.9288774,1681.5467,7.47,6346.7765,2.808,8028.3232,7.47,0.12010885,51.460111,5.6933093,58.260157,,,1,,,,0.00016154849,147.77997,42769.736,8.1309378,0
3349453.22,,5905,,206.897,-0.267,9.4E-6,206.92223,2.0144183,1610.6964,3.779,6350.3518,2.81,7961.0482,3.779,0.14958741,49.381823,4.6977129,61.604367,,,1,,,,0.00016577312,154.38033,42816.81,7.7840664,0
3349831.83,,5905,,206.902,-0.267,9.2E-6,206.92305,1.9732928,1603.6006,4.507,6350.5032,2.81,7954.1038,4.507,0.04137091,48.938032,4.4695278,62.567881,,,1,,,,0.00016689549,148.14547,42817.149,7.7497438,0
3350925.14,,5905,,212.066,-0.267,9.3E-6,211.99568,1.9713979,1693.1738,7.729,6550.1183,3.095,8243.2921,7.729,0.10584646,51.118026,5.6188233,58.123954,,,1,,,,0.00016679033,146.81409,44942.168,7.9868315,0
3351317.06,,5905,,212.072,-0.267,9.4E-6,212.10743,2.0570019,1634.9894,4.013,6553.9176,3.106,8188.907,4.013,0.15278244,49.351982,4.7265628,61.222512,,,1,,,,0.00017057572,153.35408,44989.563,7.708308,0
3351695.27,,5905,,212.071,-0.267,9.2E-6,212.11275,2.0225965,1617.2491,4.974,6554.2176,3.106,8171.4667,4.974,0.0529012,48.830538,4.527263,61.896942,,,1,,,,0.00017180294,148.05595,44991.82,7.6244783,0
3352792.28,,5905,,217.237,-0.267,9.4E-6,217.19065,2.0145413,1719.9541,7.9,6774.5723,3.729,8494.5264,7.9,0.11442729,51.091181,5.7212915,57.404959,,,1,,,,0.00017198247,146.49161,47171.78,7.9190982,0
3353182.48,,5905,,217.243,-0.267,9.4E-6,217.30168,2.1042283,1649.0119,4.709,6778.6246,3.734,8427.6366,4.709,0.1257771,49.226416,4.8079661,60.396798,,,1,,,,0.00017597909,153.27354,47220.022,7.5885833,0
3353613.22,,5905,,217.241,-0.267,9.4E-6,217.30413,2.0698214,1638.5833,3.858,6778.971,3.734,8417.5543,3.858,1.6992372,49.114973,4.753596,60.543801,,,1,,,,0.00017608438,147.67925,47221.083,7.540507,0
3354713.39,,5905,,222.412,-0.267,9.4E-6,222.39041,2.0701599,1734.1993,7.234,6999.9768,3.566,8734.1761,7.234,0.12394637,50.895275,5.5570818,57.754268,,,1,,,,0.0001771883,147.34492,49457.494,7.7979951,0
3355103.91,,5905,,222.416,-0.267,9.3E-6,222.49329,2.1498611,1666.7923,4.551,7003.3133,3.56,8670.1057,4.551,0.13329235,49.079436,4.6052429,61.121093,,,1,,,,0.00018124997,152.68583,49503.264,7.4914274,0
3355533.34,,5905,,222.416,-0.267,9.3E-6,222.49369,2.1159101,1653.4383,3.775,7003.6241,3.56,8657.0625,3.775,1.0381655,48.94747,4.5661388,61.159567,,,1,,,,0.00018139511,147.23831,49503.443,7.4313943,0
3356629.66,,5905,,227.586,-0.267,9.3E-6,227.5887,2.1177053,1760.5244,6.962,7193.6483,3.288,8954.1727,6.962,0.17439586,50.405953,5.2780014,58.686854,,,1,,,,0.00018306009,146.84241,51796.617,7.7355526,0
3357015.27,,5905,,227.585,-0.267,9.4E-6,227.68503,2.1926245,1699.2784,4.423,7196.4909,3.285,8895.7692,4.423,0.13645138,48.770236,4.3390313,62.344488,,,1,,,,0.00018682461,151.21786,51840.471,7.4632857,0
3357391,,5905,,227.586,-0.267,9.2E-6,227.69423,2.1621875,1679.7685,4.84,7196.8457,3.285,8876.6143,4.84,0.071012999,48.345783,4.0784163,63.496297,,,1,,,,0.00018774354,146.31071,51844.664,7.3772993,0
3358426.91,,5905,,232.755,-0.267,9.3E-6,232.76752,2.1566196,1815.4065,8.144,7383.8056,3.273,9199.2121,8.144,0.16686483,50.336649,5.0678862,59.760675,,,1,,,,0.00018810013,145.03735,54180.717,7.799226,0
3358812.36,,5905,,232.76,-0.267,9.3E-6,232.88343,2.2450301,1741.5859,4.435,7387.1643,3.279,9128.7502,4.435,0.16505492,48.376462,3.8627815,64.953463,,,1,,,,0.00019273722,151.00995,54234.694,7.4783588,0
3359235.31,,5905,,232.758,-0.267,9.3E-6,232.88067,2.2086242,1723.0151,3.705,7387.2338,3.279,9110.2489,3.705,0.3727509,48.087248,3.6235645,66.181083,,,1,,,,0.00019320369,145.12939,54233.408,7.3987036,0
3360268.58,,5905,,237.932,-0.267,9.4E-6,237.94932,2.2136112,1832.4544,8.624,7568.8597,3.639,9401.3141,8.624,0.1551452,49.555649,4.314323,63.208654,,,1,,,,0.0001943182,144.26174,56619.877,7.7010284,0
3360651.64,,5905,,237.931,-0.267,9.4E-6,238.05122,2.2907036,1774.7996,4.766,7571.6515,3.639,9346.4511,4.766,0.18983678,47.979155,3.3058147,68.2982,,,1,,,,0.00019830869,148.66695,56668.382,7.4555366,0
3361020.39,,5905,,237.931,-0.267,9.3E-6,238.0575,2.2585694,1769.6084,5.675,7571.9368,3.639,9341.5451,5.675,0.043075891,47.670595,2.9840608,70.376436,,,1,,,,0.00019912141,143.93747,56671.373,7.4335334,0
3362049.22,,5905,,243.11,-0.267,9.4E-6,243.14145,2.2675639,1874.6322,7.826,7733.3613,3.495,9607.9935,7.826,0.19675986,48.789171,3.4837467,67.912176,,,1,,,,0.00020074905,143.01179,59117.762,7.7100479,0
3362424.52,,5905,,243.103,-0.267,9.2E-6,243.24336,2.3353006,1823.2751,4.498,7736.0308,3.496,9559.3058,4.498,0.22727821,47.447518,2.6191836,73.107879,,,1,,,,0.00020432707,146.36751,59167.333,7.4956827,0
3362790.5,,5905,,243.103,-0.267,9.3E-6,243.25403,2.3102455,1811.4007,5.679,7736.4217,3.496,9547.8223,5.679,0.060706542,47.165693,2.3731169,74.867806,,,1,,,,0.0002050087,142.34255,59172.525,7.4465391,0
3363805.97,,5905,,248.275,-0.267,9.4E-6,248.32489,2.3216981,1917.0146,8.142,7900.5807,3.73,9817.5954,8.142,0.27871722,48.267154,2.7487108,72.809397,,,1,,,,0.00020647504,141.49708,61665.249,7.7197846,0
3364175.81,,5905,,248.278,-0.267,9.4E-6,248.43353,2.3895157,1863.164,4.567,7903.5064,3.731,9766.6705,4.567,0.30026223,46.688501,1.6680985,80.93414,,,1,,,,0.00021104836,144.80146,61719.218,7.4996481,0
3364535.31,,5905,,248.276,-0.267,9.2E-6,248.43553,2.3557797,1862.6835,5.802,7903.6555,3.731,9766.339,5.802,0.062455679,46.551637,1.5138537,82.365718,,,1,,,,0.00021148509,140.0655,61720.212,7.4976535,0
3365548.25,,5905,,253.444,-0.267,9.3E-6,253.50888,2.3758185,1968.3406,8.145,8064.9311,3.548,10033.272,8.145,0.32703308,47.697932,1.9420119,79.133803,,,1,,,,0.00021257656,139.65491,64266.754,7.7643852,0
3365914.25,,5905,,253.446,-0.267,9.2E-6,253.61117,2.4399301,1923.7568,5.035,8067.4922,3.548,9991.249,5.035,0.19690368,46.317348,1.0687204,86.948307,,,1,,,,0.00021694185,143.0938,64318.626,7.5854578,0
3366321.77,,5905,,253.448,-0.267,9.4E-6,253.61395,2.4146514,1925.7928,4.042,8067.6546,3.548,9993.4474,4.042,1.141198,46.350029,0.97720073,87.955925,,,1,,,,0.00021672834,138.95204,64320.038,7.5934023,0
3367328.95,,5905,,258.623,-0.267,9.4E-6,258.70468,2.4393623,2028.0608,8.338,8215.1185,3.871,10243.179,8.338,0.4217077,46.76385,0.84256958,89.725773,,,1,,,,0.00022004189,139.05009,66928.11,7.8392892,0
3367689.69,,5905,,258.621,-0.267,9.3E-6,258.78396,2.449618,2001.4158,9.323,8217.5788,3.878,10218.995,8.478,0.36202181,45.475195,,,,,1,,,,0.0002247158,140.29155,66969.139,7.7339253,0
3368043.81,,5905,,258.621,-0.267,9.3E-6,258.7887,2.4197616,1982.9401,7.466,8217.8249,3.879,10200.765,6.38,0.1143412,45.272247,,,,,1,,,,0.00022532049,136.42558,66971.591,7.6623907,0
3369035.75,,5905,,263.792,-0.267,9.4E-6,263.87153,2.4609045,2058.0438,8.545,8376.7282,4.308,10434.772,8.545,0.51510631,46.294279,0.98306979,88.061544,,,1,,,,0.00022661549,135.81674,69628.184,7.7994158,0
3369394.5,,5905,,263.794,-0.267,9.3E-6,263.96414,2.4890679,2019.6898,8.648,8379.638,4.313,10399.328,7.496,0.21919309,44.858936,,,,,1,,,,0.00023182288,138.88284,69677.069,7.6513795,0
3369746.64,,5905,,263.801,-0.267,9.4E-6,263.98674,2.4983241,1990.0572,5.896,8379.9169,4.314,10369.974,5.896,0.080979542,44.876792,0.29797213,95.881666,,,1,,,,0.00023144452,134.57681,69688.997,7.5384742,0
3370735.2,,5905,,268.967,-0.267,9.4E-6,269.06129,2.503696,2086.6924,9.016,8536.4999,4.57,10623.192,9.016,0.3822802,45.748662,0.90673168,88.745081,,,1,,,,0.00023336708,134.63038,72393.979,7.7554539,0
3371099.38,,5905,,268.97,-0.267,9.3E-6,269.14563,2.5268072,2041.6322,10.2,8538.9329,4.575,10580.565,9.113,0.37058166,44.308165,,,,,1,,,,0.00023879493,137.24599,72439.371,7.5856039,0
3371455.13,,5905,,268.966,-0.267,9.3E-6,269.14532,2.4892468,2033.3874,8.374,8539.0347,4.575,10572.422,7.014,0.15017812,44.205886,,,,,1,,,,0.00023916322,132.92449,72439.205,7.5549795,0
3372434.66,,5905,,274.137,-0.267,9.3E-6,274.2274,2.5319599,2136.9721,8.824,8691.933,4.989,10828.905,8.824,0.6315037,45.341096,1.0717911,86.878013,,,1,,,,0.00024027102,132.61766,75200.665,7.792701,0
3372786.58,,5905,,274.137,-0.267,9.3E-6,274.33567,2.6056769,2074.9576,6.373,8694.8002,4.999,10769.758,6.373,0.29745946,44.15268,0.47480117,93.501985,,,1,,,,0.00024455691,136.02329,75260.058,7.5635722,0
3373137.61,,5905,,274.138,-0.267,9.4E-6,274.33056,2.5382437,2084.6205,10.09,8695.2341,5,10779.855,8.762,0.19749613,43.801735,,,,,1,,,,0.00024610565,132.45804,75257.257,7.5989363,0
3374064.89,,5905,,279.316,-0.267,9.4E-6,279.37831,2.5770149,2179.3902,10.29,8864.9564,5.742,11044.347,10.29,0.60495414,45.314955,1.2646124,84.837532,,,1,,,,0.00024546932,131.40521,78052.238,7.8008569,0
3374417.25,,5905,,279.309,-0.267,9.4E-6,279.50619,2.6549703,2126.8636,7.168,8868.3664,5.763,10995.23,7.168,0.42392222,43.97092,0.55593112,92.460911,,,1,,,,0.00025082956,135.94486,78123.711,7.6093612,0
3374807.77,,5905,,279.313,-0.267,9.4E-6,279.51517,2.6227363,2109.9976,6.255,8868.822,5.766,10978.82,6.255,3.4230532,43.855179,0.54212221,92.583935,,,1,,,,0.00025109257,131.91276,78128.731,7.5487765,0
3375730.23,,5905,,284.481,-0.267,9.4E-6,284.54991,2.6199873,2234.3054,12.04,9026.0778,6.879,11260.383,12.04,0.5665238,45.006891,1.5501316,81.936313,,,1,,,,0.00025244222,131.56554,80968.649,7.8520688,0
3376079.72,,5905,,284.481,-0.267,9.3E-6,284.67769,2.6900129,2168.7457,8.255,9029.3067,6.899,11198.052,8.255,0.81133542,43.428533,0.65600067,91.120568,,,1,,,,0.0002588071,135.02067,81041.385,7.6182497,0
3376465.22,,5905,,284.484,-0.267,9.4E-6,284.67743,2.6508967,2150.9003,7.321,9029.4307,6.9,11180.331,7.321,4.2656172,43.207547,0.54115032,92.498342,,,1,,,,0.00025954533,130.2856,81041.237,7.5555704,0
3377384.98,,5905,,289.661,-0.267,9.4E-6,289.72208,2.6565206,2273.0601,11.63,9170.7688,7.166,11443.829,11.63,0.78380089,44.475917,1.5409743,81.857756,,,1,,,,0.00025963532,129.62264,83938.882,7.8456572,0
3377742.2,,5905,,289.653,-0.267,9.3E-6,289.84835,2.6930087,2212.4056,16.21,9172.958,7.148,11385.364,14.55,0.64739724,42.394629,,,,,1,,,,0.00026855674,133.42775,84012.065,7.6329763,0
3378071.97,,5905,,289.658,-0.267,9.4E-6,289.84271,2.669971,2198.0734,8.697,9172.8279,7.15,11370.901,8.697,0.43109889,42.829395,0.6347791,91.262891,,,1,,,,0.00026645704,127.18389,84008.796,7.5836767,0
3378985.83,,5905,,294.828,-0.267,9.2E-6,294.90818,2.7178987,2302.3887,11.34,9232.1648,5.675,11534.553,11.34,0.52695072,43.623724,1.3223065,83.840243,,,1,,,,0.00026650466,128.48818,86970.832,7.8071374,0
3379325.73,,5905,,294.835,-0.267,9.2E-6,295.02896,2.7850648,2239.7492,7.407,9233.0328,5.647,11472.782,7.407,0.35196901,42.224165,0.48368583,93.168484,,,1,,,,0.00027247942,130.87117,87042.086,7.5916251,0
3379656.44,,5905,,294.829,-0.267,9.3E-6,295.03535,2.7503849,2214.5977,7.542,9233.1027,5.644,11447.7,7.542,0.15910129,41.968213,0.35723386,94.80652,,,1,,,,0.00027333475,126.67249,87045.86,7.5062111,0
3380559.33,,5905,,299.999,-0.267,9.4E-6,300.05873,2.7806091,2284.8217,10.06,9292.3174,5.101,11577.139,10.06,0.41009168,42.801016,0.98720168,87.159545,,,1,,,,0.00027207643,125.90464,90035.24,7.6145817,0
3380891.98,,5905,,300.003,-0.267,9.3E-6,300.17962,2.8508402,2221.2727,6.451,9293.9336,5.113,11515.206,6.451,0.21944189,41.579924,0.37982799,94.434597,,,1,,,,0.00027755442,128.40305,90107.807,7.3998118,0
3381217.92,,5905,,300.005,-0.267,9.4E-6,300.17882,2.813041,2209.0338,6.734,9293.9766,5.113,11503.01,6.734,0.091919607,41.44041,0.37671959,94.442482,,,1,,,,0.00027818749,124.73977,90107.327,7.3590595,0
3403919.84,CALFILE: C:\QdPpms\HEATCA~1\TempCal\Standard\Puck1983.cal|Addenda #46 measured on 2/1/2024 from 3.1287 to 149.82 K
3403920.11,,5905,,11.9994,-0.267,9.3E-6,12.072936,0.12233613,45.819251,0.5007,26.068881,0.03679,71.888132,0.5007,48.955963,5.4521759,0.53853066,54.881253,,,1,,,,1.8287803E-5,18.620855,145.75579,3.7952037,0
3403991.47,,5905,,11.9999,-0.267,9.2E-6,12.06646,0.11439257,45.795611,0.5328,26.043926,0.03675,71.839537,0.5328,82.996248,5.4336754,0.54047115,54.401044,,,1,,,,1.8450404E-5,16.356528,145.59946,3.7952814,0
3404062.94,,5905,,11.9999,-0.267,9.4E-6,12.063526,0.1141563,45.915348,0.5371,26.029219,0.03673,71.944567,0.5371,71.222549,5.4499766,0.54137135,54.352958,,,1,,,,1.8444177E-5,16.301026,145.52865,3.8061301,0
3404269.56,,5905,,12.5334,-0.267,9.3E-6,12.58206,0.11495607,51.515402,0.6187,28.740174,0.04028,80.255576,0.6187,111.93049,5.8213815,0.57505605,54.022179,,,1,,,,1.9401409E-5,16.34993,158.30823,4.0943536,0
3404343.08,,5905,,12.5331,-0.267,9.4E-6,12.582396,0.11936787,51.400032,0.5922,28.737057,0.04028,80.137089,0.5922,82.190554,5.8059888,0.57264211,54.225719,,,1,,,,1.9365611E-5,17.464144,158.3167,4.085075,0
3404418.75,,5905,,12.5332,-0.267,9.2E-6,12.579765,0.11935864,51.422407,0.5888,28.722861,0.04026,80.145269,0.5888,71.050113,5.8027432,0.5711078,54.329363,,,1,,,,1.9355998E-5,17.417966,158.25049,4.0877081,0
3404622.02,,5905,,13.0686,-0.267,9.4E-6,13.106592,0.12030014,57.202301,0.6726,31.61392,0.0442,88.816221,0.6726,67.757993,6.1883628,0.60802041,53.967336,,,1,,,,2.0247272E-5,17.40823,171.78276,4.3643917,0
3404698,,5905,,13.068,-0.267,9.4E-6,13.106926,0.12514849,57.002564,0.6515,31.610907,0.04419,88.613471,0.6515,59.946598,6.171002,0.60543816,54.223053,,,1,,,,2.017829E-5,18.565088,171.7915,4.3490415,0
3404773.77,,5905,,13.0681,-0.267,9.4E-6,13.104436,0.1245292,58.255214,0.6663,31.599465,0.04418,89.854679,0.6663,50.844899,6.3163424,0.60997335,54.311238,,,1,,,,2.004836E-5,18.513006,171.72624,4.4454576,0
3404979.86,,5905,,13.6,-0.267,9.3E-6,13.623287,0.12694665,63.171568,0.7406,34.578094,0.04844,97.749662,0.7406,88.781682,6.5508775,0.63958859,53.963904,,,1,,,,2.1089138E-5,18.949027,185.59394,4.6370285,0
3405058.63,,5905,,13.5999,-0.267,9.3E-6,13.623513,0.1303536,62.686748,0.707,34.573051,0.04844,97.259799,0.707,55.018983,6.5072081,0.63819496,53.997872,,,1,,,,2.1085472E-5,19.652632,185.6001,4.6013645,0
3405138.5,,5905,,13.6003,-0.267,9.3E-6,13.62165,0.13018499,62.338584,0.713,34.561219,0.04842,96.899803,0.713,72.650236,6.4707295,0.63613009,54.071571,,,1,,,,2.1085296E-5,19.521624,185.54934,4.5764342,0
3405346.7,,5905,,14.1338,-0.267,9.4E-6,14.134065,0.13061775,68.34569,0.8123,37.633015,0.05307,105.9787,0.8123,80.060768,6.8324438,0.67277196,53.638756,,,1,,,,2.1991573E-5,19.412189,199.7718,4.8355295,0
3405427.63,,5905,,14.1327,-0.267,9.4E-6,14.133968,0.13533443,68.176664,0.7786,37.627646,0.05306,105.80431,0.7786,43.012727,6.8341771,0.67191379,53.857721,,,1,,,,2.1877467E-5,20.497331,199.76905,4.823604,0
3405498.02,,5905,,14.1332,-0.267,9.3E-6,14.133953,0.13524141,68.64535,0.7868,37.627989,0.05306,106.27334,0.7868,41.555795,6.8650429,0.67009686,54.047708,,,1,,,,2.1849203E-5,20.502531,199.76863,4.8567694,0
3405706.91,,5905,,14.6672,-0.267,9.3E-6,14.646076,0.1361462,76.004182,0.8742,40.828385,0.05822,116.83257,0.8742,39.783301,7.3654366,0.71220605,53.760362,,,1,,,,2.2556613E-5,20.595129,214.50755,5.1893886,0
3405793.13,,5905,,14.6671,-0.267,9.4E-6,14.648189,0.14188906,74.385843,0.8377,40.833621,0.05823,115.21946,0.8377,64.55785,7.1825757,0.70428426,53.794013,,,1,,,,2.2710262E-5,22.09631,214.56944,5.0781597,0
3405876.95,,5905,,14.6675,-0.267,9.3E-6,14.64572,0.14044751,74.503963,0.8278,40.81729,0.0582,115.32125,0.8278,55.375207,7.1986015,0.70444509,53.842727,,,1,,,,2.2673611E-5,21.547727,214.4971,5.0870811,0
3406088.45,,5905,,15.1998,-0.267,9.4E-6,15.167415,0.14150119,81.362781,0.9239,44.204175,0.06402,125.56696,0.9239,61.560676,7.5888902,0.74085552,53.616279,,,1,,,,2.3524646E-5,21.595805,230.05047,5.3643144,0
3406174.02,,5905,,15.2,-0.267,9.3E-6,15.168898,0.14601002,81.69913,0.9062,44.209633,0.06403,125.90876,0.9062,52.296025,7.6247991,0.74093493,53.756817,,,1,,,,2.3451467E-5,22.766671,230.09548,5.3859633,0
3406259.63,,5905,,15.2002,-0.267,9.4E-6,15.166947,0.14634146,80.645216,0.901,44.194247,0.064,124.83946,0.901,70.601006,7.5029579,0.73584762,53.698738,,,1,,,,2.359263E-5,22.874397,230.03629,5.3171685,0
3406483.94,,5905,,15.7336,-0.267,9.3E-6,15.688593,0.14479661,88.753327,1.02,47.718906,0.07045,136.47223,1.02,72.802109,7.9879024,0.77819077,53.252947,,,1,,,,2.4455889E-5,22.508874,246.13195,5.6571884,0
3406573.61,,5905,,15.7331,-0.267,9.3E-6,15.691207,0.15158379,87.540197,0.9654,47.721536,0.07046,135.26173,0.9654,38.905464,7.8819597,0.77183366,53.557097,,,1,,,,2.4402435E-5,23.963707,246.21399,5.5789332,0
3406661.36,,5905,,15.7335,-0.267,9.3E-6,15.689342,0.15067881,87.4236,0.9749,47.707705,0.07043,135.1313,0.9749,48.668446,7.8662881,0.77041553,53.596593,,,1,,,,2.4409985E-5,23.645879,246.15545,5.5721649,0
3406888.88,,5905,,16.2674,-0.267,9.4E-6,16.212917,0.15127259,96.099209,1.044,51.364612,0.07751,147.46382,1.044,89.611799,8.3849878,0.81056787,53.533775,,,1,,,,2.5107343E-5,23.598864,262.85869,5.9273237,0
3406982.45,,5905,,16.2676,-0.267,9.4E-6,16.214887,0.15691094,96.459224,1.015,51.37461,0.07753,147.83383,1.015,67.640708,8.415424,0.80820907,53.837719,,,1,,,,2.4994623E-5,25.154964,262.92255,5.9488065,0
3407074.81,,5905,,16.2676,-0.267,9.3E-6,16.214569,0.15726754,94.856335,1.024,51.368653,0.07752,146.22499,1.024,46.864242,8.2441129,0.80237999,53.679809,,,1,,,,2.5211573E-5,25.246272,262.91226,5.8500681,0
3407307.31,,5905,,16.7999,-0.267,9.4E-6,16.736976,0.15678018,103.1846,1.098,55.138734,0.0852,158.32333,1.098,51.359559,8.7216955,0.84308903,53.524502,,,1,,,,2.5919962E-5,24.732339,280.12637,6.1650682,0
3407403.56,,5905,,16.8,-0.267,9.4E-6,16.739241,0.16193345,102.54654,1.071,55.149083,0.08522,157.69562,1.071,43.978985,8.6667323,0.84093998,53.563519,,,1,,,,2.593669E-5,26.165087,280.2022,6.1261162,0
3407498.66,,5905,,16.8001,-0.267,9.4E-6,16.737047,0.16166254,102.24223,1.094,55.132555,0.08518,157.37479,1.094,29.261575,8.652036,0.84181165,53.494507,,,1,,,,2.5938815E-5,26.000197,280.12873,6.1087379,0
3407730.48,,5905,,17.3339,-0.267,9.4E-6,17.263886,0.1627723,111.7632,1.194,59.057189,0.09354,170.82039,1.194,70.921052,9.1842794,0.87806509,53.779773,,,1,,,,2.6522012E-5,25.956108,298.04177,6.4738149,0
3407829.55,,5905,,17.3337,-0.267,9.4E-6,17.267087,0.16837449,109.4612,1.128,59.07196,0.09357,168.53316,1.128,53.350937,8.9815201,0.8739624,53.525664,,,1,,,,2.6743919E-5,27.552838,298.15229,6.3392973,0
3407926.92,,5905,,17.3327,-0.267,9.3E-6,17.265947,0.16688449,109.24599,1.14,59.061498,0.09354,168.30749,1.14,32.388986,8.95556,0.87246944,53.526822,,,1,,,,2.6776201E-5,26.94456,298.11293,6.3272516,0
3408163.3,,5905,,17.8663,-0.267,9.3E-6,17.790741,0.16737851,118.40495,1.224,63.087027,0.1025,181.49198,1.224,48.08072,9.4428591,0.91114371,53.512794,,,1,,,,2.7462981E-5,26.86668,316.51047,6.6554256,0
3408262.52,,5905,,17.8657,-0.267,9.2E-6,17.793882,0.1731412,116.39737,1.194,63.102542,0.1025,179.49991,1.194,25.288261,9.2719642,0.9057296,53.465625,,,1,,,,2.7590494E-5,28.328577,316.62223,6.5414265,0
3408362.56,,5905,,17.867,-0.267,9.4E-6,17.791718,0.17159457,118.46799,1.219,63.088727,0.1025,181.55671,1.219,59.618987,9.4520152,0.90862728,53.762351,,,1,,,,2.7357729E-5,27.815893,316.54525,6.6586027,0
3408600.81,,5905,,18.3993,-0.267,9.3E-6,18.315092,0.17475036,123.68838,1.275,67.211002,0.1119,190.89938,1.275,67.521848,9.6200601,0.94300464,53.32404,,,1,,,,2.8322001E-5,28.356046,335.44259,6.7533582,0
3408702.42,,5905,,18.3997,-0.267,9.2E-6,18.313976,0.17738202,123.90852,1.273,67.195598,0.1119,191.10411,1.273,40.178302,9.6540135,0.94407033,53.40148,,,1,,,,2.8234122E-5,28.86018,335.40172,6.76579,0
3408803.91,,5905,,18.4,-0.267,9.4E-6,18.313463,0.17750237,123.67885,1.249,67.190235,0.1119,190.86908,1.249,33.030355,9.6048326,0.93987497,53.440904,,,1,,,,2.8319542E-5,28.96204,335.38293,6.7534384,0
3409042.52,,5905,,18.9342,-0.267,9.3E-6,18.836431,0.17758599,133.83752,1.401,71.435119,0.122,205.27264,1.401,55.304,10.159547,0.98230736,53.44884,,,1,,,,2.8885513E-5,28.814498,354.81113,7.1052486,0
3409147.08,,5905,,18.933,-0.267,9.4E-6,18.841004,0.18449182,131.47497,1.343,71.453906,0.122,202.92888,1.343,63.810497,9.9827366,0.97733976,53.423907,,,1,,,,2.8973479E-5,30.47864,354.98343,6.9781299,0
3409251.2,,5905,,18.9337,-0.267,9.3E-6,18.838628,0.18312295,130.93464,1.321,71.432401,0.122,202.36705,1.321,27.217489,9.944215,0.97731691,53.329,,,1,,,,2.9021094E-5,29.94821,354.89391,6.950328,0
3409492.63,,5905,,19.4665,-0.267,9.4E-6,19.360444,0.1828282,142.21331,1.473,75.775131,0.1326,217.98844,1.473,26.883227,10.555701,1.0203438,53.381629,,,1,,,,2.9559652E-5,29.832645,374.82681,7.3455602,0
3409599.42,,5905,,19.4662,-0.267,9.4E-6,19.363878,0.19066164,140.17759,1.392,75.786896,0.1326,215.96449,1.392,45.010318,10.426761,1.0160267,53.51211,,,1,,,,2.9515692E-5,31.667102,374.95979,7.239128,0
3409706.36,,5905,,19.4666,-0.267,9.2E-6,19.364199,0.18937041,138.91777,1.376,75.785157,0.1326,214.70293,1.376,45.370048,10.30017,1.0120952,53.342308,,,1,,,,2.9721028E-5,31.280283,374.97221,7.1739488,0
3409950.83,,5905,,20.0007,-0.267,9.4E-6,19.88681,0.18879524,149.44724,1.531,80.236044,0.1438,229.68328,1.531,62.391625,10.855456,1.0554614,53.328385,,,1,,,,3.0264304E-5,30.900511,395.4852,7.5148925,0
3410060.84,,5905,,20.0009,-0.267,9.3E-6,19.8913,0.19576044,146.66233,1.462,80.253562,0.1438,226.91589,1.462,57.728314,10.62507,1.0450345,53.420015,,,1,,,,3.0402402E-5,32.566367,395.66383,7.3731895,0
3410168.67,,5905,,20.0012,-0.267,9.2E-6,19.889572,0.19322837,147.08419,1.467,80.24801,0.1438,227.3322,1.467,45.468513,10.66318,1.048757,53.27713,,,1,,,,3.0423815E-5,31.87521,395.59506,7.3950405,0